Workbook
Name different: #REF!
Name mike: 'ARR Waterfall'!$A$8
Name unit: 'ARR Waterfall'!$A$1
Name unit: 'Billing Waterfall'!#REF!
Name unit: Capitalizations!#REF!
Name unit: Cohorts!$A$1
Name unit: Model!#REF!
Name unit: 'Model (Start)'!#REF!
Name unit: 'SaaS Metrics'!#REF!
Name unit: Transaction!#REF!
Name unit: #REF!

Sheet Resources
B4: GO, GO, GO!
B5: Practice really does make perfect!
B6: You got this! :-)
B10: This template is part of a comprehensive course for SaaS investing roles & interviews.
B11: For more video courses and tutorials:
B13: =HYPERLINK("https://GrowthEquityInterviewGuide.com", "GrowthEquityInterviewGuide.com") -> GrowthEquityInterviewGuide.com
B25: All rights reserved. Growth Equity Interview Guide.

Sheet Start ->

Sheet Model (Start)
B2: Income Statement | AH2: $ in thousands, except noted
C3: =YEAR(C4) -> 2020 | D3: =YEAR(D4) -> 2020 | E3: =YEAR(E4) -> 2020 | F3: =YEAR(F4) -> 2020 | G3: =YEAR(G4) -> 2021 | H3: =YEAR(H4) -> 2021 | I3: =YEAR(I4) -> 2021 | J3: =YEAR(J4) -> 2021 | ... AH3: =YEAR(AH4) -> 2027
C4: 43921 | D4: =EOMONTH(C4, 3) -> 44012 | E4: =EOMONTH(D4, 3) -> 44104 | F4: =EOMONTH(E4, 3) -> 44196 | G4: =EOMONTH(F4, 3) -> 44286 | H4: =EOMONTH(G4, 3) -> 44377 | I4: =EOMONTH(H4, 3) -> 44469 | J4: =EOMONTH(I4, 3) -> 44561 | K4: =EOMONTH(J4, 3) -> 44651 | ... AH4: =EOMONTH(AG4, 3) -> 46752
B5: Ending ARR | C5: =+'ARR Waterfall'!C11 -> 8563.9987 | D5: =+'ARR Waterfall'!D11 -> 10870.48 | E5: =+'ARR Waterfall'!E11 -> 12868.786 | F5: =+'ARR Waterfall'!F11 -> 17227.514 | G5: =+'ARR Waterfall'!G11 -> 20583.553 | H5: =+'ARR Waterfall'!H11 -> 24832.39 | I5: =+'ARR Waterfall'!I11 -> 30936.948 | J5: =+'ARR Waterfall'!J11 -> 37345.929 | ... N5: =+'ARR Waterfall'!N11 -> 71551.25
B6: % YoY Growth | G6: =G5/C5-1 -> 1.4034979 | H6: =H5/D5-1 -> 1.2843875 | I6: =I5/E5-1 -> 1.40403 | J6: =J5/F5-1 -> 1.1678072 | K6: =K5/G5-1 -> 1.1093313 | L6: =L5/H5-1 -> 1.0809316 | M6: =M5/I5-1 -> 0.91602693 | N6: =N5/J5-1 -> 0.91590496
B8: GAAP Revenue | C8: 2198.9787 | D8: 2784.2487 | E8: 3286.6844 | F8: 4387.6529 | G8: 5236.4888 | H8: 6301.1027 | I8: 7833.5468 | J8: 9427.8556 | K8: 10932.177 | L8: 12966.669 | M8: 14824.426 | N8: 17887.813
B9: % of ARR | C9: =+C8/C5 -> 0.25677009 | D9: =+D8/D5 -> 0.25612932 | E9: =+E8/E5 -> 0.25539972 | F9: =+F8/F5 -> 0.25468869 | G9: =+G8/G5 -> 0.2544016 | H9: =+H8/H5 -> 0.25374532 | I9: =+I8/I5 -> 0.25321007 | J9: =+J8/J5 -> 0.25244668 | ... N9: =+N8/N5 -> 0.25
B10: % YoY Growth | G10: =G8/C8-1 -> 1.3813276 | H10: =H8/D8-1 -> 1.2631249 | I10: =I8/E8-1 -> 1.3834193 | J10: =J8/F8-1 -> 1.1487241 | K10: =K8/G8-1 -> 1.0876922 | L10: =L8/H8-1 -> 1.0578413 | M10: =M8/I8-1 -> 0.89242832 | N10: =N8/J8-1 -> 0.89733629
B12: LTM GAAP Revenue | F12: =SUM(C8:F8) -> 12657.565 | G12: =SUM(D8:G8) -> 15695.075 | H12: =SUM(E8:H8) -> 19211.929 | I12: =SUM(F8:I8) -> 23758.791 | J12: =SUM(G8:J8) -> 28798.994 | K12: =SUM(H8:K8) -> 34494.682 | L12: =SUM(I8:L8) -> 41160.248 | M12: =SUM(J8:M8) -> 48151.127 | N12: =SUM(K8:N8) -> 56611.084
B14: Gross Profit
B15: COGS | C15: 722.2534 | D15: 918.37481 | E15: 1085.7528 | F15: 1453.3984 | G15: 1740.5519 | H15: 2108.5494 | I15: 2628.3375 | J15: 3172.8358 | K15: 3697.5797 | L15: 4401.0711 | M15: 5056.4593 | N15: 6099.5097
B16: Gross Profit | C16: =C8-C15 -> 1476.7253 | D16: =D8-D15 -> 1865.8739 | E16: =E8-E15 -> 2200.9315 | F16: =F8-F15 -> 2934.2545 | G16: =G8-G15 -> 3495.9369 | H16: =H8-H15 -> 4192.5532 | I16: =I8-I15 -> 5205.2092 | J16: =J8-J15 -> 6255.0198 | ... N16: =N8-N15 -> 11788.303
B17: Gross Margin % | C17: =C16/C8 -> 0.67155053 | D17: =D16/D8 -> 0.67015346 | E17: =E16/E8 -> 0.66965101 | F17: =F16/F8 -> 0.66875266 | G17: =G16/G8 -> 0.66761088 | H17: =H16/H8 -> 0.66536819 | I17: =I16/I8 -> 0.66447669 | J17: =J16/J8 -> 0.66346156 | ... N17: =N16/N8 -> 0.6590131
B19: Operating Expenses
B20: S&M | C20: 1200.0106 | D20: 1349.9439 | E20: 1491.0471 | F20: 1617.078 | G20: 1758.3879 | H20: 1902.2561 | I20: 2438.482 | J20: 2927.6113 | K20: 3411.8055 | L20: 4597.6605 | M20: 4968.3289 | N20: 6584.1337
B21: R&D | C21: 2384.2614 | D21: 2500.9067 | E21: 2551.3452 | F21: 2636.7793 | G21: 2660.6691 | H21: 2698.5614 | I21: 3369.0085 | J21: 4151.8057 | K21: 4502.3103 | L21: 5732.0898 | M21: 5605.4327 | N21: 7072.7661
B22: G&A | C22: 1361.0007 | D22: 1326.3992 | E22: 1478.9223 | F22: 1886.0624 | G22: 1697.4529 | H22: 2916.5136 | I22: 3509.8164 | J22: 3710.7398 | K22: 4047.0941 | L22: 4572.464 | M22: 4505.0889 | N22: 4913.5268
B23: Operating Expenses | C23: =SUM(C20:C22) -> 4945.2726 | D23: =SUM(D20:D22) -> 5177.2499 | E23: =SUM(E20:E22) -> 5521.3146 | F23: =SUM(F20:F22) -> 6139.9196 | G23: =SUM(G20:G22) -> 6116.5098 | H23: =SUM(H20:H22) -> 7517.3311 | I23: =SUM(I20:I22) -> 9317.3069 | J23: =SUM(J20:J22) -> 10790.157 | ... N23: =SUM(N20:N22) -> 18570.427
B24: =B20&" as % of Revenue" -> S&M as % of Revenue | C24: =+C20/C$8 -> 0.54571268 | D24: =+D20/D$8 -> 0.48485034 | E24: =+E20/E$8 -> 0.45366301 | F24: =+F20/F$8 -> 0.36855193 | G24: =+G20/G$8 -> 0.33579521 | H24: =+H20/H$8 -> 0.30189257 | I24: =+I20/I$8 -> 0.3112871 | J24: =+J20/J$8 -> 0.3105278 | ... N24: =+N20/N$8 -> 0.36807931
B25: =B21&" as % of Revenue" -> R&D as % of Revenue | C25: =+C21/C$8 -> 1.0842585 | D25: =+D21/D$8 -> 0.89823395 | E25: =+E21/E$8 -> 0.77626718 | F25: =+F21/F$8 -> 0.60095439 | G25: =+G21/G$8 -> 0.50810174 | H25: =+H21/H$8 -> 0.42826812 | I25: =+I21/I$8 -> 0.43007447 | J25: =+J21/J$8 -> 0.44037646 | ... N25: =+N21/N$8 -> 0.39539581
B26: =B22&" as % of Revenue" -> G&A as % of Revenue | C26: =+C22/C$8 -> 0.61892398 | D26: =+D22/D$8 -> 0.47639393 | E26: =+E22/E$8 -> 0.44997395 | F26: =+F22/F$8 -> 0.42985679 | G26: =+G22/G$8 -> 0.3241586 | H26: =+H22/H$8 -> 0.46285766 | I26: =+I22/I$8 -> 0.44804946 | J26: =+J22/J$8 -> 0.39359319 | ... N26: =+N22/N$8 -> 0.27468573
B27: =B23&" as % of Revenue" -> Operating Expenses as % of Revenue | C27: =+C23/C$8 -> 2.2488952 | D27: =+D23/D$8 -> 1.8594782 | E27: =+E23/E$8 -> 1.6799041 | F27: =+F23/F$8 -> 1.3993631 | G27: =+G23/G$8 -> 1.1680556 | H27: =+H23/H$8 -> 1.1930184 | I27: =+I23/I$8 -> 1.189411 | J27: =+J23/J$8 -> 1.1444975 | ... N27: =+N23/N$8 -> 1.0381608
B29: Operating Income | C29: =+C16-C23 -> -3468.5473 | D29: =+D16-D23 -> -3311.376 | E29: =+E16-E23 -> -3320.3831 | F29: =+F16-F23 -> -3205.6651 | G29: =+G16-G23 -> -2620.5729 | H29: =+H16-H23 -> -3324.7779 | I29: =+I16-I23 -> -4112.0977 | J29: =+J16-J23 -> -4535.1369 | ... N29: =+N16-N23 -> -6782.1238
B30: % Margin | C30: =+C29/C8 -> -1.5773446 | D30: =+D29/D8 -> -1.1893248 | E30: =+E29/E8 -> -1.0102531 | F30: =+F29/F8 -> -0.73061046 | G30: =+G29/G8 -> -0.50044468 | H30: =+H29/H8 -> -0.52765017 | I30: =+I29/I8 -> -0.52493434 | J30: =+J29/J8 -> -0.48103589 | ... N30: =+N29/N8 -> -0.37914774
B32: D&A | F32: 532.1409 | G32: 636.10833 | H32: 765.86278 | I32: 929.68827 | J32: 1124.4055 | K32: 1351.9878 | L32: 1608.1003 | M32: 1814.7037 | N32: 2119.6867
B33: EBITDA | F33: =+F29+F32 -> -2673.5242 | G33: =+G29+G32 -> -1984.4646 | H33: =+H29+H32 -> -2558.9151 | I33: =+I29+I32 -> -3182.4094 | J33: =+J29+J32 -> -3410.7314 | K33: =+K29+K32 -> -3374.6249 | L33: =+L29+L32 -> -4728.516 | M33: =+M29+M32 -> -3496.1804 | N33: =+N29+N32 -> -4662.4371
B34: % Margin | F34: =+F33/F8 -> -0.60932901 | G34: =+G33/G8 -> -0.37896856 | H34: =+H33/H8 -> -0.40610592 | I34: =+I33/I8 -> -0.40625396 | J34: =+J33/J8 -> -0.36177171 | K34: =+K33/K8 -> -0.30868737 | L34: =+L33/L8 -> -0.36466698 | M34: =+M33/M8 -> -0.23583918 | N34: =+N33/N8 -> -0.26064881
B36: Interest Expense | F36: 0 | G36: 0 | H36: 0 | I36: 0 | J36: 0 | K36: 0 | L36: 0 | M36: 0 | N36: 0
B37: Taxable Income | F37: =+F29-F36 -> -3205.6651 | G37: =+G29-G36 -> -2620.5729 | H37: =+H29-H36 -> -3324.7779 | I37: =+I29-I36 -> -4112.0977 | J37: =+J29-J36 -> -4535.1369 | K37: =+K29-K36 -> -4726.6127 | L37: =+L29-L36 -> -6336.6164 | M37: =+M29-M36 -> -5310.8841 | N37: =+N29-N36 -> -6782.1238
B39: Taxes | F39: 0 | G39: 0 | H39: 0 | I39: 0 | J39: 0 | K39: 0 | L39: 0 | M39: 0 | N39: 0
B40: Tax Rate | F40: 0.25 | G40: 0.25 | H40: 0.25 | I40: 0.25 | J40: 0.25 | K40: 0.25 | L40: 0.25 | M40: 0.25 | N40: 0.25
B42: Net Income | F42: =+F37-F39 -> -3205.6651 | G42: =+G37-G39 -> -2620.5729 | H42: =+H37-H39 -> -3324.7779 | I42: =+I37-I39 -> -4112.0977 | J42: =+J37-J39 -> -4535.1369 | K42: =+K37-K39 -> -4726.6127 | L42: =+L37-L39 -> -6336.6164 | M42: =+M37-M39 -> -5310.8841 | N42: =+N37-N39 -> -6782.1238
B43: % Margin | F43: =+F42/F8 -> -0.73061046 | G43: =+G42/G8 -> -0.50044468 | H43: =+H42/H8 -> -0.52765017 | I43: =+I42/I8 -> -0.52493434 | J43: =+J42/J8 -> -0.48103589 | K43: =+K42/K8 -> -0.43235787 | L43: =+L42/L8 -> -0.48868498 | M43: =+M42/M8 -> -0.35825227 | N43: =+N42/N8 -> -0.37914774
B45: Note:
B46: Prior Year Renewal ARR for Billing | K46: 5660.477 | L46: 6828.9072 | M46: 8507.6607 | N46: 10270.13
B49: Balance Sheet | AH49: $ in thousands, except noted
N50: =N4 -> 44926 | O50: =O4 -> 45016 | P50: =P4 -> 45107 | Q50: =Q4 -> 45199 | R50: =R4 -> 45291 | S50: =S4 -> 45382 | T50: =T4 -> 45473 | U50: =U4 -> 45565 | ... AH50: =AH4 -> 46752
B51: Cash | N51: 26476.734
B52: Accounts Receivable | N52: 15182.163
B53: Net PP&E | N53: 35699.125
...

Sheet Primary Assumptions (Start)
B2: Assumption | C2: Unit | D2: 2023 | E2: 2024 | F2: 2025 | G2: 2026 | H2: 2027
B3: New logo ARR | C3: % of beginning quarterly ARR balance | D3: 0.12 | E3: 0.1 | F3: 0.08 | G3: 0.06 | H3: 0.06
B4: Upsell ARR | C4: " | D4: 0.08 | E4: 0.07 | F4: 0.05 | G4: 0.04 | H4: 0.04
B5: Downsell ARR | C5: " | D5: -0.02 | E5: -0.02 | F5: -0.02 | G5: -0.02 | H5: -0.02
B6: Churn ARR | C6: " | D6: -0.02 | E6: -0.02 | F6: -0.02 | G6: -0.02 | H6: -0.02
B8: COGS | C8: % of quarterly GAAP revenue | D8: 0.65 | E8: 0.65 | F8: 0.65 | G8: 0.65 | H8: 0.65
B9: =Model!B20 -> S&M | C9: " | D9: 0.4 | E9: 0.38 | F9: 0.36 | G9: 0.34 | H9: 0.32
B10: =Model!B21 -> R&D | C10: " | D10: 0.42 | E10: 0.4 | F10: 0.38 | G10: 0.36 | H10: 0.34
B11: =Model!B22 -> G&A | C11: " | D11: 0.3 | E11: 0.28 | F11: 0.26 | G11: 0.24 | H11: 0.22
B13: Note: See prompt for complete list of assumptions

Sheet End ->

Sheet Transaction
B2: Entry | G2: $ in thousands, except noted
B3: Entry Assumptions | E3: Sources
B4: Entry LTM Revenue | C4: =Model!N64 -> 56611.084 | E4: Sponsor Equity | G4: 300000
B5: Entry Multiple | C5: 30 | E5: Total Sources | G5: =SUM(G4) -> 300000
B6: Entry Enterprise Value | C6: =C5*C4 -> 1698332.5
B7: (-) Debt | C7: =Model!L58 -> 0 | E7: Uses
B8: (+) Cash | C8: =Model!L48 -> 26476.734 | E8: Cash to B/S | G8: =G4 -> 300000
B9: Entry Equity Value | C9: =+C6-C7+C8 -> 1724809.3 | E9: Total Uses | G9: =SUM(G8) -> 300000
B11: Pre-Money Shares Outstanding | C11: 525000
B12: Pre-Money Stock Price | C12: =+C9/C11*1000 -> 3285.351
B13: New Shares Issued | C13: =+G4/C12*1000 -> 91314.445
B14: Post-Money Shares Outstanding | C14: =+C13+C11 -> 616314.44
B17: Exit & Returns
B18: Exit Value | E18: Exit Ownership
B19: Exit LTM Revenue | C19: =SUM(Model!AE8:AH8) -> 436393.45 | E19: Initial Ownership | G19: =+C13/C14 -> 0.1481621
B20: Exit Multiple | C20: 16 | E20: Dilution from Stock-Based Compensation | G20: =+Model!AH136 -> 0.13433396
B21: Exit Enterprise Value | C21: =C20*C19 -> 6982295.2 | E21: Exit Ownership | G21: =+G19*(1-G20) -> 0.1282589
B22: (-) Debt | C22: =+Model!AH58 -> 0
B23: (+) Cash | C23: =+Model!AH48 -> 118164.88
B24: Exit Equity value | C24: =+C21+C23-C22 -> 7100460.1
B25: (x) Exit Ownership | C25: =+G21 -> 0.1282589
B26: Exit Sponsor Value | C26: =+C24*C25 -> 910697.21
B28: IRR | C28: =XIRR(C32:C33, C34:C35) -> 0.2485264
B29: M-o-M | C29: =+C33/(-C32) -> 3.0356574
B32: Entry Investment | C32: =+-G4 -> -300000
B33: Exit Proceeds | C33: =+C26 -> 910697.21
B34: Entry Date | C34: =+Model!N4 -> 44926
B35: Exit Date | C35: =+Model!AH4 -> 46752

Sheet Model
B2: Income Statement | AH2: $ in thousands, except noted
C3: =YEAR(C4) -> 2020 | D3: =YEAR(D4) -> 2020 | E3: =YEAR(E4) -> 2020 | F3: =YEAR(F4) -> 2020 | G3: =YEAR(G4) -> 2021 | H3: =YEAR(H4) -> 2021 | I3: =YEAR(I4) -> 2021 | J3: =YEAR(J4) -> 2021 | ... AH3: =YEAR(AH4) -> 2027
C4: 43921 | D4: =EOMONTH(C4, 3) -> 44012 | E4: =EOMONTH(D4, 3) -> 44104 | F4: =EOMONTH(E4, 3) -> 44196 | G4: =EOMONTH(F4, 3) -> 44286 | H4: =EOMONTH(G4, 3) -> 44377 | I4: =EOMONTH(H4, 3) -> 44469 | J4: =EOMONTH(I4, 3) -> 44561 | K4: =EOMONTH(J4, 3) -> 44651 | ... AH4: =EOMONTH(AG4, 3) -> 46752
B5: Ending ARR | C5: =+'ARR Waterfall'!C11 -> 8563.9987 | D5: =+'ARR Waterfall'!D11 -> 10870.48 | E5: =+'ARR Waterfall'!E11 -> 12868.786 | F5: =+'ARR Waterfall'!F11 -> 17227.514 | G5: =+'ARR Waterfall'!G11 -> 20583.553 | H5: =+'ARR Waterfall'!H11 -> 24832.39 | I5: =+'ARR Waterfall'!I11 -> 30936.948 | J5: =+'ARR Waterfall'!J11 -> 37345.929 | ... AH5: =+'ARR Waterfall'!AH11 -> 475243.16
B6: % YoY Growth | G6: =G5/C5-1 -> 1.4034979 | H6: =H5/D5-1 -> 1.2843875 | I6: =I5/E5-1 -> 1.40403 | J6: =J5/F5-1 -> 1.1678072 | K6: =K5/G5-1 -> 1.1093313 | L6: =L5/H5-1 -> 1.0809316 | M6: =M5/I5-1 -> 0.91602693 | N6: =N5/J5-1 -> 0.91590496 | ... AH6: =AH5/AD5-1 -> 0.26247696
B8: GAAP Revenue | C8: 2198.9787 | D8: 2784.2487 | E8: 3286.6844 | F8: 4387.6529 | G8: 5236.4888 | H8: 6301.1027 | I8: 7833.5468 | J8: 9427.8556 | K8: 10932.177 | L8: 12966.669 | M8: 14824.426 | N8: 17887.813 | O8: =O9*O5 -> 20749.863 | P8: =P9*P5 -> 24069.841 | Q8: =Q9*Q5 -> 27921.015 | R8: =R9*R5 -> 32388.377 | S8: =S9*S5 -> 36598.867 | T8: =T9*T5 -> 41356.719 | U8: =U9*U5 -> 46733.093 | V8: =V9*V5 -> 52808.395 | ... AH8: =AH9*AH5 -> 118810.79
B9: % of ARR | C9: =+C8/C5 -> 0.25677009 | D9: =+D8/D5 -> 0.25612932 | E9: =+E8/E5 -> 0.25539972 | F9: =+F8/F5 -> 0.25468869 | G9: =+G8/G5 -> 0.2544016 | H9: =+H8/H5 -> 0.25374532 | I9: =+I8/I5 -> 0.25321007 | J9: =+J8/J5 -> 0.25244668 | ... N9: =+N8/N5 -> 0.25 | O9: 0.25 | P9: 0.25 | Q9: 0.25 | R9: 0.25 | S9: 0.25 | T9: 0.25 | U9: 0.25 | V9: 0.25 | W9: 0.25 | X9: 0.25 | Y9: 0.25 | Z9: 0.25 | AA9: 0.25 | AB9: 0.25 | AC9: 0.25 | AD9: 0.25 | AE9: 0.25 | AF9: 0.25 | AG9: 0.25 | AH9: 0.25
B10: % YoY Growth | G10: =G8/C8-1 -> 1.3813276 | H10: =H8/D8-1 -> 1.2631249 | I10: =I8/E8-1 -> 1.3834193 | J10: =J8/F8-1 -> 1.1487241 | K10: =K8/G8-1 -> 1.0876922 | L10: =L8/H8-1 -> 1.0578413 | M10: =M8/I8-1 -> 0.89242832 | N10: =N8/J8-1 -> 0.89733629 | ... AH10: =AH8/AD8-1 -> 0.26247696
B12: LTM GAAP Revenue | F12: =SUM(C8:F8) -> 12657.565 | G12: =SUM(D8:G8) -> 15695.075 | H12: =SUM(E8:H8) -> 19211.929 | I12: =SUM(F8:I8) -> 23758.791 | J12: =SUM(G8:J8) -> 28798.994 | K12: =SUM(H8:K8) -> 34494.682 | L12: =SUM(I8:L8) -> 41160.248 | M12: =SUM(J8:M8) -> 48151.127 | ... AH12: =SUM(AE8:AH8) -> 436393.45
B14: Gross Profit
B15: COGS | C15: 722.2534 | D15: 918.37481 | E15: 1085.7528 | F15: 1453.3984 | G15: 1740.5519 | H15: 2108.5494 | I15: 2628.3375 | J15: 3172.8358 | K15: 3697.5797 | L15: 4401.0711 | M15: 5056.4593 | N15: 6099.5097 | O15: =(1-O17)*O8 -> 7262.4519 | P15: =(1-P17)*P8 -> 8424.4442 | Q15: =(1-Q17)*Q8 -> 9772.3553 | R15: =(1-R17)*R8 -> 11335.932 | S15: =(1-S17)*S8 -> 12809.603 | T15: =(1-T17)*T8 -> 14474.852 | U15: =(1-U17)*U8 -> 16356.582 | V15: =(1-V17)*V8 -> 18482.938 | ... AH15: =(1-AH17)*AH8 -> 41583.776
B16: Gross Profit | C16: =C8-C15 -> 1476.7253 | D16: =D8-D15 -> 1865.8739 | E16: =E8-E15 -> 2200.9315 | F16: =F8-F15 -> 2934.2545 | G16: =G8-G15 -> 3495.9369 | H16: =H8-H15 -> 4192.5532 | I16: =I8-I15 -> 5205.2092 | J16: =J8-J15 -> 6255.0198 | ... AH16: =AH8-AH15 -> 77227.013
B17: Gross Margin % | C17: =C16/C8 -> 0.67155053 | D17: =D16/D8 -> 0.67015346 | E17: =E16/E8 -> 0.66965101 | F17: =F16/F8 -> 0.66875266 | G17: =G16/G8 -> 0.66761088 | H17: =H16/H8 -> 0.66536819 | I17: =I16/I8 -> 0.66447669 | J17: =J16/J8 -> 0.66346156 | ... N17: =N16/N8 -> 0.6590131 | O17: 0.65 | P17: 0.65 | Q17: 0.65 | R17: 0.65 | S17: 0.65 | T17: 0.65 | U17: 0.65 | V17: 0.65 | W17: 0.65 | X17: 0.65 | Y17: 0.65 | Z17: 0.65 | AA17: 0.65 | AB17: 0.65 | AC17: 0.65 | AD17: 0.65 | AE17: 0.65 | AF17: 0.65 | AG17: 0.65 | AH17: 0.65
B19: Operating Expenses
B20: S&M | C20: 1200.0106 | D20: 1349.9439 | E20: 1491.0471 | F20: 1617.078 | G20: 1758.3879 | H20: 1902.2561 | I20: 2438.482 | J20: 2927.6113 | K20: 3411.8055 | L20: 4597.6605 | M20: 4968.3289 | N20: 6584.1337 | O20: =O$8*O24 -> 8299.945 | P20: =P$8*P24 -> 9627.9362 | Q20: =Q$8*Q24 -> 11168.406 | R20: =R$8*R24 -> 12955.351 | S20: =S$8*S24 -> 13907.569 | T20: =T$8*T24 -> 15715.553 | U20: =U$8*U24 -> 17758.575 | V20: =V$8*V24 -> 20067.19 | ... AH20: =AH$8*AH24 -> 38019.453
B21: R&D | C21: 2384.2614 | D21: 2500.9067 | E21: 2551.3452 | F21: 2636.7793 | G21: 2660.6691 | H21: 2698.5614 | I21: 3369.0085 | J21: 4151.8057 | K21: 4502.3103 | L21: 5732.0898 | M21: 5605.4327 | N21: 7072.7661 | O21: =O$8*O25 -> 8714.9423 | P21: =P$8*P25 -> 10109.333 | Q21: =Q$8*Q25 -> 11726.826 | R21: =R$8*R25 -> 13603.119 | S21: =S$8*S25 -> 14639.547 | T21: =T$8*T25 -> 16542.688 | U21: =U$8*U25 -> 18693.237 | V21: =V$8*V25 -> 21123.358 | ... AH21: =AH$8*AH25 -> 40395.668
B22: G&A | C22: 1361.0007 | D22: 1326.3992 | E22: 1478.9223 | F22: 1886.0624 | G22: 1697.4529 | H22: 2916.5136 | I22: 3509.8164 | J22: 3710.7398 | K22: 4047.0941 | L22: 4572.464 | M22: 4505.0889 | N22: 4913.5268 | O22: =O$8*O26 -> 6224.9588 | P22: =P$8*P26 -> 7220.9522 | Q22: =Q$8*Q26 -> 8376.3045 | R22: =R$8*R26 -> 9716.5132 | S22: =S$8*S26 -> 10247.683 | T22: =T$8*T26 -> 11579.881 | U22: =U$8*U26 -> 13085.266 | V22: =V$8*V26 -> 14786.351 | ... AH22: =AH$8*AH26 -> 26138.374
B23: Operating Expenses | C23: =SUM(C20:C22) -> 4945.2726 | D23: =SUM(D20:D22) -> 5177.2499 | E23: =SUM(E20:E22) -> 5521.3146 | F23: =SUM(F20:F22) -> 6139.9196 | G23: =SUM(G20:G22) -> 6116.5098 | H23: =SUM(H20:H22) -> 7517.3311 | I23: =SUM(I20:I22) -> 9317.3069 | J23: =SUM(J20:J22) -> 10790.157 | ... AH23: =SUM(AH20:AH22) -> 104553.49
B24: =B20&" as % of Revenue" -> S&M as % of Revenue | C24: =+C20/C$8 -> 0.54571268 | D24: =+D20/D$8 -> 0.48485034 | E24: =+E20/E$8 -> 0.45366301 | F24: =+F20/F$8 -> 0.36855193 | G24: =+G20/G$8 -> 0.33579521 | H24: =+H20/H$8 -> 0.30189257 | I24: =+I20/I$8 -> 0.3112871 | J24: =+J20/J$8 -> 0.3105278 | ... N24: =+N20/N$8 -> 0.36807931 | O24: 0.4 | P24: 0.4 | Q24: 0.4 | R24: 0.4 | S24: 0.38 | T24: 0.38 | U24: 0.38 | V24: 0.38 | W24: 0.36 | X24: 0.36 | Y24: 0.36 | Z24: 0.36 | AA24: 0.34 | AB24: 0.34 | AC24: 0.34 | AD24: 0.34 | AE24: 0.32 | AF24: 0.32 | AG24: 0.32 | AH24: 0.32
B25: =B21&" as % of Revenue" -> R&D as % of Revenue | C25: =+C21/C$8 -> 1.0842585 | D25: =+D21/D$8 -> 0.89823395 | E25: =+E21/E$8 -> 0.77626718 | F25: =+F21/F$8 -> 0.60095439 | G25: =+G21/G$8 -> 0.50810174 | H25: =+H21/H$8 -> 0.42826812 | I25: =+I21/I$8 -> 0.43007447 | J25: =+J21/J$8 -> 0.44037646 | ... N25: =+N21/N$8 -> 0.39539581 | O25: 0.42 | P25: 0.42 | Q25: 0.42 | R25: 0.42 | S25: 0.4 | T25: 0.4 | U25: 0.4 | V25: 0.4 | W25: 0.38 | X25: 0.38 | Y25: 0.38 | Z25: 0.38 | AA25: 0.36 | AB25: 0.36 | AC25: 0.36 | AD25: 0.36 | AE25: 0.34 | AF25: 0.34 | AG25: 0.34 | AH25: 0.34
B26: =B22&" as % of Revenue" -> G&A as % of Revenue | C26: =+C22/C$8 -> 0.61892398 | D26: =+D22/D$8 -> 0.47639393 | E26: =+E22/E$8 -> 0.44997395 | F26: =+F22/F$8 -> 0.42985679 | G26: =+G22/G$8 -> 0.3241586 | H26: =+H22/H$8 -> 0.46285766 | I26: =+I22/I$8 -> 0.44804946 | J26: =+J22/J$8 -> 0.39359319 | ... N26: =+N22/N$8 -> 0.27468573 | O26: 0.3 | P26: 0.3 | Q26: 0.3 | R26: 0.3 | S26: 0.28 | T26: 0.28 | U26: 0.28 | V26: 0.28 | W26: 0.26 | X26: 0.26 | Y26: 0.26 | Z26: 0.26 | AA26: 0.24 | AB26: 0.24 | AC26: 0.24 | AD26: 0.24 | AE26: 0.22 | AF26: 0.22 | AG26: 0.22 | AH26: 0.22
B27: =B23&" as % of Revenue" -> Operating Expenses as % of Revenue | C27: =+C23/C$8 -> 2.2488952 | D27: =+D23/D$8 -> 1.8594782 | E27: =+E23/E$8 -> 1.6799041 | F27: =+F23/F$8 -> 1.3993631 | G27: =+G23/G$8 -> 1.1680556 | H27: =+H23/H$8 -> 1.1930184 | I27: =+I23/I$8 -> 1.189411 | J27: =+J23/J$8 -> 1.1444975 | ... AH27: =+AH23/AH$8 -> 0.88
B29: Operating Income | C29: =+C16-C23 -> -3468.5473 | D29: =+D16-D23 -> -3311.376 | E29: =+E16-E23 -> -3320.3831 | F29: =+F16-F23 -> -3205.6651 | G29: =+G16-G23 -> -2620.5729 | H29: =+H16-H23 -> -3324.7779 | I29: =+I16-I23 -> -4112.0977 | J29: =+J16-J23 -> -4535.1369 | ... AH29: =+AH16-AH23 -> -27326.481
B30: % Margin | C30: =+C29/C8 -> -1.5773446 | D30: =+D29/D8 -> -1.1893248 | E30: =+E29/E8 -> -1.0102531 | F30: =+F29/F8 -> -0.73061046 | G30: =+G29/G8 -> -0.50044468 | H30: =+H29/H8 -> -0.52765017 | I30: =+I29/I8 -> -0.52493434 | J30: =+J29/J8 -> -0.48103589 | ... AH30: =+AH29/AH8 -> -0.23
B32: D&A | F32: 532.1409 | G32: 636.10833 | H32: 765.86278 | I32: 929.68827 | J32: 1124.4055 | K32: 1351.9878 | L32: 1608.1003 | M32: 1814.7037 | N32: 2119.6867 | O32: =+O106+O107 -> 2093.5817 | P32: =+P106+P107 -> 2484.4798 | Q32: =+Q106+Q107 -> 2942.2599 | R32: =+R106+R107 -> 3459.4552 | S32: =+S106+S107 -> 4039.9687 | T32: =+T106+T107 -> 4668.7375 | U32: =+U106+U107 -> 5364.8043 | V32: =+V106+V107 -> 6134.6073 | ... AH32: =+AH106+AH107 -> 16008.64
B33: EBITDA | F33: =+F29+F32 -> -2673.5242 | G33: =+G29+G32 -> -1984.4646 | H33: =+H29+H32 -> -2558.9151 | I33: =+I29+I32 -> -3182.4094 | J33: =+J29+J32 -> -3410.7314 | K33: =+K29+K32 -> -3374.6249 | L33: =+L29+L32 -> -4728.516 | M33: =+M29+M32 -> -3496.1804 | ... AH33: =+AH29+AH32 -> -11317.841
B34: % Margin | F34: =+F33/F8 -> -0.60932901 | G34: =+G33/G8 -> -0.37896856 | H34: =+H33/H8 -> -0.40610592 | I34: =+I33/I8 -> -0.40625396 | J34: =+J33/J8 -> -0.36177171 | K34: =+K33/K8 -> -0.30868737 | L34: =+L33/L8 -> -0.36466698 | M34: =+M33/M8 -> -0.23583918 | ... AH34: =+AH33/AH8 -> -0.095259372
B36: Interest Expense | F36: 0 | G36: 0 | H36: 0 | I36: 0 | J36: 0 | K36: 0 | L36: 0 | M36: 0 | N36: 0 | O36: 0 | P36: 0 | Q36: 0 | R36: 0 | S36: 0 | T36: 0 | U36: 0 | V36: 0 | W36: 0 | X36: 0 | Y36: 0 | Z36: 0 | AA36: 0 | AB36: 0 | AC36: 0 | AD36: 0 | AE36: 0 | AF36: 0 | AG36: 0 | AH36: 0
B37: Taxable Income | F37: =+F29-F36 -> -3205.6651 | G37: =+G29-G36 -> -2620.5729 | H37: =+H29-H36 -> -3324.7779 | I37: =+I29-I36 -> -4112.0977 | J37: =+J29-J36 -> -4535.1369 | K37: =+K29-K36 -> -4726.6127 | L37: =+L29-L36 -> -6336.6164 | M37: =+M29-M36 -> -5310.8841 | ... AH37: =+AH29-AH36 -> -27326.481
B39: Taxes | F39: 0 | G39: 0 | H39: 0 | I39: 0 | J39: 0 | K39: 0 | L39: 0 | M39: 0 | N39: 0 | O39: =IF(O37<0, 0, O37*O40) -> 0 | P39: =IF(P37<0, 0, P37*P40) -> 0 | Q39: =IF(Q37<0, 0, Q37*Q40) -> 0 | R39: =IF(R37<0, 0, R37*R40) -> 0 | S39: =IF(S37<0, 0, S37*S40) -> 0 | T39: =IF(T37<0, 0, T37*T40) -> 0 | U39: =IF(U37<0, 0, U37*U40) -> 0 | V39: =IF(V37<0, 0, V37*V40) -> 0 | ... AH39: =IF(AH37<0, 0, AH37*AH40) -> 0
B40: Tax Rate | F40: 0.25 | G40: 0.25 | H40: 0.25 | I40: 0.25 | J40: 0.25 | K40: 0.25 | L40: 0.25 | M40: 0.25 | N40: 0.25 | O40: 0.25 | P40: 0.25 | Q40: 0.25 | R40: 0.25 | S40: 0.25 | T40: 0.25 | U40: 0.25 | V40: 0.25 | W40: 0.25 | X40: 0.25 | Y40: 0.25 | Z40: 0.25 | AA40: 0.25 | AB40: 0.25 | AC40: 0.25 | AD40: 0.25 | AE40: 0.25 | AF40: 0.25 | AG40: 0.25 | AH40: 0.25
B42: Net Income | F42: =+F37-F39 -> -3205.6651 | G42: =+G37-G39 -> -2620.5729 | H42: =+H37-H39 -> -3324.7779 | I42: =+I37-I39 -> -4112.0977 | J42: =+J37-J39 -> -4535.1369 | K42: =+K37-K39 -> -4726.6127 | L42: =+L37-L39 -> -6336.6164 | M42: =+M37-M39 -> -5310.8841 | ... AH42: =+AH37-AH39 -> -27326.481
B43: % Margin | F43: =+F42/F8 -> -0.73061046 | G43: =+G42/G8 -> -0.50044468 | H43: =+H42/H8 -> -0.52765017 | I43: =+I42/I8 -> -0.52493434 | J43: =+J42/J8 -> -0.48103589 | K43: =+K42/K8 -> -0.43235787 | L43: =+L42/L8 -> -0.48868498 | M43: =+M42/M8 -> -0.35825227 | ... AH43: =+AH42/AH8 -> -0.23
B46: Balance Sheet | L46: Actual | N46: PF | AH46: $ in thousands, except noted
L47: =N4 -> 44926 | M47: Adj. | N47: =+L47 -> 44926 | O47: =O4 -> 45016 | P47: =P4 -> 45107 | Q47: =Q4 -> 45199 | R47: =R4 -> 45291 | S47: =S4 -> 45382 | T47: =T4 -> 45473 | U47: =U4 -> 45565 | V47: =V4 -> 45657 | ... AH47: =AH4 -> 46752
B48: Cash | L48: 26476.734 | M48: =Transaction!G8 -> 300000 | N48: =+M48+L48 -> 326476.73 | O48: =+O119 -> 318575.88 | P48: =+P119 -> 309646.37 | Q48: =+Q119 -> 299517.55 | R48: =+R119 -> 288309.15 | S48: =+S119 -> 278010.43 | T48: =+T119 -> 266296 | U48: =+U119 -> 253503.79 | V48: =+V119 -> 239769.99 | ... AH48: =+AH119 -> 118164.88
B49: Accounts Receivable | L49: 15182.163 | N49: =+M49+L49 -> 15182.163 | O49: =O92 -> 16390.475 | P49: =P92 -> 18237.018 | Q49: =Q92 -> 20092.296 | R49: =R92 -> 22769.334 | S49: =S92 -> 24414.272 | T49: =T92 -> 27054.91 | U49: =U92 -> 29767.677 | V49: =V92 -> 33367.461 | ... AH49: =AH92 -> 67051.233
B50: Net PP&E | L50: 35699.125 | N50: =+M50+L50 -> 35699.125 | O50: =+O82 -> 36031.269 | P50: =+P82 -> 36418.929 | Q50: =+Q82 -> 36872.071 | R50: =+R82 -> 37397.717 | S50: =+S82 -> 38002.607 | T50: =+T82 -> 38693.932 | U50: =+U82 -> 39479.317 | V50: =+V82 -> 40366.803 | ... AH50: =+AH82 -> 59307.169
B51: Prepaid Expenses | L51: 4374.0516 | N51: =+M51+L51 -> 4374.0516 | O51: =O73*O64 -> 5115.0153 | P51: =P73*P64 -> 5969.9595 | Q51: =Q73*Q64 -> 6978.3969 | R51: =R73*R64 -> 8094.9404 | S51: =S73*S64 -> 9315.3137 | T51: =T73*T64 -> 10646.403 | U51: =U73*U64 -> 12094.933 | V51: =V73*V64 -> 13667.275 | ... AH51: =AH73*AH64 -> 33602.295
B52: Deferred Commissions | L52: 7406.8 | N52: =+M52+L52 -> 7406.8 | O52: =Capitalizations!H9 -> 8449.5557 | P52: =Capitalizations!I9 -> 9619.5772 | Q52: =Capitalizations!J9 -> 10937.227 | R52: =Capitalizations!K9 -> 12426.126 | S52: =Capitalizations!L9 -> 13889.546 | T52: =Capitalizations!M9 -> 15482.77 | U52: =Capitalizations!N9 -> 17222.672 | V52: =Capitalizations!O9 -> 19128.321 | ... AH52: =Capitalizations!AA9 -> 41600.197
...

Sheet Billing Waterfall
AB2: $ in thousands, except noted
I3: =EOMONTH(#REF!, 3) -> #REF! | J3: =EOMONTH(I3, 3) -> #REF! | K3: =EOMONTH(J3, 3) -> #REF! | L3: =EOMONTH(K3, 3) -> #REF! | M3: =EOMONTH(L3, 3) -> #REF! | N3: =EOMONTH(M3, 3) -> #REF! | O3: =EOMONTH(N3, 3) -> #REF! | P3: =EOMONTH(O3, 3) -> #REF! | Q3: =EOMONTH(P3, 3) -> #REF! | ... AB3: =EOMONTH(AA3, 3) -> #REF!
I4: =EOMONTH(#REF!, 2)+1 -> #REF! | J4: =EOMONTH(I4, 2)+1 -> #REF! | K4: =EOMONTH(J4, 2)+1 -> #REF! | L4: =EOMONTH(K4, 2)+1 -> #REF! | M4: =EOMONTH(L4, 2)+1 -> #REF! | N4: =EOMONTH(M4, 2)+1 -> #REF! | O4: =EOMONTH(N4, 2)+1 -> #REF! | P4: =EOMONTH(O4, 2)+1 -> #REF! | Q4: =EOMONTH(P4, 2)+1 -> #REF! | ... AB4: =EOMONTH(AA4, 2)+1 -> #REF!
E5: =EOMONTH(F5, -3) -> 44651 | F5: =EOMONTH(G5, -3) -> 44742 | G5: =EOMONTH(H5, -3) -> 44834 | H5: =EOMONTH(I5, -3) -> 44926 | I5: =Model!O4 -> 45016 | J5: =EOMONTH(I5, 3) -> 45107 | K5: =EOMONTH(J5, 3) -> 45199 | L5: =EOMONTH(K5, 3) -> 45291 | M5: =EOMONTH(L5, 3) -> 45382 | N5: =EOMONTH(M5, 3) -> 45473 | O5: =EOMONTH(N5, 3) -> 45565 | P5: =EOMONTH(O5, 3) -> 45657 | Q5: =EOMONTH(P5, 3) -> 45747 | ... AB5: =EOMONTH(AA5, 3) -> 46752
B6: ARR Eligible for Billings
B7: Prior Year Renewal ARR | E7: 5660.477 | F7: 6828.9072 | G7: 8507.6607 | H7: 10270.13 | I7: =+E12 -> 11732.08 | J7: =+F12 -> 15085.88 | K7: =+G12 -> 16109.181 | L7: =+H12 -> 22545.355 | M7: =+I12 -> 23180.28 | N7: =+J12 -> 28365.792 | O7: =+K12 -> 31513.879 | P7: =+L12 -> 40414.805 | ... AB7: =+X12 -> 110643.6
B8: New Logo ARR | E8: ='ARR Waterfall'!K7 -> 2938.65 | F8: ='ARR Waterfall'!L7 -> 4775.55 | G8: ='ARR Waterfall'!M7 -> 4969.35 | H8: ='ARR Waterfall'!N7 -> 6157.89 | I8: ='ARR Waterfall'!O7 -> 8586.15 | J8: ='ARR Waterfall'!P7 -> 9959.934 | K8: ='ARR Waterfall'!Q7 -> 11553.523 | L8: ='ARR Waterfall'!R7 -> 13402.087 | ... AB8: ='ARR Waterfall'!AH7 -> 26900.556
B9: Upsell ARR | E9: ='ARR Waterfall'!K8 -> 4008.832 | F9: ='ARR Waterfall'!L8 -> 4671.897 | G9: ='ARR Waterfall'!M8 -> 4734.5702 | H9: ='ARR Waterfall'!N8 -> 7403.581 | I9: ='ARR Waterfall'!O8 -> 5724.1 | J9: ='ARR Waterfall'!P8 -> 6639.956 | K9: ='ARR Waterfall'!Q8 -> 7702.349 | L9: ='ARR Waterfall'!R8 -> 8934.7248 | ... AB9: ='ARR Waterfall'!AH8 -> 17933.704
B10: Downsell ARR | E10: ='ARR Waterfall'!K9 -> -379.4445 | F10: ='ARR Waterfall'!L9 -> -407.0975 | G10: ='ARR Waterfall'!M9 -> -880.041 | H10: ='ARR Waterfall'!N9 -> -556.12475 | I10: ='ARR Waterfall'!O9 -> -1431.025 | J10: ='ARR Waterfall'!P9 -> -1659.989 | K10: ='ARR Waterfall'!Q9 -> -1925.5872 | L10: ='ARR Waterfall'!R9 -> -2233.6812 | ... AB10: ='ARR Waterfall'!AH9 -> -8966.852
B11: Churn ARR | E11: ='ARR Waterfall'!K10 -> -496.4345 | F11: ='ARR Waterfall'!L10 -> -783.3765 | G11: ='ARR Waterfall'!M10 -> -1222.3585 | H11: ='ARR Waterfall'!N10 -> -730.1215 | I11: ='ARR Waterfall'!O10 -> -1431.025 | J11: ='ARR Waterfall'!P10 -> -1659.989 | K11: ='ARR Waterfall'!Q10 -> -1925.5872 | L11: ='ARR Waterfall'!R10 -> -2233.6812 | ... AB11: ='ARR Waterfall'!AH10 -> -8966.852
B12: ARR Eligible for Billing | E12: =SUM(E7:E11) -> 11732.08 | F12: =SUM(F7:F11) -> 15085.88 | G12: =SUM(G7:G11) -> 16109.181 | H12: =SUM(H7:H11) -> 22545.355 | I12: =SUM(I7:I11) -> 23180.28 | J12: =SUM(J7:J11) -> 28365.792 | K12: =SUM(K7:K11) -> 31513.879 | L12: =SUM(L7:L11) -> 40414.805 | ... AB12: =SUM(AB7:AB11) -> 137544.15
B14: Upfront (Annual) Billing
B15: Cohort | C15: $ Eligible | D15: Cohort %
B16: {=TRANSPOSE(E5:AB5)} -> 44651 | C16: {=TRANSPOSE(E12:AB12)} -> 11732.08 | D16: 0.2 | E16: =$C16*$D16 -> 2346.416
B17: 44742 | C17: 15085.88 | D17: =+D16 -> 0.2 | F17: =$C17*$D17 -> 3017.1761
B18: 44834 | C18: 16109.181 | D18: =+D17 -> 0.2 | G18: =$C18*$D18 -> 3221.8363
B19: 44926 | C19: 22545.355 | D19: =+D18 -> 0.2 | H19: =$C19*$D19 -> 4509.071
B20: 45016 | C20: 23180.28 | D20: =+D19 -> 0.2 | I20: =$C20*$D20 -> 4636.056
B21: 45107 | C21: 28365.792 | D21: =+D20 -> 0.2 | J21: =$C21*$D21 -> 5673.1585
B22: 45199 | C22: 31513.879 | D22: =+D21 -> 0.2 | K22: =$C22*$D22 -> 6302.7759
B23: 45291 | C23: 40414.805 | D23: =+D22 -> 0.2 | L23: =$C23*$D23 -> 8082.961
B24: 45382 | C24: 40022.236 | D24: =+D23 -> 0.2 | M24: =$C24*$D24 -> 8004.4473
B25: 45473 | C25: 47397.203 | D25: =+D24 -> 0.2 | N25: =$C25*$D25 -> 9479.4406
B26: 45565 | C26: 53019.373 | D26: =+D25 -> 0.2 | O26: =$C26*$D26 -> 10603.875
B27: 45657 | C27: 64716.013 | D27: =+D26 -> 0.2 | P27: =$C27*$D27 -> 12943.203
B28: 45747 | C28: 59033.258 | D28: =+D27 -> 0.2 | Q28: =$C28*$D28 -> 11806.652
B29: 45838 | C29: 68119.217 | D29: =+D28 -> 0.2 | R29: =$C29*$D29 -> 13623.843
B30: 45930 | C30: 75606.369 | D30: =+D29 -> 0.2 | S30: =$C30*$D30 -> 15121.274
B31: 46022 | C31: 89335.838 | D31: =+D30 -> 0.2 | T31: =$C31*$D31 -> 17867.168
B32: 46112 | C32: 76923.665 | D32: =+D31 -> 0.2 | U32: =$C32*$D32 -> 15384.733
B33: 46203 | C33: 87083.048 | D33: =+D32 -> 0.2 | V33: =$C33*$D33 -> 17416.61
B34: 46295 | C34: 95708.029 | D34: =+D33 -> 0.2 | W34: =$C34*$D34 -> 19141.606
B35: 46387 | C35: 110643.6 | D35: =+D34 -> 0.2 | X35: =$C35*$D35 -> 22128.72
B36: 46477 | C36: 99509.89 | D36: =+D35 -> 0.2 | Y36: =$C36*$D36 -> 19901.978
B37: 46568 | C37: 111024.45 | D37: =+D36 -> 0.2 | Z37: =$C37*$D37 -> 22204.889
B38: 46660 | C38: 121085.91 | D38: =+D37 -> 0.2 | AA38: =$C38*$D38 -> 24217.182
B39: 46752 | C39: 137544.15 | D39: =+D38 -> 0.2 | AB39: =$C39*$D39 -> 27508.831
B42: Quarterly Billing
B43: Cohort | C43: $ Eligible | D43: Cohort %
B44: =+B16 -> 44651 | C44: =+C16 -> 11732.08 | D44: =1-D16 -> 0.8 | E44: =$C44*$D44/4 -> 2346.416 | F44: =$C44*$D44/4 -> 2346.416 | G44: =$C44*$D44/4 -> 2346.416 | H44: =$C44*$D44/4 -> 2346.416
...

Sheet Capitalizations
AA2: $ in thousands, except noted
G3: 44926 | H3: =EOMONTH(G3, 3) -> 45016 | I3: =EOMONTH(H3, 3) -> 45107 | J3: =EOMONTH(I3, 3) -> 45199 | K3: =EOMONTH(J3, 3) -> 45291 | L3: =EOMONTH(K3, 3) -> 45382 | M3: =EOMONTH(L3, 3) -> 45473 | N3: =EOMONTH(M3, 3) -> 45565 | O3: =EOMONTH(N3, 3) -> 45657 | ... AA3: =EOMONTH(Z3, 3) -> 46752
B4: Deferred Commissions
B5: Balance Sheet
B6: Beginning Deferred Commissions | H6: =+G9 -> 7406.8 | I6: =+H9 -> 8449.5557 | J6: =+I9 -> 9619.5772 | K6: =+J9 -> 10937.227 | L6: =+K9 -> 12426.126 | M6: =+L9 -> 13889.546 | N6: =+M9 -> 15482.77 | O6: =+N9 -> 17222.672 | ... AA6: =+Z9 -> 39562.707
B7: New Deferred Commissions | H7: =+H12*H13 -> 1659.989 | I7: =+I12*I13 -> 1925.5872 | J7: =+J12*J13 -> 2233.6812 | K7: =+K12*K13 -> 2591.0702 | L7: =+L12*L13 -> 2781.5139 | M7: =+M12*M13 -> 3143.1107 | N7: =+N12*N13 -> 3551.715 | O7: =+O12*O13 -> 4013.438 | ... AA7: =+AA12*AA13 -> 7603.8905
B8: Amortization of Deferred Commissions | H8: =+-H39 -> -617.23333 | I8: =+-I39 -> -755.56575 | J8: =+-J39 -> -916.03135 | K8: =+-K39 -> -1102.1715 | L8: =+-L39 -> -1318.094 | M8: =+-M39 -> -1549.8868 | N8: =+-N39 -> -1811.8127 | O8: =+-O39 -> -2107.7889 | ... AA8: =+-AA39 -> -5566.4002
B9: Ending Deferred Commissions | G9: =Model!N52 -> 7406.8 | H9: =SUM(H6:H8) -> 8449.5557 | I9: =SUM(I6:I8) -> 9619.5772 | J9: =SUM(J6:J8) -> 10937.227 | K9: =SUM(K6:K8) -> 12426.126 | L9: =SUM(L6:L8) -> 13889.546 | M9: =SUM(M6:M8) -> 15482.77 | N9: =SUM(N6:N8) -> 17222.672 | O9: =SUM(O6:O8) -> 19128.321 | ... AA9: =SUM(AA6:AA8) -> 41600.197
B11: Memo/Drivers:
B12: Total S&M Expense | H12: =Model!O20 -> 8299.945 | I12: =Model!P20 -> 9627.9362 | J12: =Model!Q20 -> 11168.406 | K12: =Model!R20 -> 12955.351 | L12: =Model!S20 -> 13907.569 | M12: =Model!T20 -> 15715.553 | N12: =Model!U20 -> 17758.575 | O12: =Model!V20 -> 20067.19 | ... AA12: =Model!AH20 -> 38019.453
B13: Deferred Comp as % of Total S&M Expense | H13: 0.2 | I13: 0.2 | J13: 0.2 | K13: 0.2 | L13: 0.2 | M13: 0.2 | N13: 0.2 | O13: 0.2 | P13: 0.2 | Q13: 0.2 | R13: 0.2 | S13: 0.2 | T13: 0.2 | U13: 0.2 | V13: 0.2 | W13: 0.2 | X13: 0.2 | Y13: 0.2 | Z13: 0.2 | AA13: 0.2
B15: Amortization Schedule
B16: Cohort | C16: $ Deferrals | D16: Years | E16: Quarters | F16: End
B17: {=TRANSPOSE(G3:AA3)} -> 44926 | C17: =G9 -> 7406.8 | D17: 3 | E17: =+D17*4 -> 12 | F17: =EOMONTH(B17, D17*12) -> 46022 | H17: =$C17/$E17 -> 617.23333 | I17: =$C17/$E17 -> 617.23333 | J17: =$C17/$E17 -> 617.23333 | K17: =$C17/$E17 -> 617.23333 | L17: =$C17/$E17 -> 617.23333 | M17: =$C17/$E17 -> 617.23333 | N17: =$C17/$E17 -> 617.23333 | O17: =$C17/$E17 -> 617.23333 | ... S17: =$C17/$E17 -> 617.23333
B18: 45016 | C18: {=TRANSPOSE(H7:AA7)} -> 1659.989 | D18: 3 | E18: =+D18*4 -> 12 | F18: =EOMONTH(B18, D18*12) -> 46112 | I18: =$C18/$E18 -> 138.33242 | J18: =$C18/$E18 -> 138.33242 | K18: =$C18/$E18 -> 138.33242 | L18: =$C18/$E18 -> 138.33242 | M18: =$C18/$E18 -> 138.33242 | N18: =$C18/$E18 -> 138.33242 | O18: =$C18/$E18 -> 138.33242 | P18: =$C18/$E18 -> 138.33242 | ... T18: =$C18/$E18 -> 138.33242
B19: 45107 | C19: 1925.5872 | D19: 3 | E19: =+D19*4 -> 12 | F19: =EOMONTH(B19, D19*12) -> 46203 | J19: =$C19/$E19 -> 160.4656 | K19: =$C19/$E19 -> 160.4656 | L19: =$C19/$E19 -> 160.4656 | M19: =$C19/$E19 -> 160.4656 | N19: =$C19/$E19 -> 160.4656 | O19: =$C19/$E19 -> 160.4656 | P19: =$C19/$E19 -> 160.4656 | Q19: =$C19/$E19 -> 160.4656 | ... U19: =$C19/$E19 -> 160.4656
B20: 45199 | C20: 2233.6812 | D20: 3 | E20: =+D20*4 -> 12 | F20: =EOMONTH(B20, D20*12) -> 46295 | K20: =$C20/$E20 -> 186.1401 | L20: =$C20/$E20 -> 186.1401 | M20: =$C20/$E20 -> 186.1401 | N20: =$C20/$E20 -> 186.1401 | O20: =$C20/$E20 -> 186.1401 | P20: =$C20/$E20 -> 186.1401 | Q20: =$C20/$E20 -> 186.1401 | R20: =$C20/$E20 -> 186.1401 | ... V20: =$C20/$E20 -> 186.1401
B21: 45291 | C21: 2591.0702 | D21: 3 | E21: =+D21*4 -> 12 | F21: =EOMONTH(B21, D21*12) -> 46387 | L21: =$C21/$E21 -> 215.92252 | M21: =$C21/$E21 -> 215.92252 | N21: =$C21/$E21 -> 215.92252 | O21: =$C21/$E21 -> 215.92252 | P21: =$C21/$E21 -> 215.92252 | Q21: =$C21/$E21 -> 215.92252 | R21: =$C21/$E21 -> 215.92252 | S21: =$C21/$E21 -> 215.92252 | ... W21: =$C21/$E21 -> 215.92252
B22: 45382 | C22: 2781.5139 | D22: 3 | E22: =+D22*4 -> 12 | F22: =EOMONTH(B22, D22*12) -> 46477 | M22: =$C22/$E22 -> 231.79282 | N22: =$C22/$E22 -> 231.79282 | O22: =$C22/$E22 -> 231.79282 | P22: =$C22/$E22 -> 231.79282 | Q22: =$C22/$E22 -> 231.79282 | R22: =$C22/$E22 -> 231.79282 | S22: =$C22/$E22 -> 231.79282 | T22: =$C22/$E22 -> 231.79282 | ... X22: =$C22/$E22 -> 231.79282
B23: 45473 | C23: 3143.1107 | D23: 3 | E23: =+D23*4 -> 12 | F23: =EOMONTH(B23, D23*12) -> 46568 | N23: =$C23/$E23 -> 261.92589 | O23: =$C23/$E23 -> 261.92589 | P23: =$C23/$E23 -> 261.92589 | Q23: =$C23/$E23 -> 261.92589 | R23: =$C23/$E23 -> 261.92589 | S23: =$C23/$E23 -> 261.92589 | T23: =$C23/$E23 -> 261.92589 | U23: =$C23/$E23 -> 261.92589 | ... Y23: =$C23/$E23 -> 261.92589
B24: 45565 | C24: 3551.715 | D24: 3 | E24: =+D24*4 -> 12 | F24: =EOMONTH(B24, D24*12) -> 46660 | O24: =$C24/$E24 -> 295.97625 | P24: =$C24/$E24 -> 295.97625 | Q24: =$C24/$E24 -> 295.97625 | R24: =$C24/$E24 -> 295.97625 | S24: =$C24/$E24 -> 295.97625 | T24: =$C24/$E24 -> 295.97625 | U24: =$C24/$E24 -> 295.97625 | V24: =$C24/$E24 -> 295.97625 | ... Z24: =$C24/$E24 -> 295.97625
B25: 45657 | C25: 4013.438 | D25: 3 | E25: =+D25*4 -> 12 | F25: =EOMONTH(B25, D25*12) -> 46752 | P25: =$C25/$E25 -> 334.45317 | Q25: =$C25/$E25 -> 334.45317 | R25: =$C25/$E25 -> 334.45317 | S25: =$C25/$E25 -> 334.45317 | T25: =$C25/$E25 -> 334.45317 | U25: =$C25/$E25 -> 334.45317 | V25: =$C25/$E25 -> 334.45317 | W25: =$C25/$E25 -> 334.45317 | ... AA25: =$C25/$E25 -> 334.45317
B26: 45747 | C26: 4144.4028 | D26: 3 | E26: =+D26*4 -> 12 | F26: =EOMONTH(B26, D26*12) -> 46843 | Q26: =$C26/$E26 -> 345.3669 | R26: =$C26/$E26 -> 345.3669 | S26: =$C26/$E26 -> 345.3669 | T26: =$C26/$E26 -> 345.3669 | U26: =$C26/$E26 -> 345.3669 | V26: =$C26/$E26 -> 345.3669 | W26: =$C26/$E26 -> 345.3669 | X26: =$C26/$E26 -> 345.3669 | ... AA26: =$C26/$E26 -> 345.3669
B27: 45838 | C27: 4517.3991 | D27: 3 | E27: =+D27*4 -> 12 | F27: =EOMONTH(B27, D27*12) -> 46934 | R27: =$C27/$E27 -> 376.44992 | S27: =$C27/$E27 -> 376.44992 | T27: =$C27/$E27 -> 376.44992 | U27: =$C27/$E27 -> 376.44992 | V27: =$C27/$E27 -> 376.44992 | W27: =$C27/$E27 -> 376.44992 | X27: =$C27/$E27 -> 376.44992 | Y27: =$C27/$E27 -> 376.44992 | ... AA27: =$C27/$E27 -> 376.44992
B28: 45930 | C28: 4923.965 | D28: 3 | E28: =+D28*4 -> 12 | F28: =EOMONTH(B28, D28*12) -> 47026 | S28: =$C28/$E28 -> 410.33042 | T28: =$C28/$E28 -> 410.33042 | U28: =$C28/$E28 -> 410.33042 | V28: =$C28/$E28 -> 410.33042 | W28: =$C28/$E28 -> 410.33042 | X28: =$C28/$E28 -> 410.33042 | Y28: =$C28/$E28 -> 410.33042 | Z28: =$C28/$E28 -> 410.33042 | AA28: =$C28/$E28 -> 410.33042
B29: 46022 | C29: 5367.1218 | D29: 3 | E29: =+D29*4 -> 12 | F29: =EOMONTH(B29, D29*12) -> 47118 | T29: =$C29/$E29 -> 447.26015 | U29: =$C29/$E29 -> 447.26015 | V29: =$C29/$E29 -> 447.26015 | W29: =$C29/$E29 -> 447.26015 | X29: =$C29/$E29 -> 447.26015 | Y29: =$C29/$E29 -> 447.26015 | Z29: =$C29/$E29 -> 447.26015 | AA29: =$C29/$E29 -> 447.26015
B30: 46112 | C30: 5373.0853 | D30: 3 | E30: =+D30*4 -> 12 | F30: =EOMONTH(B30, D30*12) -> 47208 | U30: =$C30/$E30 -> 447.75711 | V30: =$C30/$E30 -> 447.75711 | W30: =$C30/$E30 -> 447.75711 | X30: =$C30/$E30 -> 447.75711 | Y30: =$C30/$E30 -> 447.75711 | Z30: =$C30/$E30 -> 447.75711 | AA30: =$C30/$E30 -> 447.75711
B31: 46203 | C31: 5695.4704 | D31: 3 | E31: =+D31*4 -> 12 | F31: =EOMONTH(B31, D31*12) -> 47299 | V31: =$C31/$E31 -> 474.62254 | W31: =$C31/$E31 -> 474.62254 | X31: =$C31/$E31 -> 474.62254 | Y31: =$C31/$E31 -> 474.62254 | Z31: =$C31/$E31 -> 474.62254 | AA31: =$C31/$E31 -> 474.62254
B32: 46295 | C32: 6037.1987 | D32: 3 | E32: =+D32*4 -> 12 | F32: =EOMONTH(B32, D32*12) -> 47391 | W32: =$C32/$E32 -> 503.09989 | X32: =$C32/$E32 -> 503.09989 | Y32: =$C32/$E32 -> 503.09989 | Z32: =$C32/$E32 -> 503.09989 | AA32: =$C32/$E32 -> 503.09989
B33: 46387 | C33: 6399.4306 | D33: 3 | E33: =+D33*4 -> 12 | F33: =EOMONTH(B33, D33*12) -> 47483 | X33: =$C33/$E33 -> 533.28588 | Y33: =$C33/$E33 -> 533.28588 | Z33: =$C33/$E33 -> 533.28588 | AA33: =$C33/$E33 -> 533.28588
B34: 46477 | C34: 6384.3731 | D34: 3 | E34: =+D34*4 -> 12 | F34: =EOMONTH(B34, D34*12) -> 47573 | Y34: =$C34/$E34 -> 532.03109 | Z34: =$C34/$E34 -> 532.03109 | AA34: =$C34/$E34 -> 532.03109
B35: 46568 | C35: 6767.4355 | D35: 3 | E35: =+D35*4 -> 12 | F35: =EOMONTH(B35, D35*12) -> 47664 | Z35: =$C35/$E35 -> 563.95296 | AA35: =$C35/$E35 -> 563.95296
B36: 46660 | C36: 7173.4816 | D36: 3 | E36: =+D36*4 -> 12 | F36: =EOMONTH(B36, D36*12) -> 47756 | AA36: =$C36/$E36 -> 597.79013
B37: 46752 | C37: 7603.8905 | D37: 3 | E37: =+D37*4 -> 12 | F37: =EOMONTH(B37, D37*12) -> 47848
B39: Amortization of Deferred Compensation | H39: =SUM(H17:H38) -> 617.23333 | I39: =SUM(I17:I38) -> 755.56575 | J39: =SUM(J17:J38) -> 916.03135 | K39: =SUM(K17:K38) -> 1102.1715 | L39: =SUM(L17:L38) -> 1318.094 | M39: =SUM(M17:M38) -> 1549.8868 | N39: =SUM(N17:N38) -> 1811.8127 | O39: =SUM(O17:O38) -> 2107.7889 | ... AA39: =SUM(AA17:AA38) -> 5566.4002
B44: Capitalized Software Costs
B45: Balance Sheet
B46: Beginning Capitalized Software Costs | H46: =+G49 -> 2955.4587 | I46: =+H49 -> 3417.7317 | J46: =+I49 -> 3947.1098 | K46: =+J49 -> 4554.3297 | L46: =+K49 -> 5251.8462 | M46: =+L49 -> 5974.3018 | N46: =+M49 -> 6778.7388 | O46: =+N49 -> 7675.8149 | ... AA46: =+Z49 -> 20660.222
B47: New Capitalized Software Costs | H47: =H52*H53 -> 610.04596 | I47: =I52*I53 -> 707.65331 | J47: =J52*J53 -> 820.87784 | K47: =K52*K53 -> 952.2183 | L47: =L52*L53 -> 1024.7683 | M47: =M52*M53 -> 1157.9881 | N47: =N52*N53 -> 1308.5266 | O47: =O52*O53 -> 1478.6351 | ... AA47: =AA52*AA53 -> 2827.6968
B48: Amortization of Capitalized Software Costs | H48: =-H78 -> -147.77293 | I48: =-I78 -> -178.27523 | J48: =-J78 -> -213.6579 | K48: =-K78 -> -254.70179 | L48: =-L78 -> -302.3127 | M48: =-M78 -> -353.55112 | N48: =-N78 -> -411.45052 | O48: =-O78 -> -476.87685 | ... AA48: =-AA78 -> -1714.3712
...

Sheet SaaS Metrics
B2: Key Metrics | AH2: $ in thousands, except noted
C3: =YEAR(C4) -> 2020 | D3: =YEAR(D4) -> 2020 | E3: =YEAR(E4) -> 2020 | F3: =YEAR(F4) -> 2020 | G3: =YEAR(G4) -> 2021 | H3: =YEAR(H4) -> 2021 | I3: =YEAR(I4) -> 2021 | J3: =YEAR(J4) -> 2021 | ... AH3: =YEAR(AH4) -> 2027
C4: ='ARR Waterfall'!C4 -> 43921 | D4: =EOMONTH(C4, 3) -> 44012 | E4: =EOMONTH(D4, 3) -> 44104 | F4: =EOMONTH(E4, 3) -> 44196 | G4: =EOMONTH(F4, 3) -> 44286 | H4: =EOMONTH(G4, 3) -> 44377 | I4: =EOMONTH(H4, 3) -> 44469 | J4: =EOMONTH(I4, 3) -> 44561 | K4: =EOMONTH(J4, 3) -> 44651 | ... AH4: =EOMONTH(AG4, 3) -> 46752
B5: =+'ARR Waterfall'!B5 -> ARR Build
B6: =+'ARR Waterfall'!B6 -> Beginning ARR | C6: =+'ARR Waterfall'!C6 -> 6783.5742 | D6: =+'ARR Waterfall'!D6 -> 8563.9987 | E6: =+'ARR Waterfall'!E6 -> 10870.48 | F6: =+'ARR Waterfall'!F6 -> 12868.786 | G6: =+'ARR Waterfall'!G6 -> 17227.514 | H6: =+'ARR Waterfall'!H6 -> 20583.553 | I6: =+'ARR Waterfall'!I6 -> 24832.39 | ... AH6: =+'ARR Waterfall'!AH6 -> 448342.6
B7: =+'ARR Waterfall'!B7 -> New Logo ARR | C7: =+'ARR Waterfall'!C7 -> 1389.75 | D7: =+'ARR Waterfall'!D7 -> 1457.7 | E7: =+'ARR Waterfall'!E7 -> 1443.9 | F7: =+'ARR Waterfall'!F7 -> 2939.85 | G7: =+'ARR Waterfall'!G7 -> 1869.3 | H7: =+'ARR Waterfall'!H7 -> 2653.5 | I7: =+'ARR Waterfall'!I7 -> 3860.4 | ... AH7: =+'ARR Waterfall'!AH7 -> 26900.556
B8: =+'ARR Waterfall'!B8 -> Upsell ARR | C8: =+'ARR Waterfall'!C8 -> 575.678 | D8: =+'ARR Waterfall'!D8 -> 994.191 | E8: =+'ARR Waterfall'!E8 -> 955.39325 | F8: =+'ARR Waterfall'!F8 -> 1583.759 | G8: =+'ARR Waterfall'!G8 -> 1911.3585 | H8: =+'ARR Waterfall'!H8 -> 2160.428 | I8: =+'ARR Waterfall'!I8 -> 2432.2903 | ... AH8: =+'ARR Waterfall'!AH8 -> 17933.704
B9: =+'ARR Waterfall'!B9 -> Downsell ARR | C9: =+'ARR Waterfall'!C9 -> -116.0035 | D9: =+'ARR Waterfall'!D9 -> -145.40925 | E9: =+'ARR Waterfall'!E9 -> -189.91525 | F9: =+'ARR Waterfall'!F9 -> -164.88125 | G9: =+'ARR Waterfall'!G9 -> -208.328 | H9: =+'ARR Waterfall'!H9 -> -403.57425 | I9: =+'ARR Waterfall'!I9 -> -188.13225 | ... AH9: =+'ARR Waterfall'!AH9 -> -8966.852
B10: =+'ARR Waterfall'!B10 -> Churn ARR | C10: =+'ARR Waterfall'!C10 -> -69 | D10: =+'ARR Waterfall'!D10 -> 0 | E10: =+'ARR Waterfall'!E10 -> -211.0725 | F10: =+'ARR Waterfall'!F10 -> 0 | G10: =+'ARR Waterfall'!G10 -> -216.2915 | H10: =+'ARR Waterfall'!H10 -> -161.5165 | I10: =+'ARR Waterfall'!I10 -> 0 | ... AH10: =+'ARR Waterfall'!AH10 -> -8966.852
B11: =+'ARR Waterfall'!B11 -> Ending ARR | C11: =+'ARR Waterfall'!C11 -> 8563.9987 | D11: =+'ARR Waterfall'!D11 -> 10870.48 | E11: =+'ARR Waterfall'!E11 -> 12868.786 | F11: =+'ARR Waterfall'!F11 -> 17227.514 | G11: =+'ARR Waterfall'!G11 -> 20583.553 | H11: =+'ARR Waterfall'!H11 -> 24832.39 | I11: =+'ARR Waterfall'!I11 -> 30936.948 | ... AH11: =+'ARR Waterfall'!AH11 -> 475243.16
B13: =+'ARR Waterfall'!B20 -> Customer Bridge
B14: =+'ARR Waterfall'!B21 -> Beginning Customers | C14: =+'ARR Waterfall'!C21 -> 51 | D14: =+'ARR Waterfall'!D21 -> 63 | E14: =+'ARR Waterfall'!E21 -> 77 | F14: =+'ARR Waterfall'!F21 -> 89 | G14: =+'ARR Waterfall'!G21 -> 118 | H14: =+'ARR Waterfall'!H21 -> 135 | I14: =+'ARR Waterfall'!I21 -> 159 | ... AH14: =+'ARR Waterfall'!AH21 -> 3249.6923
B15: =+'ARR Waterfall'!B22 -> New Customers | C15: =+'ARR Waterfall'!C22 -> 13 | D15: =+'ARR Waterfall'!D22 -> 14 | E15: =+'ARR Waterfall'!E22 -> 13 | F15: =+'ARR Waterfall'!F22 -> 29 | G15: =+'ARR Waterfall'!G22 -> 18 | H15: =+'ARR Waterfall'!H22 -> 25 | I15: =+'ARR Waterfall'!I22 -> 37 | ... AH15: =+'ARR Waterfall'!AH22 -> 269.00556
B16: =+'ARR Waterfall'!B23 -> Churn Customers | C16: =+'ARR Waterfall'!C23 -> -1 | D16: =+'ARR Waterfall'!D23 -> 0 | E16: =+'ARR Waterfall'!E23 -> -1 | F16: =+'ARR Waterfall'!F23 -> 0 | G16: =+'ARR Waterfall'!G23 -> -1 | H16: =+'ARR Waterfall'!H23 -> -1 | I16: =+'ARR Waterfall'!I23 -> 0 | ... AH16: =+'ARR Waterfall'!AH23 -> -48.46947
B17: =+'ARR Waterfall'!B24 -> Ending Customers | C17: =+'ARR Waterfall'!C24 -> 63 | D17: =+'ARR Waterfall'!D24 -> 77 | E17: =+'ARR Waterfall'!E24 -> 89 | F17: =+'ARR Waterfall'!F24 -> 118 | G17: =+'ARR Waterfall'!G24 -> 135 | H17: =+'ARR Waterfall'!H24 -> 159 | I17: =+'ARR Waterfall'!I24 -> 196 | ... AH17: =+'ARR Waterfall'!AH24 -> 3470.2284
B20: Revenue & Retention
B21: YoY ARR Growth
B22: Ending ARR | C22: =+'ARR Waterfall'!C11 -> 8563.9987 | D22: =+'ARR Waterfall'!D11 -> 10870.48 | E22: =+'ARR Waterfall'!E11 -> 12868.786 | F22: =+'ARR Waterfall'!F11 -> 17227.514 | G22: =+'ARR Waterfall'!G11 -> 20583.553 | H22: =+'ARR Waterfall'!H11 -> 24832.39 | I22: =+'ARR Waterfall'!I11 -> 30936.948 | J22: =+'ARR Waterfall'!J11 -> 37345.929 | ... AH22: =+'ARR Waterfall'!AH11 -> 475243.16
B23: YoY ARR Growth | G23: =+G22/C22-1 -> 1.4034979 | H23: =+H22/D22-1 -> 1.2843875 | I23: =+I22/E22-1 -> 1.40403 | J23: =+J22/F22-1 -> 1.1678072 | K23: =+K22/G22-1 -> 1.1093313 | L23: =+L22/H22-1 -> 1.0809316 | M23: =+M22/I22-1 -> 0.91602693 | N23: =+N22/J22-1 -> 0.91590496 | ... AH23: =+AH22/AD22-1 -> 0.26247696
B25: Retention
B26: Annualized Net Dollar Retention | C26: {=1+((SUM(C8:C10/C6)*4))} -> 1.230365 | D26: {=1+((SUM(D8:D10/D6)*4))} -> 1.3964418 | E26: {=1+((SUM(E8:E10/E6)*4))} -> 1.204004 | F26: {=1+((SUM(F8:F10/F6)*4))} -> 1.4410292 | G26: {=1+((SUM(G8:G10/G6)*4))} -> 1.3452011 | H26: {=1+((SUM(H8:H10/H6)*4))} -> 1.3100217 | I26: {=1+((SUM(I8:I10/I6)*4))} -> 1.3614888 | J26: {=1+((SUM(J8:J10/J6)*4))} -> 1.2919817 | ... AH26: {=1+((SUM(AH8:AH10/AH6)*4))} -> 1
B27: Annualized Gross Dollar Retention | C27: =1+((SUM(C9:C10)/C6)*4) -> 0.8909109 | D27: =1+((SUM(D9:D10)/D6)*4) -> 0.93208348 | E27: =1+((SUM(E9:E10)/E6)*4) -> 0.85244893 | F27: =1+((SUM(F9:F10)/F6)*4) -> 0.94875002 | G27: =1+((SUM(G9:G10)/G6)*4) -> 0.90140899 | H27: =1+((SUM(H9:H10)/H6)*4) -> 0.89018596 | I27: =1+((SUM(I9:I10)/I6)*4) -> 0.96969567 | J27: =1+((SUM(J9:J10)/J6)*4) -> 0.92467234 | ... AH27: =1+((SUM(AH9:AH10)/AH6)*4) -> 0.84
B28: Annualized Logo Retention | C28: =1+((C16/C14)*4) -> 0.92156863 | D28: =1+((D16/D14)*4) -> 1 | E28: =1+((E16/E14)*4) -> 0.94805195 | F28: =1+((F16/F14)*4) -> 1 | G28: =1+((G16/G14)*4) -> 0.96610169 | H28: =1+((H16/H14)*4) -> 0.97037037 | I28: =1+((I16/I14)*4) -> 1 | J28: =1+((J16/J14)*4) -> 0.95918367 | ... AH28: =1+((AH16/AH14)*4) -> 0.94033962
B30: Quick Ratio
B31: New Logo ARR | C31: =+C7 -> 1389.75 | D31: =+D7 -> 1457.7 | E31: =+E7 -> 1443.9 | F31: =+F7 -> 2939.85 | G31: =+G7 -> 1869.3 | H31: =+H7 -> 2653.5 | I31: =+I7 -> 3860.4 | J31: =+J7 -> 4150.725 | ... AH31: =+AH7 -> 26900.556
B32: Upsell ARR | C32: =+C8 -> 575.678 | D32: =+D8 -> 994.191 | E32: =+E8 -> 955.39325 | F32: =+F8 -> 1583.759 | G32: =+G8 -> 1911.3585 | H32: =+H8 -> 2160.428 | I32: =+I8 -> 2432.2903 | J32: =+J8 -> 2840.8578 | ... AH32: =+AH8 -> 17933.704
B33: Downsell ARR | C33: =+C9 -> -116.0035 | D33: =+D9 -> -145.40925 | E33: =+E9 -> -189.91525 | F33: =+F9 -> -164.88125 | G33: =+G9 -> -208.328 | H33: =+H9 -> -403.57425 | I33: =+I9 -> -188.13225 | J33: =+J9 -> -271.31825 | ... AH33: =+AH9 -> -8966.852
B34: Churn ARR | C34: =+C10 -> -69 | D34: =+D10 -> 0 | E34: =+E10 -> -211.0725 | F34: =+F10 -> 0 | G34: =+G10 -> -216.2915 | H34: =+H10 -> -161.5165 | I34: =+I10 -> 0 | J34: =+J10 -> -311.28375 | ... AH34: =+AH10 -> -8966.852
B35: Quick Ratio | C35: =-SUM(C31:C32)/SUM(C33:C34) -> 10.623734 | D35: =-SUM(D31:D32)/SUM(D33:D34) -> 16.862002 | E35: =-SUM(E31:E32)/SUM(E33:E34) -> 5.9834577 | F35: =-SUM(F31:F32)/SUM(F33:F34) -> 27.435557 | G35: =-SUM(G31:G32)/SUM(G33:G34) -> 8.9036384 | H35: =-SUM(H31:H32)/SUM(H33:H34) -> 8.5188583 | I35: =-SUM(I31:I32)/SUM(I33:I34) -> 33.448227 | J35: =-SUM(J31:J32)/SUM(J33:J34) -> 12.000616 | ... AH35: =-SUM(AH31:AH32)/SUM(AH33:AH34) -> 2.5
B37: Efficiency
B38: Rule of 40
B39: LTM GAAP Revenue | C39: =SUM(Model!C8:C8) -> 2198.9787 | D39: =SUM(Model!C8:D8) -> 4983.2274 | E39: =SUM(Model!C8:E8) -> 8269.9118 | F39: =SUM(Model!C8:F8) -> 12657.565 | G39: =SUM(Model!D8:G8) -> 15695.075 | H39: =SUM(Model!E8:H8) -> 19211.929 | I39: =SUM(Model!F8:I8) -> 23758.791 | J39: =SUM(Model!G8:J8) -> 28798.994 | K39: =SUM(Model!H8:K8) -> 34494.682 | L39: =SUM(Model!I8:L8) -> 41160.248 | M39: =SUM(Model!J8:M8) -> 48151.127 | ... AH39: =SUM(Model!AE8:AH8) -> 436393.45
B40: LTM EBITDA | C40: =SUM(Model!C33:C33) -> 0 | D40: =SUM(Model!C33:D33) -> 0 | E40: =SUM(Model!C33:E33) -> 0 | F40: =SUM(Model!C33:F33) -> -2673.5242 | G40: =SUM(Model!D33:G33) -> -4657.9888 | H40: =SUM(Model!E33:H33) -> -7216.9039 | I40: =SUM(Model!F33:I33) -> -10399.313 | J40: =SUM(Model!G33:J33) -> -11136.521 | K40: =SUM(Model!H33:K33) -> -12526.681 | L40: =SUM(Model!I33:L33) -> -14696.282 | M40: =SUM(Model!J33:M33) -> -15010.053 | ... AH40: =SUM(Model!AE33:AH33) -> -41770.094
B41: YoY Growth | G41: =G39/C39-1 -> 6.1374382 | H41: =H39/D39-1 -> 2.8553185 | I41: =I39/E39-1 -> 1.8729195 | J41: =J39/F39-1 -> 1.2752397 | K41: =K39/G39-1 -> 1.197803 | L41: =L39/H39-1 -> 1.1424319 | M41: =M39/I39-1 -> 1.0266657 | N41: =N39/J39-1 -> 0.96573132 | ... AH41: =AH39/AD39-1 -> 0.26247696
B42: EBITDA Margin | G42: =G40/G39 -> -0.29678029 | H42: =H40/H39 -> -0.37564703 | I42: =I40/I39 -> -0.43770381 | J42: =J40/J39 -> -0.38669825 | K42: =K40/K39 -> -0.36314818 | L42: =L40/L39 -> -0.35705037 | M42: =M40/M39 -> -0.31172796 | N42: =N40/N39 -> -0.28725397 | ... AH42: =AH40/AH39 -> -0.095716593
B43: Rule of 40 | G43: =G41+G42 -> 5.840658 | H43: =H41+H42 -> 2.4796714 | I43: =I41+I42 -> 1.4352157 | J43: =J41+J42 -> 0.88854146 | K43: =K41+K42 -> 0.83465479 | L43: =L41+L42 -> 0.7853815 | M43: =M41+M42 -> 0.71493775 | N43: =N41+N42 -> 0.67847736 | ... AH43: =AH41+AH42 -> 0.16676037
B45: Magic Number
B46: New Logo ARR | D46: =+D7 -> 1457.7 | E46: =+E7 -> 1443.9 | F46: =+F7 -> 2939.85 | G46: =+G7 -> 1869.3 | H46: =+H7 -> 2653.5 | I46: =+I7 -> 3860.4 | J46: =+J7 -> 4150.725 | K46: =+K7 -> 2938.65 | ... AH46: =+AH7 -> 26900.556
B47: Upsell ARR | D47: =+D8 -> 994.191 | E47: =+E8 -> 955.39325 | F47: =+F8 -> 1583.759 | G47: =+G8 -> 1911.3585 | H47: =+H8 -> 2160.428 | I47: =+I8 -> 2432.2903 | J47: =+J8 -> 2840.8578 | K47: =+K8 -> 4008.832 | ... AH47: =+AH8 -> 17933.704
B48: Prior Period S&M | D48: =+Model!C20 -> 1200.0106 | E48: =+Model!D20 -> 1349.9439 | F48: =+Model!E20 -> 1491.0471 | G48: =+Model!F20 -> 1617.078 | H48: =+Model!G20 -> 1758.3879 | I48: =+Model!H20 -> 1902.2561 | J48: =+Model!I20 -> 2438.482 | K48: =+Model!J20 -> 2927.6113 | ... AH48: =+Model!AG20 -> 35867.408
...

Sheet Cohorts
A1: 1000
B2: Cohorts | O2: $ in thousands, except noted
D3: =EOMONTH(#REF!, 3) -> #REF! | E3: =EOMONTH(D3, 3) -> #REF! | F3: =EOMONTH(E3, 3) -> #REF! | G3: =EOMONTH(F3, 3) -> #REF! | H3: =EOMONTH(G3, 3) -> #REF! | I3: =EOMONTH(H3, 3) -> #REF! | J3: =EOMONTH(I3, 3) -> #REF! | K3: =EOMONTH(J3, 3) -> #REF! | L3: =EOMONTH(K3, 3) -> #REF! | ... O3: =EOMONTH(N3, 3) -> #REF!
D4: =EOMONTH(#REF!, 2)+1 -> #REF! | E4: =EOMONTH(D4, 2)+1 -> #REF! | F4: =EOMONTH(E4, 2)+1 -> #REF! | G4: =EOMONTH(F4, 2)+1 -> #REF! | H4: =EOMONTH(G4, 2)+1 -> #REF! | I4: =EOMONTH(H4, 2)+1 -> #REF! | J4: =EOMONTH(I4, 2)+1 -> #REF! | K4: =EOMONTH(J4, 2)+1 -> #REF! | L4: =EOMONTH(K4, 2)+1 -> #REF! | ... O4: =EOMONTH(N4, 2)+1 -> #REF!
D5: ='Raw Customer ARR'!D1 -> 43921 | E5: =EOMONTH(D5, 3) -> 44012 | F5: =EOMONTH(E5, 3) -> 44104 | G5: =EOMONTH(F5, 3) -> 44196 | H5: =EOMONTH(G5, 3) -> 44286 | I5: =EOMONTH(H5, 3) -> 44377 | J5: =EOMONTH(I5, 3) -> 44469 | K5: =EOMONTH(J5, 3) -> 44561 | L5: =EOMONTH(K5, 3) -> 44651 | ... O5: =EOMONTH(N5, 3) -> 44926
B6: ARR by Cohort
B7: {=TRANSPOSE(D5:O5)} -> 43921 | D7: =SUMIFS('Raw Customer ARR'!D$2:D$422, 'Raw Customer ARR'!$B$2:$B$422, Cohorts!$B7)/unit -> 8563.9988 | E7: =SUMIFS('Raw Customer ARR'!E$2:E$422, 'Raw Customer ARR'!$B$2:$B$422, Cohorts!$B7)/unit -> 9412.7805 | F7: =SUMIFS('Raw Customer ARR'!F$2:F$422, 'Raw Customer ARR'!$B$2:$B$422, Cohorts!$B7)/unit -> 9869.6385 | G7: =SUMIFS('Raw Customer ARR'!G$2:G$422, 'Raw Customer ARR'!$B$2:$B$422, Cohorts!$B7)/unit -> 10954.97 | H7: =SUMIFS('Raw Customer ARR'!H$2:H$422, 'Raw Customer ARR'!$B$2:$B$422, Cohorts!$B7)/unit -> 11939.255 | I7: =SUMIFS('Raw Customer ARR'!I$2:I$422, 'Raw Customer ARR'!$B$2:$B$422, Cohorts!$B7)/unit -> 12477.348 | J7: =SUMIFS('Raw Customer ARR'!J$2:J$422, 'Raw Customer ARR'!$B$2:$B$422, Cohorts!$B7)/unit -> 13802.687 | K7: =SUMIFS('Raw Customer ARR'!K$2:K$422, 'Raw Customer ARR'!$B$2:$B$422, Cohorts!$B7)/unit -> 14898.418 | ... O7: =SUMIFS('Raw Customer ARR'!O$2:O$422, 'Raw Customer ARR'!$B$2:$B$422, Cohorts!$B7)/unit -> 21666.762
B8: 44012 | D8: =SUMIFS('Raw Customer ARR'!D$2:D$422, 'Raw Customer ARR'!$B$2:$B$422, Cohorts!$B8)/unit -> 0 | E8: =SUMIFS('Raw Customer ARR'!E$2:E$422, 'Raw Customer ARR'!$B$2:$B$422, Cohorts!$B8)/unit -> 1457.7 | F8: =SUMIFS('Raw Customer ARR'!F$2:F$422, 'Raw Customer ARR'!$B$2:$B$422, Cohorts!$B8)/unit -> 1555.2475 | G8: =SUMIFS('Raw Customer ARR'!G$2:G$422, 'Raw Customer ARR'!$B$2:$B$422, Cohorts!$B8)/unit -> 1640.4162 | H8: =SUMIFS('Raw Customer ARR'!H$2:H$422, 'Raw Customer ARR'!$B$2:$B$422, Cohorts!$B8)/unit -> 1767.1488 | I8: =SUMIFS('Raw Customer ARR'!I$2:I$422, 'Raw Customer ARR'!$B$2:$B$422, Cohorts!$B8)/unit -> 1929.651 | J8: =SUMIFS('Raw Customer ARR'!J$2:J$422, 'Raw Customer ARR'!$B$2:$B$422, Cohorts!$B8)/unit -> 2118.0377 | K8: =SUMIFS('Raw Customer ARR'!K$2:K$422, 'Raw Customer ARR'!$B$2:$B$422, Cohorts!$B8)/unit -> 2317.1225 | ... O8: =SUMIFS('Raw Customer ARR'!O$2:O$422, 'Raw Customer ARR'!$B$2:$B$422, Cohorts!$B8)/unit -> 2707.4702
B9: 44104 | D9: =SUMIFS('Raw Customer ARR'!D$2:D$422, 'Raw Customer ARR'!$B$2:$B$422, Cohorts!$B9)/unit -> 0 | E9: =SUMIFS('Raw Customer ARR'!E$2:E$422, 'Raw Customer ARR'!$B$2:$B$422, Cohorts!$B9)/unit -> 0 | F9: =SUMIFS('Raw Customer ARR'!F$2:F$422, 'Raw Customer ARR'!$B$2:$B$422, Cohorts!$B9)/unit -> 1443.9 | G9: =SUMIFS('Raw Customer ARR'!G$2:G$422, 'Raw Customer ARR'!$B$2:$B$422, Cohorts!$B9)/unit -> 1692.2775 | H9: =SUMIFS('Raw Customer ARR'!H$2:H$422, 'Raw Customer ARR'!$B$2:$B$422, Cohorts!$B9)/unit -> 1800.8265 | I9: =SUMIFS('Raw Customer ARR'!I$2:I$422, 'Raw Customer ARR'!$B$2:$B$422, Cohorts!$B9)/unit -> 2044.897 | J9: =SUMIFS('Raw Customer ARR'!J$2:J$422, 'Raw Customer ARR'!$B$2:$B$422, Cohorts!$B9)/unit -> 2255.5147 | K9: =SUMIFS('Raw Customer ARR'!K$2:K$422, 'Raw Customer ARR'!$B$2:$B$422, Cohorts!$B9)/unit -> 2328.4815 | ... O9: =SUMIFS('Raw Customer ARR'!O$2:O$422, 'Raw Customer ARR'!$B$2:$B$422, Cohorts!$B9)/unit -> 2422.1962
B10: 44196 | D10: =SUMIFS('Raw Customer ARR'!D$2:D$422, 'Raw Customer ARR'!$B$2:$B$422, Cohorts!$B10)/unit -> 0 | E10: =SUMIFS('Raw Customer ARR'!E$2:E$422, 'Raw Customer ARR'!$B$2:$B$422, Cohorts!$B10)/unit -> 0 | F10: =SUMIFS('Raw Customer ARR'!F$2:F$422, 'Raw Customer ARR'!$B$2:$B$422, Cohorts!$B10)/unit -> 0 | G10: =SUMIFS('Raw Customer ARR'!G$2:G$422, 'Raw Customer ARR'!$B$2:$B$422, Cohorts!$B10)/unit -> 2939.85 | H10: =SUMIFS('Raw Customer ARR'!H$2:H$422, 'Raw Customer ARR'!$B$2:$B$422, Cohorts!$B10)/unit -> 3207.0222 | I10: =SUMIFS('Raw Customer ARR'!I$2:I$422, 'Raw Customer ARR'!$B$2:$B$422, Cohorts!$B10)/unit -> 3558.4857 | J10: =SUMIFS('Raw Customer ARR'!J$2:J$422, 'Raw Customer ARR'!$B$2:$B$422, Cohorts!$B10)/unit -> 3760.8792 | K10: =SUMIFS('Raw Customer ARR'!K$2:K$422, 'Raw Customer ARR'!$B$2:$B$422, Cohorts!$B10)/unit -> 3986.4198 | ... O10: =SUMIFS('Raw Customer ARR'!O$2:O$422, 'Raw Customer ARR'!$B$2:$B$422, Cohorts!$B10)/unit -> 5812.52
B11: 44286 | D11: =SUMIFS('Raw Customer ARR'!D$2:D$422, 'Raw Customer ARR'!$B$2:$B$422, Cohorts!$B11)/unit -> 0 | E11: =SUMIFS('Raw Customer ARR'!E$2:E$422, 'Raw Customer ARR'!$B$2:$B$422, Cohorts!$B11)/unit -> 0 | F11: =SUMIFS('Raw Customer ARR'!F$2:F$422, 'Raw Customer ARR'!$B$2:$B$422, Cohorts!$B11)/unit -> 0 | G11: =SUMIFS('Raw Customer ARR'!G$2:G$422, 'Raw Customer ARR'!$B$2:$B$422, Cohorts!$B11)/unit -> 0 | H11: =SUMIFS('Raw Customer ARR'!H$2:H$422, 'Raw Customer ARR'!$B$2:$B$422, Cohorts!$B11)/unit -> 1869.3 | I11: =SUMIFS('Raw Customer ARR'!I$2:I$422, 'Raw Customer ARR'!$B$2:$B$422, Cohorts!$B11)/unit -> 2168.5085 | J11: =SUMIFS('Raw Customer ARR'!J$2:J$422, 'Raw Customer ARR'!$B$2:$B$422, Cohorts!$B11)/unit -> 2347.2458 | K11: =SUMIFS('Raw Customer ARR'!K$2:K$422, 'Raw Customer ARR'!$B$2:$B$422, Cohorts!$B11)/unit -> 2586.914 | ... O11: =SUMIFS('Raw Customer ARR'!O$2:O$422, 'Raw Customer ARR'!$B$2:$B$422, Cohorts!$B11)/unit -> 3609.1748
B12: 44377 | D12: =SUMIFS('Raw Customer ARR'!D$2:D$422, 'Raw Customer ARR'!$B$2:$B$422, Cohorts!$B12)/unit -> 0 | E12: =SUMIFS('Raw Customer ARR'!E$2:E$422, 'Raw Customer ARR'!$B$2:$B$422, Cohorts!$B12)/unit -> 0 | F12: =SUMIFS('Raw Customer ARR'!F$2:F$422, 'Raw Customer ARR'!$B$2:$B$422, Cohorts!$B12)/unit -> 0 | G12: =SUMIFS('Raw Customer ARR'!G$2:G$422, 'Raw Customer ARR'!$B$2:$B$422, Cohorts!$B12)/unit -> 0 | H12: =SUMIFS('Raw Customer ARR'!H$2:H$422, 'Raw Customer ARR'!$B$2:$B$422, Cohorts!$B12)/unit -> 0 | I12: =SUMIFS('Raw Customer ARR'!I$2:I$422, 'Raw Customer ARR'!$B$2:$B$422, Cohorts!$B12)/unit -> 2653.5 | J12: =SUMIFS('Raw Customer ARR'!J$2:J$422, 'Raw Customer ARR'!$B$2:$B$422, Cohorts!$B12)/unit -> 2792.1833 | K12: =SUMIFS('Raw Customer ARR'!K$2:K$422, 'Raw Customer ARR'!$B$2:$B$422, Cohorts!$B12)/unit -> 2901.4828 | ... O12: =SUMIFS('Raw Customer ARR'!O$2:O$422, 'Raw Customer ARR'!$B$2:$B$422, Cohorts!$B12)/unit -> 3158.4428
B13: 44469 | D13: =SUMIFS('Raw Customer ARR'!D$2:D$422, 'Raw Customer ARR'!$B$2:$B$422, Cohorts!$B13)/unit -> 0 | E13: =SUMIFS('Raw Customer ARR'!E$2:E$422, 'Raw Customer ARR'!$B$2:$B$422, Cohorts!$B13)/unit -> 0 | F13: =SUMIFS('Raw Customer ARR'!F$2:F$422, 'Raw Customer ARR'!$B$2:$B$422, Cohorts!$B13)/unit -> 0 | G13: =SUMIFS('Raw Customer ARR'!G$2:G$422, 'Raw Customer ARR'!$B$2:$B$422, Cohorts!$B13)/unit -> 0 | H13: =SUMIFS('Raw Customer ARR'!H$2:H$422, 'Raw Customer ARR'!$B$2:$B$422, Cohorts!$B13)/unit -> 0 | I13: =SUMIFS('Raw Customer ARR'!I$2:I$422, 'Raw Customer ARR'!$B$2:$B$422, Cohorts!$B13)/unit -> 0 | J13: =SUMIFS('Raw Customer ARR'!J$2:J$422, 'Raw Customer ARR'!$B$2:$B$422, Cohorts!$B13)/unit -> 3860.4 | K13: =SUMIFS('Raw Customer ARR'!K$2:K$422, 'Raw Customer ARR'!$B$2:$B$422, Cohorts!$B13)/unit -> 4176.3655 | ... O13: =SUMIFS('Raw Customer ARR'!O$2:O$422, 'Raw Customer ARR'!$B$2:$B$422, Cohorts!$B13)/unit -> 5568.6332
