Workbook

Sheet Start ->

Sheet Model - Start
B2: Historical financials | J2: $ millions
B3: Income statement | C3: =+D3-1 -> -2 | D3: =+E3-1 -> -1 | E3: 0 | F3: 1 | G3: =F3+1 -> 2 | H3: =G3+1 -> 3 | I3: =H3+1 -> 4 | J3: =I3+1 -> 5
B4: Gross revenue | C4: 27.24 | D4: 13.08 | E4: 33.2
B6: Discounts | C6: 1.6344 | D6: 1.635 | E6: 2.7224
B7: Returns | C7: 2.1792 | D7: 1.59576 | E7: 2.6228
B8: Net revenue | C8: =C4-C6-C7 -> 23.4264 | D8: =D4-D6-D7 -> 9.84924 | E8: =E4-E6-E7 -> 27.8548
B10: Product cost | C10: 8.9254584 | D10: 3.9593945 | E10: 13.426014
B11: Freight, duties, & taxes | C11: 0.5622336 | D11: 0.3447234 | E11: 1.0584824
B12: COGS | C12: =C10+C11 -> 9.487692 | D12: =D10+D11 -> 4.3041179 | E12: =E10+E11 -> 14.484496
B14: Gross profit | C14: =C8-C12 -> 13.938708 | D14: =D8-D12 -> 5.5451221 | E14: =E8-E12 -> 13.370304
B16: Picking & packing | C16: 0.4919544 | D16: 0.20683404 | E16: 0.5849508
B17: Packaging material | C17: 0.117132 | D17: 0.03939696 | E17: 0.139274
B18: Shipping to customers | C18: 1.6164216 | D18: 0.738693 | E18: 2.0055456
B19: Merchant fees | C19: 0.7496448 | D19: 0.31517568 | E19: 0.8913536
B20: Fulfillment costs | C20: =SUM(C16:C19) -> 2.9751528 | D20: =SUM(D16:D19) -> 1.3000997 | E20: =SUM(E16:E19) -> 3.621124
B22: Contribution Profit | C22: =C14-C20 -> 10.963555 | D22: =D14-D20 -> 4.2450224 | E22: =E14-E20 -> 9.74918
B24: Ad spend | C24: 4.7087064 | D24: 1.477386 | E24: 6.26733
B25: Other marketing spend | C25: 0.351396 | D25: 0.0492462 | E25: 0.557096
B26: Marketing expenses | C26: =SUM(C24:C25) -> 5.0601024 | D26: =SUM(D24:D25) -> 1.5266322 | E26: =SUM(E24:E25) -> 6.824426
B28: Headcount | C28: 2 | D28: 1.2 | E28: 3.254902
B29: Research & development | C29: 0.234264 | D29: 0.0492462 | E29: 0.1671288
B30: General & administrative | C30: 1.17132 | D30: 0.7879392 | E30: 1.1699016
B31: Operating expenses | C31: =SUM(C28:C30) -> 3.405584 | D31: =SUM(D28:D30) -> 2.0371854 | E31: =SUM(E28:E30) -> 4.5919324
B33: EBITDA | C33: =+C22-C26-C31 -> 2.4978688 | D33: =+D22-D26-D31 -> 0.68120484 | E33: =+E22-E26-E31 -> -1.6671784
B36: Balance sheet | E36: 0 | F36: 1 | G36: =F36+1 -> 2 | H36: =G36+1 -> 3 | I36: =H36+1 -> 4 | J36: =I36+1 -> 5
B37: Cash | E37: 2.2
B38: Accounts receivable | E38: 0.12836384
B39: Inventory | E39: 2.5993677
B40: Prepaid expenses | E40: 0.468528
B41: Capitalized financing fees | E41: 0
B42: Goodwill | E42: 0
B43: Net PP&E | E43: 2.5
B44: Total assets | E44: =SUM(E37:E43) -> 7.8962595
B46: Accounts payable | E46: 1.2996838
B47: Accrued expenses | E47: 0.4743846
B48: Existing debt | E48: 0
B49: New debt | E49: 0
B50: Shareholder equity | E50: 6.1221911
B51: Total liabilities & equity | E51: =SUM(E46:E50) -> 7.8962595

Sheet End ->

Sheet Model - End
B2: Assumptions | J2: $ millions
B3: Entry assumptions | G3: Other assumptions
C4: Pre-Money | D4: Post-Money | E4: Assumptions | G4: Management option pool | J4: 0.05
B5: LTM revenue | C5: =E51 -> 27.8548 | G5: Founders - % shares sold | J5: 0.25
B6: Entry multiple | C6: 3 | G6: Investor 1 - % shares sold | J6: 0
B7: Enterprise value | C7: =C5*C6 -> 83.5644 | D7: =C7 -> 83.5644 | G7: Investor 2 - % shares sold | J7: 1
B8: (-) Existing debt | C8: =C135 -> 0 | D8: =D135 -> 0
B9: (-) New debt | C9: =+C136 -> 0 | D9: 0
B10: (+) Cash | C10: =C124 -> 2.2 | D10: 35
B11: Equity value | C11: =C7-C8+C10-C9 -> 85.7644 | D11: =D7-D8+D10-D9 -> 118.5644
B12: (+) Transaction fees | D12: =+E12*D7 -> 0 | E12: 0
B13: (+) Financing fees | D13: =+E13*D9 -> 0 | E13: 0
B14: Equity value (incl. fees) | D14: =+D11+D12+D13 -> 118.5644
B17: Sources & uses | J17: $ millions
B18: Sources | G18: Uses
B19: New debt | D19: =+D9 -> 0 | G19: Proceeds to selling shareholders | J19: =+SUM(D35:D37)-SUM(H35:H37) -> 18.760963
B20: Rollover equity | D20: =+J20 -> 67.003438 | G20: Rollover equity | J20: =SUM(H35:H37) -> 67.003438
B21: Sponsor equity | D21: =+J25-D20-D19 -> 51.560963 | G21: Cash added to B/S | J21: =+D10-C10 -> 32.8
G22: Transaction fees | J22: =+D12 -> 0
G23: Financing fees | J23: =+D13 -> 0
B25: Total sources | D25: =SUM(D19:D24) -> 118.5644 | G25: Total uses | J25: =SUM(J19:J24) -> 118.5644
B26: Check 1? | D26: =+D25-J25 -> 0
B27: Check 2? | D27: =+D21-H34 -> 0
B29: Capitalization table
D30: Pre-Money | H30: Post-Money
D31: $ Amount | E31: Shares | F31: FD own % | H31: $ Amount | I31: Shares | J31: FD own %
B32: Primary (incl. fees) | D32: =+E32*D$41/1000000 -> 0 | E32: 0 | F32: =+E32/E$39 -> 0 | H32: =+J21+J22+J23 -> 32.8 | I32: =+H32*1000000/H$41 -> 152977.23 | J32: =+I32/I$39 -> 0.26281076
B33: Secondary | D33: =+E33*D$41/1000000 -> 0 | E33: 0 | F33: =+E33/E$39 -> 0 | H33: =D35-H35+D36-H36+D37-H37 -> 18.760962 | I33: =+H33*1000000/H$41 -> 87500 | J33: =+I33/I$39 -> 0.15032265
B34: Total new sponsor | D34: =SUM(D32:D33) -> 0 | E34: =SUM(E32:E33) -> 0 | F34: =+E34/E$39 -> 0 | H34: =+SUM(H32:H33) -> 51.560962 | I34: =+H34*1000000/H$41 -> 240477.23 | J34: =+I34/I$39 -> 0.41313341
B35: Founders | D35: =+E35*D$41/1000000 -> 32.16165 | E35: 150000 | F35: =+E35/E$39 -> 0.375 | H35: =+I35*H$41/1000000 -> 24.121238 | I35: =+E35*(1-J5) -> 112500 | J35: =+I35/I$39 -> 0.19327197
B36: Investor 1 | D36: =+E36*D$41/1000000 -> 42.8822 | E36: 200000 | F36: =+E36/E$39 -> 0.5 | H36: =+I36*H$41/1000000 -> 42.8822 | I36: =+E36*(1-J6) -> 200000 | J36: =+I36/I$39 -> 0.34359462
B37: Investor 2 | D37: =+E37*D$41/1000000 -> 10.72055 | E37: 50000 | F37: =+E37/E$39 -> 0.125 | H37: =+I37*H$41/1000000 -> 0 | I37: =+E37*(1-J7) -> 0 | J37: =+I37/I$39 -> 0
B38: New management option pool | D38: =+E38*D$41/1000000 -> 0 | E38: 0 | F38: =+E38/E$39 -> 0 | H38: 0 | I38: =SUM(I34:I37)/(1-J4)*J4 -> 29104.065 | J38: =+I38/I$39 -> 0.05
B39: Total company | D39: =SUM(D34:D38) -> 85.7644 | E39: =SUM(E34:E38) -> 400000 | F39: =+E39/E$39 -> 1 | H39: =SUM(H34:H38) -> 118.5644 | I39: =SUM(I34:I38) -> 582081.29 | J39: =+I39/I$39 -> 1
B41: Share price | D41: =+C11*1000000/E39 -> 214.411 | H41: =+D41 -> 214.411
B44: Model | J44: $ millions
B45: Income statement | C45: =+D45-1 -> -2 | D45: =+E45-1 -> -1 | E45: 0 | F45: 1 | G45: =F45+1 -> 2 | H45: =G45+1 -> 3 | I45: =H45+1 -> 4 | J45: =I45+1 -> 5
B46: Gross revenue | C46: =+'Revenue Build - End'!C10 -> 27.24 | D46: =+'Revenue Build - End'!D10 -> 13.08 | E46: =+'Revenue Build - End'!E10 -> 33.2 | F46: =+'Revenue Build - End'!F10 -> 58.1 | G46: =+'Revenue Build - End'!G10 -> 96.59125 | H46: =+'Revenue Build - End'!H10 -> 152.13122 | I46: =+'Revenue Build - End'!I10 -> 226.29519 | J46: =+'Revenue Build - End'!J10 -> 316.81326
B47: % Growth | D47: =D46/C46-1 -> -0.51982379 | E47: =E46/D46-1 -> 1.5382263 | F47: =F46/E46-1 -> 0.75 | G47: =G46/F46-1 -> 0.6625 | H47: =H46/G46-1 -> 0.575 | I47: =I46/H46-1 -> 0.4875 | J47: =J46/I46-1 -> 0.4
B49: Discounts | C49: =C55*C$46 -> 1.6344 | D49: =D55*D$46 -> 1.635 | E49: =E55*E$46 -> 2.7224 | F49: =F55*F$46 -> 4.648 | G49: =G55*G$46 -> 7.7273 | H49: =H55*H$46 -> 12.170497 | I49: =I55*I$46 -> 18.103615 | J49: =J55*J$46 -> 25.345061
...

Sheet Revenue Build - End
B3: Revenue Build | J3: $ millions
B4: Paid Traffic | C4: =+D4-1 -> -2 | D4: =+E4-1 -> -1 | E4: 0 | F4: 1 | G4: =F4+1 -> 2 | H4: =G4+1 -> 3 | I4: =H4+1 -> 4 | J4: =I4+1 -> 5
B5: Total ad budget | C5: 4.7087064 | D5: 1.477386 | E5: 6.26733 | F5: =+F6*E10 -> 11.62 | G5: =+G6*F10 -> 20.335 | H5: =+H6*G10 -> 33.806937 | I5: =+I6*H10 -> 53.245927 | J5: =+J6*I10 -> 79.203316
B6: % of previous gross revenue | D6: =+D5/C10 -> 0.054235903 | E6: =+E5/D10 -> 0.47915367 | F6: 0.35 | G6: 0.35 | H6: 0.35 | I6: 0.35 | J6: 0.35
B8: Revenue per ad dollar spent | C8: =+C13/C18 -> 5.7850283 | D8: =+D13/D18 -> 8.853475 | E8: =+E13/E18 -> 5.2973116 | F8: 5 | G8: 4.75 | H8: 4.5 | I8: 4.25 | J8: 4
B10: Gross revenue | C10: 27.24 | D10: 13.08 | E10: 33.2 | F10: =+F5*F8 -> 58.1 | G10: =+G5*G8 -> 96.59125 | H10: =+H5*H8 -> 152.13122 | I10: =+I5*I8 -> 226.29519 | J10: =+J5*J8 -> 316.81326
B11: % Growth | D11: =D10/C10-1 -> -0.51982379 | E11: =E10/D10-1 -> 1.5382263 | F11: =F10/E10-1 -> 0.75 | G11: =G10/F10-1 -> 0.6625 | H11: =H10/G10-1 -> 0.575 | I11: =I10/H10-1 -> 0.4875 | J11: =J10/I10-1 -> 0.4
B13: Price per unit | C13: 4150 | D13: 4150 | E13: 4150 | F13: 4150 | G13: 4150 | H13: 4150 | I13: 4150 | J13: 4150
B15: Units sold | C15: =+C10*1000000/C13 -> 6563.8554 | D15: =+D10*1000000/D13 -> 3151.8072 | E15: =+E10*1000000/E13 -> 8000 | F15: =+F10*1000000/F13 -> 14000 | G15: =+G10*1000000/G13 -> 23275 | H15: =+H10*1000000/H13 -> 36658.125 | I15: =+I10*1000000/I13 -> 54528.961 | J15: =+J10*1000000/J13 -> 76340.545
B16: % Growth | D16: =+D15/C15-1 -> -0.51982379 | E16: =+E15/D15-1 -> 1.5382263 | F16: =+F15/E15-1 -> 0.75 | G16: =+G15/F15-1 -> 0.6625 | H16: =+H15/G15-1 -> 0.575 | I16: =+I15/H15-1 -> 0.4875 | J16: =+J15/I15-1 -> 0.4
B18: Ad spend per unit sold | C18: =+C5*1000000/C15 -> 717.369 | D18: =+D5*1000000/D15 -> 468.7425 | E18: =+E5*1000000/E15 -> 783.41625 | F18: =+F5*1000000/F15 -> 830 | G18: =+G5*1000000/G15 -> 873.68421 | H18: =+H5*1000000/H15 -> 922.22222 | I18: =+I5*1000000/I15 -> 976.47059 | J18: =+J5*1000000/J15 -> 1037.5
B19: % Growth | D19: =+D18/C18-1 -> -0.34658105 | E19: =+E18/D18-1 -> 0.67131474 | F19: =+F18/E18-1 -> 0.059462323 | G19: =+G18/F18-1 -> 0.052631579 | H19: =+H18/G18-1 -> 0.055555556 | I19: =+I18/H18-1 -> 0.058823529 | J19: =+J18/I18-1 -> 0.0625
B20: aka CAC
