Workbook
Name different: #REF!
Name mike: 'ARR Waterfall'!$A$8
Name unit: 'ARR Waterfall'!$A$1
Name unit: 'Billing Waterfall'!#REF!
Name unit: Capitalizations!#REF!
Name unit: Cohorts!$A$1
Name unit: Model!#REF!
Name unit: 'Model (Start)'!#REF!
Name unit: 'SaaS Metrics'!#REF!
Name unit: Transaction!#REF!
Name unit: #REF!

Sheet Resources
B4: GO, GO, GO!
B5: Practice really does make perfect!
B6: You got this! :-)
B10: This template is part of a comprehensive course for SaaS investing roles & interviews.
B11: For more video courses and tutorials:
B13: =HYPERLINK("https://GrowthEquityInterviewGuide.com", "GrowthEquityInterviewGuide.com") -> GrowthEquityInterviewGuide.com
B25: All rights reserved. Growth Equity Interview Guide.

Sheet Start ->

Sheet Model (Start)
B2: Income Statement | AH2: $ in millions, except noted
C3: =YEAR(C4) -> 2020 | D3: =YEAR(D4) -> 2020 | E3: =YEAR(E4) -> 2020 | F3: =YEAR(F4) -> 2020 | G3: =YEAR(G4) -> 2021 | H3: =YEAR(H4) -> 2021 | I3: =YEAR(I4) -> 2021 | J3: =YEAR(J4) -> 2021 | ... AH3: =YEAR(AH4) -> 2027
C4: 43921 | D4: =EOMONTH(C4, 3) -> 44012 | E4: =EOMONTH(D4, 3) -> 44104 | F4: =EOMONTH(E4, 3) -> 44196 | G4: =EOMONTH(F4, 3) -> 44286 | H4: =EOMONTH(G4, 3) -> 44377 | I4: =EOMONTH(H4, 3) -> 44469 | J4: =EOMONTH(I4, 3) -> 44561 | K4: =EOMONTH(J4, 3) -> 44651 | ... AH4: =EOMONTH(AG4, 3) -> 46752
B5: GAAP Revenue | C5: 73.455054 | D5: 73.869141 | E5: 77.137926 | F5: 78.14858 | G5: 76.99011 | H5: 76.949729 | I5: 77.996212 | J5: 78.018904 | K5: 79.197922 | L5: 80.146255 | M5: 81.768686 | N5: 82.397303
B6: % YoY Growth | G6: =G5/C5-1 -> 0.04812543 | H6: =H5/D5-1 -> 0.041703321 | I6: =I5/E5-1 -> 0.011126641 | J6: =J5/F5-1 -> -0.0016593573 | K6: =K5/G5-1 -> 0.028676573 | L6: =L5/H5-1 -> 0.041540435 | M6: =M5/I5-1 -> 0.0483674 | N6: =N5/J5-1 -> 0.056119714
B8: Gross Profit
B9: COGS | C9: 16.814184 | D9: 16.439784 | E9: 17.243159 | F9: 17.381202 | G9: 17.181649 | H9: 17.041217 | I9: 17.760996 | J9: 17.260387 | K9: 18.194632 | L9: 18.159883 | M9: 18.430077 | N9: 18.925571
B10: Gross Profit | C10: =C5-C9 -> 56.64087 | D10: =D5-D9 -> 57.429357 | E10: =E5-E9 -> 59.894767 | F10: =F5-F9 -> 60.767378 | G10: =G5-G9 -> 59.808461 | H10: =H5-H9 -> 59.908513 | I10: =I5-I9 -> 60.235216 | J10: =J5-J9 -> 60.758517 | ... N10: =N5-N9 -> 63.471732
B11: Gross Margin % | C11: =C10/C5 -> 0.77109561 | D11: =D10/D5 -> 0.77744721 | E11: =E10/E5 -> 0.77646328 | F11: =F10/F5 -> 0.77758774 | G11: =G10/G5 -> 0.77683304 | H11: =H10/H5 -> 0.77854092 | I11: =I10/I5 -> 0.77228386 | J11: =J10/J5 -> 0.77876661 | ... N11: =N10/N5 -> 0.77031322
B13: Operating Expenses
B14: S&M | C14: 14.00397 | D14: 14.083162 | E14: 14.056085 | F14: 14.845196 | G14: 13.968859 | H14: 14.048706 | I14: 14.759204 | J14: 14.257532 | K14: 14.673868 | L14: 15.107327 | M14: 15.409772 | N14: 15.384978
B15: R&D | C15: 9.2062254 | D15: 9.6841711 | E15: 9.7135544 | F15: 10.07255 | G15: 9.3605583 | H15: 9.9635406 | I15: 9.5611794 | J15: 9.4684992 | K15: 10.008531 | L15: 9.9327403 | M15: 10.530412 | N15: 10.727017
B16: G&A | C16: 7.8364503 | D16: 7.7408835 | E16: 8.5227341 | F16: 8.297927 | G16: 7.7674467 | H16: 8.4813746 | I16: 8.1831799 | J16: 8.5208101 | K16: 8.1719339 | L16: 8.6967456 | M16: 8.4261176 | N16: 9.0984912
B17: Operating Expenses | C17: =SUM(C14:C16) -> 31.046645 | D17: =SUM(D14:D16) -> 31.508217 | E17: =SUM(E14:E16) -> 32.292374 | F17: =SUM(F14:F16) -> 33.215673 | G17: =SUM(G14:G16) -> 31.096864 | H17: =SUM(H14:H16) -> 32.493621 | I17: =SUM(I14:I16) -> 32.503563 | J17: =SUM(J14:J16) -> 32.246841 | ... N17: =SUM(N14:N16) -> 35.210486
B18: =B14&" as % of Revenue" -> S&M as % of Revenue | C18: =+C14/C$5 -> 0.19064678 | D18: =+D14/D$5 -> 0.19065014 | E18: =+E14/E$5 -> 0.18222016 | F18: =+F14/F$5 -> 0.18996118 | G18: =+G14/G$5 -> 0.18143705 | H18: =+H14/H$5 -> 0.18256992 | I18: =+I14/I$5 -> 0.18922975 | J18: =+J14/J$5 -> 0.18274458 | ... N18: =+N14/N$5 -> 0.18671701
B19: =B15&" as % of Revenue" -> R&D as % of Revenue | C19: =+C15/C$5 -> 0.12533141 | D19: =+D15/D$5 -> 0.13109901 | E19: =+E15/E$5 -> 0.1259245 | F19: =+F15/F$5 -> 0.12888973 | G19: =+G15/G$5 -> 0.12158131 | H19: =+H15/H$5 -> 0.12948117 | I19: =+I15/I$5 -> 0.12258518 | J19: =+J15/J$5 -> 0.1213616 | ... N19: =+N15/N$5 -> 0.1301865
B20: =B16&" as % of Revenue" -> G&A as % of Revenue | C20: =+C16/C$5 -> 0.10668361 | D20: =+D16/D$5 -> 0.10479184 | E20: =+E16/E$5 -> 0.11048695 | F20: =+F16/F$5 -> 0.10618142 | G20: =+G16/G$5 -> 0.10088889 | H20: =+H16/H$5 -> 0.11021968 | I20: =+I16/I$5 -> 0.10491766 | J20: =+J16/J$5 -> 0.10921469 | ... N20: =+N16/N$5 -> 0.1104222
B21: =B17&" as % of Revenue" -> Operating Expenses as % of Revenue | C21: =+C17/C$5 -> 0.4226618 | D21: =+D17/D$5 -> 0.426541 | E21: =+E17/E$5 -> 0.4186316 | F21: =+F17/F$5 -> 0.42503233 | G21: =+G17/G$5 -> 0.40390725 | H21: =+H17/H$5 -> 0.42227077 | I21: =+I17/I$5 -> 0.41673259 | J21: =+J17/J$5 -> 0.41332086 | ... N21: =+N17/N$5 -> 0.42732571
B23: Operating Income | C23: =+C10-C17 -> 25.594225 | D23: =+D10-D17 -> 25.92114 | E23: =+E10-E17 -> 27.602394 | F23: =+F10-F17 -> 27.551705 | G23: =+G10-G17 -> 28.711597 | H23: =+H10-H17 -> 27.414892 | I23: =+I10-I17 -> 27.731653 | J23: =+J10-J17 -> 28.511676 | ... N23: =+N10-N17 -> 28.261246
B24: % Margin | C24: =+C23/C5 -> 0.34843381 | D24: =+D23/D5 -> 0.35090621 | E24: =+E23/E5 -> 0.35783168 | F24: =+F23/F5 -> 0.35255542 | G24: =+G23/G5 -> 0.37292579 | H24: =+H23/H5 -> 0.35627015 | I24: =+I23/I5 -> 0.35555128 | J24: =+J23/J5 -> 0.36544574 | ... N24: =+N23/N5 -> 0.34298752
B26: D&A | F26: 7.6474565 | G26: 7.8761646 | H26: 7.8292759 | I26: 7.9909183 | J26: 7.7891753 | K26: 7.881978 | L26: 8.1080011 | M26: 8.090979 | N26: 8.3755639
B27: EBITDA | F27: =+F23+F26 -> 35.199162 | G27: =+G23+G26 -> 36.587762 | H27: =+H23+H26 -> 35.244167 | I27: =+I23+I26 -> 35.722571 | J27: =+J23+J26 -> 36.300852 | K27: =+K23+K26 -> 36.030935 | L27: =+L23+L26 -> 36.357559 | M27: =+M23+M26 -> 37.063287 | N27: =+N23+N26 -> 36.63681
B28: % Margin | F28: =+F27/F5 -> 0.45041332 | G28: =+G27/G5 -> 0.47522678 | H28: =+H27/H5 -> 0.45801548 | I28: =+I27/I5 -> 0.45800392 | J28: =+J27/J5 -> 0.46528277 | K28: =+K27/K5 -> 0.45494799 | L28: =+L27/L5 -> 0.45364015 | M28: =+M27/M5 -> 0.45326994 | N28: =+N27/N5 -> 0.44463604
B30: LTM EBITDA | I30: =SUM(F27:I27) -> 142.75366 | J30: =SUM(G27:J27) -> 143.85535 | K30: =SUM(H27:K27) -> 143.29853 | L30: =SUM(I27:L27) -> 144.41192 | M30: =SUM(J27:M27) -> 145.75263 | N30: =SUM(K27:N27) -> 146.08859
B32: Note:
B33: Prior Year Renewal ARR for Billing | K33: 72.741228 | L33: 73.966444 | M33: 74.663909 | N33: 75.736755
B36: Balance Sheet | AH36: $ in millions, except noted
N37: =N4 -> 44926
B38: Cash | N38: =(55601.141636816-990)/1000 -> 54.611142
B39: Accounts Receivable | N39: 12.312163
B40: Net PP&E | N40: 35.699125
B41: Prepaid Expenses | N41: 13.122155
B42: Deferred Commissions | N42: 14.2204
B43: Capitalized Software Costs | N43: 5.9109174
B44: Goodwill | N44: 0
B45: Total Assets | N45: =SUM(N38:N44) -> 135.8759
B47: Accounts Payable | N47: 14.671147
B48: Deferred Revenue | N48: 17.993601
B49: Existing Debt | N49: 12.201
B50: New Debt | N50: 0
...

Sheet Raw Customer ARR (Start)
A1: Customer | B1: =EOMONTH(C1, -3) -> 43830 | C1: 43921 | D1: =EOMONTH(C1,3) -> 44012 | E1: =EOMONTH(D1,3) -> 44104 | F1: =EOMONTH(E1,3) -> 44196 | G1: =EOMONTH(F1,3) -> 44286 | H1: =EOMONTH(G1,3) -> 44377 | I1: =EOMONTH(H1,3) -> 44469 | J1: =EOMONTH(I1,3) -> 44561 | K1: =EOMONTH(J1,3) -> 44651 | ... N1: =EOMONTH(M1,3) -> 44926
A2: 1 | B2: 0 | C2: 0 | D2: 0 | E2: 0 | F2: 0 | G2: 0 | H2: 0 | I2: 1152000 | J2: 1152000 | K2: 1152000 | L2: 1152000 | M2: 975056 | N2: 975056
A3: =+A2+1 -> 2 | B3: 0 | C3: 0 | D3: 0 | E3: 0 | F3: 0 | G3: 0 | H3: 0 | I3: 2304000 | J3: 1950104 | K3: 1950104 | L3: 1950104 | M3: 1950104 | N3: 1950104
A4: =+A3+1 -> 3 | B4: 0 | C4: 0 | D4: 0 | E4: 0 | F4: 0 | G4: 0 | H4: 0 | I4: 2304000 | J4: 2304000 | K4: 2119680 | L4: 2119680 | M4: 2119680 | N4: 2119680
A5: =+A4+1 -> 4 | B5: 0 | C5: 0 | D5: 0 | E5: 0 | F5: 0 | G5: 0 | H5: 0 | I5: 2304000 | J5: 2304000 | K5: 2304000 | L5: 2304000 | M5: 2304000 | N5: 2304000
A6: =+A5+1 -> 5 | B6: 0 | C6: 0 | D6: 0 | E6: 0 | F6: 0 | G6: 0 | H6: 0 | I6: 3456000 | J6: 3456000 | K6: 3456000 | L6: 3456000 | M6: 3456000 | N6: 3456000
A7: =+A6+1 -> 6 | B7: 1445072 | C7: 0 | D7: 0 | E7: 0 | F7: 0 | G7: 0 | H7: 0 | I7: 0 | J7: 0 | K7: 0 | L7: 0 | M7: 0 | N7: 0
A8: =+A7+1 -> 7 | B8: 2119680 | C8: 0 | D8: 0 | E8: 0 | F8: 0 | G8: 0 | H8: 0 | I8: 0 | J8: 0 | K8: 0 | L8: 0 | M8: 0 | N8: 0
A9: =+A8+1 -> 8 | B9: 975056 | C9: 0 | D9: 0 | E9: 0 | F9: 0 | G9: 0 | H9: 0 | I9: 0 | J9: 0 | K9: 0 | L9: 0 | M9: 0 | N9: 0
A10: =+A9+1 -> 9 | B10: 2739760 | C10: 0 | D10: 0 | E10: 0 | F10: 0 | G10: 0 | H10: 0 | I10: 0 | J10: 0 | K10: 0 | L10: 0 | M10: 0 | N10: 0
A11: =+A10+1 -> 10 | B11: 0 | C11: 0 | D11: 0 | E11: 0 | F11: 0 | G11: 0 | H11: 0 | I11: 0 | J11: 0 | K11: 0 | L11: 0 | M11: 0 | N11: 3456000
A12: =+A11+1 -> 11 | B12: 0 | C12: 0 | D12: 0 | E12: 0 | F12: 0 | G12: 0 | H12: 0 | I12: 0 | J12: 0 | K12: 0 | L12: 0 | M12: 0 | N12: 2304000
A13: =+A12+1 -> 12 | B13: 0 | C13: 0 | D13: 0 | E13: 0 | F13: 0 | G13: 0 | H13: 0 | I13: 0 | J13: 0 | K13: 0 | L13: 0 | M13: 0 | N13: 2580480
A14: =+A13+1 -> 13 | B14: 0 | C14: 0 | D14: 0 | E14: 0 | F14: 0 | G14: 0 | H14: 0 | I14: 0 | J14: 0 | K14: 0 | L14: 0 | M14: 0 | N14: 2304000
... A197: =+A196+1 -> 196 | B197: 1489000 | C197: 1489000 | D197: 1489000 | E197: 1489000 | F197: 1489000 | G197: 1489000 | H197: 0 | I197: 0 | J197: 0 | K197: 0 | L197: 0 | M197: 0 | N197: 0

Sheet End ->

Sheet Transaction
B2: Entry | G2: $ in millions, except noted
B3: Entry Assumptions | E3: Sources
B4: Entry LTM EBITDA | C4: =Model!N36 -> 146.08859 | E4: Sponsor Equity | G4: =G13-G5 -> 770.05182
B5: Entry Multiple | C5: 10 | E5: New Debt | G5: =+D21 -> 730.44296
B6: Purchase Enterprise Value | C6: =C5*C4 -> 1460.8859 | E6: Total Sources | G6: =SUM(G4:G5) -> 1500.4948
B7: (-) Debt | C7: =Model!L61 -> 12.201
B8: (+) Cash | C8: =Model!L50 -> 54.611142 | E8: Uses
B9: Purchase Equity Value | C9: =+C6-C7+C8 -> 1503.2961 | E9: Purchase Enterprise Value | G9: =+C6 -> 1460.8859
E10: Ending Cash to B/S | G10: 25
B11: Pre-Money Shares Outstanding | C11: 1230000 | E11: Transaction Fees | G11: =1%*C6 -> 14.608859
B12: Pre-Money Stock Price | C12: =+C9/C11*1000 -> 1.2221919
B13: Post-Money Shares Outstanding | C13: =+C11 -> 1230000 | E13: Total Uses | G13: =SUM(G9:G12) -> 1500.4948
B16: Debt Assumptions
C17: xEBITDA | D17: $ Amount | E17: % Interest
B18: Revolver | C18: 0 | D18: =C18*C$4 -> 0 | E18: 0.02
B19: Term Loan B | C19: 3 | D19: =C19*C$4 -> 438.26578 | E19: 0.02
B20: Senior Notes | C20: 2 | D20: =C20*C$4 -> 292.17718 | E20: 0.05
B21: Total Debt | C21: =SUM(C18:C20) -> 5 | D21: =SUM(D18:D20) -> 730.44296
B24: Exit & Returns
B25: Exit Value | E25: Exit Ownership
B26: Exit LTM EBITDA | C26: =Model!AH36 -> 176.07296 | E26: Initial Ownership | G26: 1
B27: Exit Multiple | C27: 10 | E27: Dilution from SBC | G27: =+Model!AH182 -> 0.057442591
B28: Exit Enterprise Value | C28: =C27*C26 -> 1760.7296 | E28: Exit Ownership | G28: =+G26*(1-G27) -> 0.94255741
B29: (-) Debt | C29: =+Model!AH62+Model!AH61 -> 546.27792
B30: (+) Cash | C30: =+Model!AH50 -> 25
B31: Exit Equity value | C31: =+C28+C30-C29 -> 1239.4517
B32: (x) Exit Ownership | C32: =+G28 -> 0.94255741
B33: Exit Sponsor Value | C33: =+C31*C32 -> 1168.2543
B35: IRR | C35: =XIRR(C39:C40, C41:C42) -> 0.086885175
B36: M-o-M | C36: =+C40/(-C39) -> 1.5171113
B39: Entry Investment | C39: =+-G4 -> -770.05182
B40: Exit Proceeds | C40: =+C33 -> 1168.2543
B41: Entry Date | C41: =+Model!N4 -> 44926
B42: Exit Date | C42: =+Model!AH4 -> 46752

Sheet Model
B2: Income Statement | AH2: $ in millions, except noted
C3: =YEAR(C4) -> 2020 | D3: =YEAR(D4) -> 2020 | E3: =YEAR(E4) -> 2020 | F3: =YEAR(F4) -> 2020 | G3: =YEAR(G4) -> 2021 | H3: =YEAR(H4) -> 2021 | I3: =YEAR(I4) -> 2021 | J3: =YEAR(J4) -> 2021 | ... AH3: =YEAR(AH4) -> 2027
C4: 43921 | D4: =EOMONTH(C4, 3) -> 44012 | E4: =EOMONTH(D4, 3) -> 44104 | F4: =EOMONTH(E4, 3) -> 44196 | G4: =EOMONTH(F4, 3) -> 44286 | H4: =EOMONTH(G4, 3) -> 44377 | I4: =EOMONTH(H4, 3) -> 44469 | J4: =EOMONTH(I4, 3) -> 44561 | K4: =EOMONTH(J4, 3) -> 44651 | ... AH4: =EOMONTH(AG4, 3) -> 46752
B5: Ending ARR | C5: =+'ARR Waterfall'!C11 -> 301.18761 | D5: =+'ARR Waterfall'!D11 -> 304.4751 | E5: =+'ARR Waterfall'!E11 -> 308.34238 | F5: =+'ARR Waterfall'!F11 -> 313.78571 | G5: =+'ARR Waterfall'!G11 -> 310.36867 | H5: =+'ARR Waterfall'!H11 -> 309.6027 | I5: =+'ARR Waterfall'!I11 -> 312.48882 | J5: =+'ARR Waterfall'!J11 -> 315.91418 | ... AH5: =+'ARR Waterfall'!AH11 -> 373.35968
B6: % YoY Growth | G6: =G5/C5-1 -> 0.030482874 | H6: =H5/D5-1 -> 0.016840759 | I6: =I5/E5-1 -> 0.013447545 | J6: =J5/F5-1 -> 0.0067832024 | K6: =K5/G5-1 -> 0.026340777 | L6: =L5/H5-1 -> 0.039668698 | M6: =M5/I5-1 -> 0.049247534 | N6: =N5/J5-1 -> 0.069638583 | ... AH6: =AH5/AD5-1 -> 0.020150501
B8: GAAP Revenue | C8: 73.455054 | D8: 73.869141 | E8: 77.137926 | F8: 78.14858 | G8: 76.99011 | H8: 76.949729 | I8: 77.996212 | J8: 78.018904 | K8: 79.197922 | L8: 80.146255 | M8: 81.768686 | N8: 82.397303 | O8: =O9*O5 -> 81.504857 | P8: =P9*P5 -> 81.912381 | Q8: =Q9*Q5 -> 82.321943 | R8: =R9*R5 -> 82.733553 | S8: =S9*S5 -> 83.14722 | T8: =T9*T5 -> 83.562957 | U8: =U9*U5 -> 83.980771 | V8: =V9*V5 -> 84.400675 | ... AH8: =AH9*AH5 -> 89.606324
B9: % of ARR | C9: =+C8/C5 -> 0.24388471 | D9: =+D8/D5 -> 0.24261143 | E9: =+E8/E5 -> 0.25016972 | F9: =+F8/F5 -> 0.24905079 | G9: =+G8/G5 -> 0.24806018 | H9: =+H8/H5 -> 0.24854347 | I9: =+I8/I5 -> 0.24959681 | J9: =+J8/J5 -> 0.24696233 | ... N9: =+N8/N5 -> 0.24384104 | O9: 0.24 | P9: 0.24 | Q9: 0.24 | R9: 0.24 | S9: 0.24 | T9: 0.24 | U9: 0.24 | V9: 0.24 | W9: 0.24 | X9: 0.24 | Y9: 0.24 | Z9: 0.24 | AA9: 0.24 | AB9: 0.24 | AC9: 0.24 | AD9: 0.24 | AE9: 0.24 | AF9: 0.24 | AG9: 0.24 | AH9: 0.24
B10: % YoY Growth | G10: =G8/C8-1 -> 0.04812543 | H10: =H8/D8-1 -> 0.041703321 | I10: =I8/E8-1 -> 0.011126641 | J10: =J8/F8-1 -> -0.0016593573 | K10: =K8/G8-1 -> 0.028676573 | L10: =L8/H8-1 -> 0.041540435 | M10: =M8/I8-1 -> 0.0483674 | N10: =N8/J8-1 -> 0.056119714 | ... AH10: =AH8/AD8-1 -> 0.020150501
B12: LTM GAAP Revenue | F12: =SUM(C8:F8) -> 302.6107 | G12: =SUM(D8:G8) -> 306.14576 | H12: =SUM(E8:H8) -> 309.22635 | I12: =SUM(F8:I8) -> 310.08463 | J12: =SUM(G8:J8) -> 309.95496 | K12: =SUM(H8:K8) -> 312.16277 | L12: =SUM(I8:L8) -> 315.35929 | M12: =SUM(J8:M8) -> 319.13177 | ... AH12: =SUM(AE8:AH8) -> 355.75934
B14: Gross Profit
B15: COGS | C15: 16.814184 | D15: 16.439784 | E15: 17.243159 | F15: 17.381202 | G15: 17.181649 | H15: 17.041217 | I15: 17.760996 | J15: 17.260387 | K15: 18.194632 | L15: 18.159883 | M15: 18.430077 | N15: 18.925571 | O15: =(1-O17)*O8 -> 18.746117 | P15: =(1-P17)*P8 -> 18.839848 | Q15: =(1-Q17)*Q8 -> 18.934047 | R15: =(1-R17)*R8 -> 19.028717 | S15: =(1-S17)*S8 -> 19.123861 | T15: =(1-T17)*T8 -> 19.21948 | U15: =(1-U17)*U8 -> 19.315577 | V15: =(1-V17)*V8 -> 19.412155 | ... AH15: =(1-AH17)*AH8 -> 20.609455
B16: Gross Profit | C16: =C8-C15 -> 56.64087 | D16: =D8-D15 -> 57.429357 | E16: =E8-E15 -> 59.894767 | F16: =F8-F15 -> 60.767378 | G16: =G8-G15 -> 59.808461 | H16: =H8-H15 -> 59.908513 | I16: =I8-I15 -> 60.235216 | J16: =J8-J15 -> 60.758517 | ... AH16: =AH8-AH15 -> 68.99687
B17: Gross Margin % | C17: =C16/C8 -> 0.77109561 | D17: =D16/D8 -> 0.77744721 | E17: =E16/E8 -> 0.77646328 | F17: =F16/F8 -> 0.77758774 | G17: =G16/G8 -> 0.77683304 | H17: =H16/H8 -> 0.77854092 | I17: =I16/I8 -> 0.77228386 | J17: =J16/J8 -> 0.77876661 | ... N17: =N16/N8 -> 0.77031322 | O17: 0.77 | P17: 0.77 | Q17: 0.77 | R17: 0.77 | S17: 0.77 | T17: 0.77 | U17: 0.77 | V17: 0.77 | W17: 0.77 | X17: 0.77 | Y17: 0.77 | Z17: 0.77 | AA17: 0.77 | AB17: 0.77 | AC17: 0.77 | AD17: 0.77 | AE17: 0.77 | AF17: 0.77 | AG17: 0.77 | AH17: 0.77
B19: Operating Expenses
B20: S&M | C20: 14.00397 | D20: 14.083162 | E20: 14.056085 | F20: 14.845196 | G20: 13.968859 | H20: 14.048706 | I20: 14.759204 | J20: 14.257532 | K20: 14.673868 | L20: 15.107327 | M20: 15.409772 | N20: 15.384978 | O20: =O$8*O24 -> 14.670874 | P20: =P$8*P24 -> 14.744229 | Q20: =Q$8*Q24 -> 14.81795 | R20: =R$8*R24 -> 14.892039 | S20: =S$8*S24 -> 14.9665 | T20: =T$8*T24 -> 15.041332 | U20: =U$8*U24 -> 15.116539 | V20: =V$8*V24 -> 15.192122 | ... AH20: =AH$8*AH24 -> 16.129138
B21: R&D | C21: 9.2062254 | D21: 9.6841711 | E21: 9.7135544 | F21: 10.07255 | G21: 9.3605583 | H21: 9.9635406 | I21: 9.5611794 | J21: 9.4684992 | K21: 10.008531 | L21: 9.9327403 | M21: 10.530412 | N21: 10.727017 | O21: =O$8*O25 -> 9.7805828 | P21: =P$8*P25 -> 9.8294857 | Q21: =Q$8*Q25 -> 9.8786332 | R21: =R$8*R25 -> 9.9280263 | S21: =S$8*S25 -> 9.9776665 | T21: =T$8*T25 -> 10.027555 | U21: =U$8*U25 -> 10.077693 | V21: =V$8*V25 -> 10.128081 | ... AH21: =AH$8*AH25 -> 10.752759
B22: G&A | C22: 7.8364503 | D22: 7.7408835 | E22: 8.5227341 | F22: 8.297927 | G22: 7.7674467 | H22: 8.4813746 | I22: 8.1831799 | J22: 8.5208101 | K22: 8.1719339 | L22: 8.6967456 | M22: 8.4261176 | N22: 9.0984912 | O22: =O$8*O26 -> 8.9655342 | P22: =P$8*P26 -> 9.0103619 | Q22: =Q$8*Q26 -> 9.0554137 | R22: =R$8*R26 -> 9.1006908 | S22: =S$8*S26 -> 9.1461943 | T22: =T$8*T26 -> 9.1919252 | U22: =U$8*U26 -> 9.2378848 | V22: =V$8*V26 -> 9.2840743 | ... AH22: =AH$8*AH26 -> 9.8566957
B23: Operating Expenses | C23: =SUM(C20:C22) -> 31.046645 | D23: =SUM(D20:D22) -> 31.508217 | E23: =SUM(E20:E22) -> 32.292374 | F23: =SUM(F20:F22) -> 33.215673 | G23: =SUM(G20:G22) -> 31.096864 | H23: =SUM(H20:H22) -> 32.493621 | I23: =SUM(I20:I22) -> 32.503563 | J23: =SUM(J20:J22) -> 32.246841 | ... AH23: =SUM(AH20:AH22) -> 36.738593
B24: =B20&" as % of Revenue" -> S&M as % of Revenue | C24: =+C20/C$8 -> 0.19064678 | D24: =+D20/D$8 -> 0.19065014 | E24: =+E20/E$8 -> 0.18222016 | F24: =+F20/F$8 -> 0.18996118 | G24: =+G20/G$8 -> 0.18143705 | H24: =+H20/H$8 -> 0.18256992 | I24: =+I20/I$8 -> 0.18922975 | J24: =+J20/J$8 -> 0.18274458 | ... N24: =+N20/N$8 -> 0.18671701 | O24: 0.18 | P24: 0.18 | Q24: 0.18 | R24: 0.18 | S24: 0.18 | T24: 0.18 | U24: 0.18 | V24: 0.18 | W24: 0.18 | X24: 0.18 | Y24: 0.18 | Z24: 0.18 | AA24: 0.18 | AB24: 0.18 | AC24: 0.18 | AD24: 0.18 | AE24: 0.18 | AF24: 0.18 | AG24: 0.18 | AH24: 0.18
B25: =B21&" as % of Revenue" -> R&D as % of Revenue | C25: =+C21/C$8 -> 0.12533141 | D25: =+D21/D$8 -> 0.13109901 | E25: =+E21/E$8 -> 0.1259245 | F25: =+F21/F$8 -> 0.12888973 | G25: =+G21/G$8 -> 0.12158131 | H25: =+H21/H$8 -> 0.12948117 | I25: =+I21/I$8 -> 0.12258518 | J25: =+J21/J$8 -> 0.1213616 | ... N25: =+N21/N$8 -> 0.1301865 | O25: 0.12 | P25: 0.12 | Q25: 0.12 | R25: 0.12 | S25: 0.12 | T25: 0.12 | U25: 0.12 | V25: 0.12 | W25: 0.12 | X25: 0.12 | Y25: 0.12 | Z25: 0.12 | AA25: 0.12 | AB25: 0.12 | AC25: 0.12 | AD25: 0.12 | AE25: 0.12 | AF25: 0.12 | AG25: 0.12 | AH25: 0.12
B26: =B22&" as % of Revenue" -> G&A as % of Revenue | C26: =+C22/C$8 -> 0.10668361 | D26: =+D22/D$8 -> 0.10479184 | E26: =+E22/E$8 -> 0.11048695 | F26: =+F22/F$8 -> 0.10618142 | G26: =+G22/G$8 -> 0.10088889 | H26: =+H22/H$8 -> 0.11021968 | I26: =+I22/I$8 -> 0.10491766 | J26: =+J22/J$8 -> 0.10921469 | ... N26: =+N22/N$8 -> 0.1104222 | O26: 0.11 | P26: 0.11 | Q26: 0.11 | R26: 0.11 | S26: 0.11 | T26: 0.11 | U26: 0.11 | V26: 0.11 | W26: 0.11 | X26: 0.11 | Y26: 0.11 | Z26: 0.11 | AA26: 0.11 | AB26: 0.11 | AC26: 0.11 | AD26: 0.11 | AE26: 0.11 | AF26: 0.11 | AG26: 0.11 | AH26: 0.11
B27: =B23&" as % of Revenue" -> Operating Expenses as % of Revenue | C27: =+C23/C$8 -> 0.4226618 | D27: =+D23/D$8 -> 0.426541 | E27: =+E23/E$8 -> 0.4186316 | F27: =+F23/F$8 -> 0.42503233 | G27: =+G23/G$8 -> 0.40390725 | H27: =+H23/H$8 -> 0.42227077 | I27: =+I23/I$8 -> 0.41673259 | J27: =+J23/J$8 -> 0.41332086 | ... AH27: =+AH23/AH$8 -> 0.41
B29: Operating Income | C29: =+C16-C23 -> 25.594225 | D29: =+D16-D23 -> 25.92114 | E29: =+E16-E23 -> 27.602394 | F29: =+F16-F23 -> 27.551705 | G29: =+G16-G23 -> 28.711597 | H29: =+H16-H23 -> 27.414892 | I29: =+I16-I23 -> 27.731653 | J29: =+J16-J23 -> 28.511676 | ... AH29: =+AH16-AH23 -> 32.258277
B30: % Margin | C30: =+C29/C8 -> 0.34843381 | D30: =+D29/D8 -> 0.35090621 | E30: =+E29/E8 -> 0.35783168 | F30: =+F29/F8 -> 0.35255542 | G30: =+G29/G8 -> 0.37292579 | H30: =+H29/H8 -> 0.35627015 | I30: =+I29/I8 -> 0.35555128 | J30: =+J29/J8 -> 0.36544574 | ... AH30: =+AH29/AH8 -> 0.36
B32: D&A | F32: 7.6474565 | G32: 7.8761646 | H32: 7.8292759 | I32: 7.9909183 | J32: 7.7891753 | K32: 7.881978 | L32: 8.1080011 | M32: 8.090979 | N32: 8.3755639 | O32: =+O149+O150 -> 9.2804907 | P32: =+P149+P150 -> 9.5141427 | Q32: =+Q149+Q150 -> 9.7184204 | R32: =+R149+R150 -> 9.9182252 | S32: =+S149+S150 -> 10.15164 | T32: =+T149+T150 -> 10.386221 | U32: =+U149+U150 -> 10.621976 | V32: =+V149+V150 -> 10.858909 | ... AH32: =+AH149+AH150 -> 12.089822
B33: EBITDA | F33: =+F29+F32 -> 35.199162 | G33: =+G29+G32 -> 36.587762 | H33: =+H29+H32 -> 35.244167 | I33: =+I29+I32 -> 35.722571 | J33: =+J29+J32 -> 36.300852 | K33: =+K29+K32 -> 36.030935 | L33: =+L29+L32 -> 36.357559 | M33: =+M29+M32 -> 37.063287 | ... AH33: =+AH29+AH32 -> 44.348099
B34: % Margin | F34: =+F33/F8 -> 0.45041332 | G34: =+G33/G8 -> 0.47522678 | H34: =+H33/H8 -> 0.45801548 | I34: =+I33/I8 -> 0.45800392 | J34: =+J33/J8 -> 0.46528277 | K34: =+K33/K8 -> 0.45494799 | L34: =+L33/L8 -> 0.45364015 | M34: =+M33/M8 -> 0.45326994 | ... AH34: =+AH33/AH8 -> 0.49492153
B36: LTM EBITDA | I36: =SUM(F33:I33) -> 142.75366 | J36: =SUM(G33:J33) -> 143.85535 | K36: =SUM(H33:K33) -> 143.29853 | L36: =SUM(I33:L33) -> 144.41192 | M36: =SUM(J33:M33) -> 145.75263 | N36: =SUM(K33:N33) -> 146.08859 | O36: =SUM(L33:O33) -> 148.6799 | P36: =SUM(M33:P33) -> 151.32494 | ... AH36: =SUM(AE33:AH33) -> 176.07296
B38: Interest Expense | O38: =O140 -> 23.337718 | P38: =P140 -> 23.261522 | Q38: =Q140 -> 23.159876 | R38: =R140 -> 23.002742 | S38: =S140 -> 22.854347 | T38: =T140 -> 22.744444 | U38: =U140 -> 22.609001 | V38: =V140 -> 22.418071 | ... AH38: =AH140 -> 19.84632
B39: Taxable Income | O39: =+O29-O38 -> 6.0040305 | P39: =+P29-P38 -> 6.2269347 | Q39: =+Q29-Q38 -> 6.4760233 | R39: =+R29-R38 -> 6.7813374 | S39: =+S29-S38 -> 7.0786526 | T39: =+T29-T38 -> 7.3382207 | U39: =+U29-U38 -> 7.6240766 | V39: =+V29-V38 -> 7.9661724 | ... AH39: =+AH29-AH38 -> 12.411956
B41: Taxes | O41: =IF(O39<0, 0, O39*O42) -> 1.5010076 | P41: =IF(P39<0, 0, P39*P42) -> 1.5567337 | Q41: =IF(Q39<0, 0, Q39*Q42) -> 1.6190058 | R41: =IF(R39<0, 0, R39*R42) -> 1.6953343 | S41: =IF(S39<0, 0, S39*S42) -> 1.7696631 | T41: =IF(T39<0, 0, T39*T42) -> 1.8345552 | U41: =IF(U39<0, 0, U39*U42) -> 1.9060192 | V41: =IF(V39<0, 0, V39*V42) -> 1.9915431 | ... AH41: =IF(AH39<0, 0, AH39*AH42) -> 3.1029891
B42: Tax Rate | O42: 0.25 | P42: 0.25 | Q42: 0.25 | R42: 0.25 | S42: 0.25 | T42: 0.25 | U42: 0.25 | V42: 0.25 | W42: 0.25 | X42: 0.25 | Y42: 0.25 | Z42: 0.25 | AA42: 0.25 | AB42: 0.25 | AC42: 0.25 | AD42: 0.25 | AE42: 0.25 | AF42: 0.25 | AG42: 0.25 | AH42: 0.25
B44: Net Income | O44: =+O39-O41 -> 4.5030229 | P44: =+P39-P41 -> 4.6702011 | Q44: =+Q39-Q41 -> 4.8570175 | R44: =+R39-R41 -> 5.086003 | S44: =+S39-S41 -> 5.3089894 | T44: =+T39-T41 -> 5.5036655 | U44: =+U39-U41 -> 5.7180575 | V44: =+V39-V41 -> 5.9746293 | ... AH44: =+AH39-AH41 -> 9.3089672
B45: % Margin | O45: =+O44/O8 -> 0.055248522 | P45: =+P44/P8 -> 0.057014593 | Q45: =+Q44/Q8 -> 0.059000278 | R45: =+R44/R8 -> 0.061474491 | S45: =+S44/S8 -> 0.063850474 | T45: =+T44/T8 -> 0.065862504 | U45: =+U44/U8 -> 0.068087699 | V45: =+V44/V8 -> 0.070788881 | ... AH45: =+AH44/AH8 -> 0.10388739
B48: Balance Sheet | L48: Actual | N48: PF | AH48: $ in millions, except noted
L49: =N4 -> 44926 | M49: Adj. | N49: =+L49 -> 44926 | O49: =O4 -> 45016 | P49: =P4 -> 45107 | Q49: =Q4 -> 45199 | R49: =R4 -> 45291 | S49: =S4 -> 45382 | T49: =T4 -> 45473 | U49: =U4 -> 45565 | V49: =V4 -> 45657 | ... AH49: =AH4 -> 46752
B50: Cash | L50: =(55601.141636816-990)/1000 -> 54.611142 | M50: =+-L50+Transaction!G10 -> -29.611142 | N50: =+M50+L50 -> 25 | O50: =+O165 -> 25 | P50: =+P165 -> 25 | Q50: =+Q165 -> 25 | R50: =+R165 -> 25 | S50: =+S165 -> 25 | T50: =+T165 -> 25 | U50: =+U165 -> 25 | V50: =+V165 -> 25 | ... AH50: =+AH165 -> 25
B51: Accounts Receivable | L51: 12.312163 | N51: =+M51+L51 -> 12.312163 | O51: =O96 -> 11.484919 | P51: =P96 -> 11.696749 | Q51: =Q96 -> 12.046712 | R51: =R96 -> 12.568749 | S51: =S96 -> 11.742789 | T51: =T96 -> 11.955908 | U51: =U96 -> 12.307167 | V51: =V96 -> 12.830506 | ... AH51: =AH96 -> 13.64785
B52: Net PP&E | L52: 35.699125 | N52: =+M52+L52 -> 35.699125 | O52: =+O86 -> 36.513668 | P52: =+P86 -> 37.332626 | Q52: =+Q86 -> 38.152967 | R52: =+R86 -> 38.974149 | S52: =+S86 -> 39.799437 | T52: =+T86 -> 40.628851 | U52: =+U86 -> 41.462412 | V52: =+V86 -> 42.300141 | ... AH52: =+AH86 -> 52.68567
B53: Prepaid Expenses | L53: 13.122155 | N53: =+M53+L53 -> 13.122155 | O53: =O77*O68 -> 13.032684 | P53: =P77*P68 -> 13.103329 | Q53: =Q77*Q68 -> 13.125459 | R53: =R77*R68 -> 13.138909 | S53: =S77*S68 -> 13.204604 | T53: =T77*T68 -> 13.270627 | U53: =U77*U68 -> 13.33698 | V53: =V77*V68 -> 13.403665 | ... AH53: =AH77*AH68 -> 14.230374
...

Sheet Billing Waterfall
AB2: $ in millions, except noted
I3: =EOMONTH(#REF!, 3) -> #REF! | J3: =EOMONTH(I3, 3) -> #REF! | K3: =EOMONTH(J3, 3) -> #REF! | L3: =EOMONTH(K3, 3) -> #REF! | M3: =EOMONTH(L3, 3) -> #REF! | N3: =EOMONTH(M3, 3) -> #REF! | O3: =EOMONTH(N3, 3) -> #REF! | P3: =EOMONTH(O3, 3) -> #REF! | Q3: =EOMONTH(P3, 3) -> #REF! | ... AB3: =EOMONTH(AA3, 3) -> #REF!
I4: =EOMONTH(#REF!, 2)+1 -> #REF! | J4: =EOMONTH(I4, 2)+1 -> #REF! | K4: =EOMONTH(J4, 2)+1 -> #REF! | L4: =EOMONTH(K4, 2)+1 -> #REF! | M4: =EOMONTH(L4, 2)+1 -> #REF! | N4: =EOMONTH(M4, 2)+1 -> #REF! | O4: =EOMONTH(N4, 2)+1 -> #REF! | P4: =EOMONTH(O4, 2)+1 -> #REF! | Q4: =EOMONTH(P4, 2)+1 -> #REF! | ... AB4: =EOMONTH(AA4, 2)+1 -> #REF!
E5: =EOMONTH(F5, -3) -> 44651 | F5: =EOMONTH(G5, -3) -> 44742 | G5: =EOMONTH(H5, -3) -> 44834 | H5: =EOMONTH(I5, -3) -> 44926 | I5: =Model!O4 -> 45016 | J5: =EOMONTH(I5, 3) -> 45107 | K5: =EOMONTH(J5, 3) -> 45199 | L5: =EOMONTH(K5, 3) -> 45291 | M5: =EOMONTH(L5, 3) -> 45382 | N5: =EOMONTH(M5, 3) -> 45473 | O5: =EOMONTH(N5, 3) -> 45565 | P5: =EOMONTH(O5, 3) -> 45657 | Q5: =EOMONTH(P5, 3) -> 45747 | ... AB5: =EOMONTH(AA5, 3) -> 46752
B6: ARR Eligible for Billings | H6: `
B7: Prior Year Renewal ARR | E7: 72.741228 | F7: 73.966444 | G7: 74.663909 | H7: 75.736755 | I7: =+E12 -> 75.371068 | J7: =+F12 -> 77.306652 | K7: =+G12 -> 80.657805 | L7: =+H12 -> 85.772627 | M7: =+I12 -> 77.060638 | N7: =+J12 -> 79.004669 | O7: =+K12 -> 82.364313 | P7: =+L12 -> 87.487667 | ... AB7: =+X12 -> 92.842942
B8: New Logo ARR | E8: ='ARR Waterfall'!K7 -> 15.34464 | F8: ='ARR Waterfall'!L7 -> 12.672 | G8: ='ARR Waterfall'!M7 -> 18.432 | H8: ='ARR Waterfall'!N7 -> 18.98496 | I8: ='ARR Waterfall'!O7 -> 13.51656 | J8: ='ARR Waterfall'!P7 -> 13.584143 | K8: ='ARR Waterfall'!Q7 -> 13.652064 | L8: ='ARR Waterfall'!R7 -> 13.720324 | ... AB8: ='ARR Waterfall'!AH7 -> 14.860087
B9: Upsell ARR | E9: ='ARR Waterfall'!K8 -> 4.374232 | F9: ='ARR Waterfall'!L8 -> 4.794456 | G9: ='ARR Waterfall'!M8 -> 3.091184 | H9: ='ARR Waterfall'!N8 -> 4.551768 | I9: ='ARR Waterfall'!O8 -> 5.06871 | J9: ='ARR Waterfall'!P8 -> 5.0940536 | K9: ='ARR Waterfall'!Q8 -> 5.1195238 | L9: ='ARR Waterfall'!R8 -> 5.1451214 | ... AB9: ='ARR Waterfall'!AH8 -> 5.5725326
B10: Downsell ARR | E10: ='ARR Waterfall'!K9 -> -3.469624 | F10: ='ARR Waterfall'!L9 -> -1.843504 | G10: ='ARR Waterfall'!M9 -> -4.098736 | H10: ='ARR Waterfall'!N9 -> -1.989072 | I10: ='ARR Waterfall'!O9 -> -3.37914 | J10: ='ARR Waterfall'!P9 -> -3.3960357 | K10: ='ARR Waterfall'!Q9 -> -3.4130159 | L10: ='ARR Waterfall'!R9 -> -3.430081 | ... AB10: ='ARR Waterfall'!AH9 -> -3.7150217
B11: Churn ARR | E11: ='ARR Waterfall'!K10 -> -13.619408 | F11: ='ARR Waterfall'!L10 -> -12.282744 | G11: ='ARR Waterfall'!M10 -> -11.430552 | H11: ='ARR Waterfall'!N10 -> -11.511784 | I11: ='ARR Waterfall'!O10 -> -13.51656 | J11: ='ARR Waterfall'!P10 -> -13.584143 | K11: ='ARR Waterfall'!Q10 -> -13.652064 | L11: ='ARR Waterfall'!R10 -> -13.720324 | ... AB11: ='ARR Waterfall'!AH10 -> -14.860087
B12: ARR Eligible for Billing | E12: =SUM(E7:E11) -> 75.371068 | F12: =SUM(F7:F11) -> 77.306652 | G12: =SUM(G7:G11) -> 80.657805 | H12: =SUM(H7:H11) -> 85.772627 | I12: =SUM(I7:I11) -> 77.060638 | J12: =SUM(J7:J11) -> 79.004669 | K12: =SUM(K7:K11) -> 82.364313 | L12: =SUM(L7:L11) -> 87.487667 | ... AB12: =SUM(AB7:AB11) -> 94.700452
B14: Upfront (Annual) Billing
B15: Cohort | C15: $ Eligible | D15: Cohort %
B16: {=TRANSPOSE(E5:AB5)} -> 44651 | C16: {=TRANSPOSE(E12:AB12)} -> 75.371068 | D16: 0.65 | E16: =$C16*$D16 -> 48.991194
B17: 44742 | C17: 77.306652 | D17: =+D16 -> 0.65 | F17: =$C17*$D17 -> 50.249323
B18: 44834 | C18: 80.657805 | D18: =+D17 -> 0.65 | G18: =$C18*$D18 -> 52.427573
B19: 44926 | C19: 85.772627 | D19: =+D18 -> 0.65 | H19: =$C19*$D19 -> 55.752207
B20: 45016 | C20: 77.060638 | D20: =+D19 -> 0.65 | I20: =$C20*$D20 -> 50.089415
B21: 45107 | C21: 79.004669 | D21: =+D20 -> 0.65 | J21: =$C21*$D21 -> 51.353035
B22: 45199 | C22: 82.364313 | D22: =+D21 -> 0.65 | K22: =$C22*$D22 -> 53.536803
B23: 45291 | C23: 87.487667 | D23: =+D22 -> 0.65 | L23: =$C23*$D23 -> 56.866984
B24: 45382 | C24: 78.784254 | D24: =+D23 -> 0.65 | M24: =$C24*$D24 -> 51.209765
B25: 45473 | C25: 80.736903 | D25: =+D24 -> 0.65 | N25: =$C25*$D25 -> 52.478987
B26: 45565 | C26: 84.105208 | D26: =+D25 -> 0.65 | O26: =$C26*$D26 -> 54.668385
B27: 45657 | C27: 89.237266 | D27: =+D26 -> 0.65 | P27: =$C27*$D27 -> 58.004223
B28: 45747 | C28: 80.542601 | D28: =+D27 -> 0.65 | Q28: =$C28*$D28 -> 52.352691
B29: 45838 | C29: 82.504042 | D29: =+D28 -> 0.65 | R29: =$C29*$D29 -> 53.627627
B30: 45930 | C30: 85.881183 | D30: =+D29 -> 0.65 | S30: =$C30*$D30 -> 55.822769
B31: 46022 | C31: 91.022121 | D31: =+D30 -> 0.65 | T31: =$C31*$D31 -> 59.164379
B32: 46112 | C32: 82.33638 | D32: =+D31 -> 0.65 | U32: =$C32*$D32 -> 53.518647
B33: 46203 | C33: 84.30679 | D33: =+D32 -> 0.65 | V33: =$C33*$D33 -> 54.799414
B34: 46295 | C34: 87.692944 | D34: =+D33 -> 0.65 | W34: =$C34*$D34 -> 57.000414
B35: 46387 | C35: 92.842942 | D35: =+D34 -> 0.65 | X35: =$C35*$D35 -> 60.347912
B36: 46477 | C36: 84.166305 | D36: =+D35 -> 0.65 | Y36: =$C36*$D36 -> 54.708098
B37: 46568 | C37: 86.145864 | D37: =+D36 -> 0.65 | Z37: =$C37*$D37 -> 55.994812
B38: 46660 | C38: 89.541214 | D38: =+D37 -> 0.65 | AA38: =$C38*$D38 -> 58.201789
B39: 46752 | C39: 94.700452 | D39: =+D38 -> 0.65 | AB39: =$C39*$D39 -> 61.555294
B42: Quarterly Billing
B43: Cohort | C43: $ Eligible | D43: Cohort %
B44: =+B16 -> 44651 | C44: =+C16 -> 75.371068 | D44: =1-D16 -> 0.35 | E44: =$C44*$D44/4 -> 6.5949685 | F44: =$C44*$D44/4 -> 6.5949685 | G44: =$C44*$D44/4 -> 6.5949685 | H44: =$C44*$D44/4 -> 6.5949685
...

Sheet Capitalizations
AA2: $ in millions, except noted
G3: 44926 | H3: =EOMONTH(G3, 3) -> 45016 | I3: =EOMONTH(H3, 3) -> 45107 | J3: =EOMONTH(I3, 3) -> 45199 | K3: =EOMONTH(J3, 3) -> 45291 | L3: =EOMONTH(K3, 3) -> 45382 | M3: =EOMONTH(L3, 3) -> 45473 | N3: =EOMONTH(M3, 3) -> 45565 | O3: =EOMONTH(N3, 3) -> 45657 | ... AA3: =EOMONTH(Z3, 3) -> 46752
B4: Deferred Commissions
B5: Balance Sheet
B6: Beginning Deferred Commissions | H6: =+G9 -> 14.2204 | I6: =+H9 -> 15.972382 | J6: =+I9 -> 17.572521 | K6: =+J9 -> 19.020057 | L6: =+K9 -> 20.314227 | M6: =+L9 -> 21.454265 | N6: =+M9 -> 22.4394 | O6: =+N9 -> 23.268856 | ... AA6: =+Z9 -> 23.954491
B7: New Deferred Commissions | H7: =+H12*H13 -> 2.6407574 | I7: =+I12*I13 -> 2.6539611 | J7: =+J12*J13 -> 2.667231 | K7: =+K12*K13 -> 2.6805671 | L7: =+L12*L13 -> 2.6939699 | M7: =+M12*M13 -> 2.7074398 | N7: =+N12*N13 -> 2.720977 | O7: =+O12*O13 -> 2.7345819 | ... AA7: =+AA12*AA13 -> 2.9032449
B8: Amortization of Deferred Commissions | H8: =+-H39 -> -0.888775 | I8: =+-I39 -> -1.0538223 | J8: =+-J39 -> -1.2196949 | K8: =+-K39 -> -1.3863968 | L8: =+-L39 -> -1.5539323 | M8: =+-M39 -> -1.7223054 | N8: =+-N39 -> -1.8915204 | O8: =+-O39 -> -2.0615815 | ... AA8: =+-AA39 -> -2.7834724
B9: Ending Deferred Commissions | G9: =Model!N54 -> 14.2204 | H9: =SUM(H6:H8) -> 15.972382 | I9: =SUM(I6:I8) -> 17.572521 | J9: =SUM(J6:J8) -> 19.020057 | K9: =SUM(K6:K8) -> 20.314227 | L9: =SUM(L6:L8) -> 21.454265 | M9: =SUM(M6:M8) -> 22.4394 | N9: =SUM(N6:N8) -> 23.268856 | O9: =SUM(O6:O8) -> 23.941857 | ... AA9: =SUM(AA6:AA8) -> 24.074264
B11: Memo/Drivers:
B12: Total S&M Expense | H12: =Model!O20 -> 14.670874 | I12: =Model!P20 -> 14.744229 | J12: =Model!Q20 -> 14.81795 | K12: =Model!R20 -> 14.892039 | L12: =Model!S20 -> 14.9665 | M12: =Model!T20 -> 15.041332 | N12: =Model!U20 -> 15.116539 | O12: =Model!V20 -> 15.192122 | ... AA12: =Model!AH20 -> 16.129138
B13: Deferred Comp as % of Total S&M Expense | H13: 0.18 | I13: 0.18 | J13: 0.18 | K13: 0.18 | L13: 0.18 | M13: 0.18 | N13: 0.18 | O13: 0.18 | P13: 0.18 | Q13: 0.18 | R13: 0.18 | S13: 0.18 | T13: 0.18 | U13: 0.18 | V13: 0.18 | W13: 0.18 | X13: 0.18 | Y13: 0.18 | Z13: 0.18 | AA13: 0.18
B15: Amortization Schedule
B16: Cohort | C16: $ Deferrals | D16: Years | E16: Quarters | F16: End
B17: {=TRANSPOSE(G3:AA3)} -> 44926 | C17: =G9 -> 14.2204 | D17: 4 | E17: =+D17*4 -> 16 | F17: =EOMONTH(B17, D17*12) -> 46387 | H17: =$C17/$E17 -> 0.888775 | I17: =$C17/$E17 -> 0.888775 | J17: =$C17/$E17 -> 0.888775 | K17: =$C17/$E17 -> 0.888775 | L17: =$C17/$E17 -> 0.888775 | M17: =$C17/$E17 -> 0.888775 | N17: =$C17/$E17 -> 0.888775 | O17: =$C17/$E17 -> 0.888775 | ... W17: =$C17/$E17 -> 0.888775
B18: 45016 | C18: {=TRANSPOSE(H7:AA7)} -> 2.6407574 | D18: 4 | E18: =+D18*4 -> 16 | F18: =EOMONTH(B18, D18*12) -> 46477 | I18: =$C18/$E18 -> 0.16504734 | J18: =$C18/$E18 -> 0.16504734 | K18: =$C18/$E18 -> 0.16504734 | L18: =$C18/$E18 -> 0.16504734 | M18: =$C18/$E18 -> 0.16504734 | N18: =$C18/$E18 -> 0.16504734 | O18: =$C18/$E18 -> 0.16504734 | P18: =$C18/$E18 -> 0.16504734 | ... X18: =$C18/$E18 -> 0.16504734
B19: 45107 | C19: 2.6539611 | D19: 4 | E19: =+D19*4 -> 16 | F19: =EOMONTH(B19, D19*12) -> 46568 | J19: =$C19/$E19 -> 0.16587257 | K19: =$C19/$E19 -> 0.16587257 | L19: =$C19/$E19 -> 0.16587257 | M19: =$C19/$E19 -> 0.16587257 | N19: =$C19/$E19 -> 0.16587257 | O19: =$C19/$E19 -> 0.16587257 | P19: =$C19/$E19 -> 0.16587257 | Q19: =$C19/$E19 -> 0.16587257 | ... Y19: =$C19/$E19 -> 0.16587257
B20: 45199 | C20: 2.667231 | D20: 4 | E20: =+D20*4 -> 16 | F20: =EOMONTH(B20, D20*12) -> 46660 | K20: =$C20/$E20 -> 0.16670193 | L20: =$C20/$E20 -> 0.16670193 | M20: =$C20/$E20 -> 0.16670193 | N20: =$C20/$E20 -> 0.16670193 | O20: =$C20/$E20 -> 0.16670193 | P20: =$C20/$E20 -> 0.16670193 | Q20: =$C20/$E20 -> 0.16670193 | R20: =$C20/$E20 -> 0.16670193 | ... Z20: =$C20/$E20 -> 0.16670193
B21: 45291 | C21: 2.6805671 | D21: 4 | E21: =+D21*4 -> 16 | F21: =EOMONTH(B21, D21*12) -> 46752 | L21: =$C21/$E21 -> 0.16753544 | M21: =$C21/$E21 -> 0.16753544 | N21: =$C21/$E21 -> 0.16753544 | O21: =$C21/$E21 -> 0.16753544 | P21: =$C21/$E21 -> 0.16753544 | Q21: =$C21/$E21 -> 0.16753544 | R21: =$C21/$E21 -> 0.16753544 | S21: =$C21/$E21 -> 0.16753544 | ... AA21: =$C21/$E21 -> 0.16753544
B22: 45382 | C22: 2.6939699 | D22: 4 | E22: =+D22*4 -> 16 | F22: =EOMONTH(B22, D22*12) -> 46843 | M22: =$C22/$E22 -> 0.16837312 | N22: =$C22/$E22 -> 0.16837312 | O22: =$C22/$E22 -> 0.16837312 | P22: =$C22/$E22 -> 0.16837312 | Q22: =$C22/$E22 -> 0.16837312 | R22: =$C22/$E22 -> 0.16837312 | S22: =$C22/$E22 -> 0.16837312 | T22: =$C22/$E22 -> 0.16837312 | ... AA22: =$C22/$E22 -> 0.16837312
B23: 45473 | C23: 2.7074398 | D23: 4 | E23: =+D23*4 -> 16 | F23: =EOMONTH(B23, D23*12) -> 46934 | N23: =$C23/$E23 -> 0.16921499 | O23: =$C23/$E23 -> 0.16921499 | P23: =$C23/$E23 -> 0.16921499 | Q23: =$C23/$E23 -> 0.16921499 | R23: =$C23/$E23 -> 0.16921499 | S23: =$C23/$E23 -> 0.16921499 | T23: =$C23/$E23 -> 0.16921499 | U23: =$C23/$E23 -> 0.16921499 | ... AA23: =$C23/$E23 -> 0.16921499
B24: 45565 | C24: 2.720977 | D24: 4 | E24: =+D24*4 -> 16 | F24: =EOMONTH(B24, D24*12) -> 47026 | O24: =$C24/$E24 -> 0.17006106 | P24: =$C24/$E24 -> 0.17006106 | Q24: =$C24/$E24 -> 0.17006106 | R24: =$C24/$E24 -> 0.17006106 | S24: =$C24/$E24 -> 0.17006106 | T24: =$C24/$E24 -> 0.17006106 | U24: =$C24/$E24 -> 0.17006106 | V24: =$C24/$E24 -> 0.17006106 | ... AA24: =$C24/$E24 -> 0.17006106
B25: 45657 | C25: 2.7345819 | D25: 4 | E25: =+D25*4 -> 16 | F25: =EOMONTH(B25, D25*12) -> 47118 | P25: =$C25/$E25 -> 0.17091137 | Q25: =$C25/$E25 -> 0.17091137 | R25: =$C25/$E25 -> 0.17091137 | S25: =$C25/$E25 -> 0.17091137 | T25: =$C25/$E25 -> 0.17091137 | U25: =$C25/$E25 -> 0.17091137 | V25: =$C25/$E25 -> 0.17091137 | W25: =$C25/$E25 -> 0.17091137 | ... AA25: =$C25/$E25 -> 0.17091137
B26: 45747 | C26: 2.7482548 | D26: 4 | E26: =+D26*4 -> 16 | F26: =EOMONTH(B26, D26*12) -> 47208 | Q26: =$C26/$E26 -> 0.17176592 | R26: =$C26/$E26 -> 0.17176592 | S26: =$C26/$E26 -> 0.17176592 | T26: =$C26/$E26 -> 0.17176592 | U26: =$C26/$E26 -> 0.17176592 | V26: =$C26/$E26 -> 0.17176592 | W26: =$C26/$E26 -> 0.17176592 | X26: =$C26/$E26 -> 0.17176592 | ... AA26: =$C26/$E26 -> 0.17176592
B27: 45838 | C27: 2.7619961 | D27: 4 | E27: =+D27*4 -> 16 | F27: =EOMONTH(B27, D27*12) -> 47299 | R27: =$C27/$E27 -> 0.17262475 | S27: =$C27/$E27 -> 0.17262475 | T27: =$C27/$E27 -> 0.17262475 | U27: =$C27/$E27 -> 0.17262475 | V27: =$C27/$E27 -> 0.17262475 | W27: =$C27/$E27 -> 0.17262475 | X27: =$C27/$E27 -> 0.17262475 | Y27: =$C27/$E27 -> 0.17262475 | ... AA27: =$C27/$E27 -> 0.17262475
B28: 45930 | C28: 2.775806 | D28: 4 | E28: =+D28*4 -> 16 | F28: =EOMONTH(B28, D28*12) -> 47391 | S28: =$C28/$E28 -> 0.17348788 | T28: =$C28/$E28 -> 0.17348788 | U28: =$C28/$E28 -> 0.17348788 | V28: =$C28/$E28 -> 0.17348788 | W28: =$C28/$E28 -> 0.17348788 | X28: =$C28/$E28 -> 0.17348788 | Y28: =$C28/$E28 -> 0.17348788 | Z28: =$C28/$E28 -> 0.17348788 | AA28: =$C28/$E28 -> 0.17348788
B29: 46022 | C29: 2.7896851 | D29: 4 | E29: =+D29*4 -> 16 | F29: =EOMONTH(B29, D29*12) -> 47483 | T29: =$C29/$E29 -> 0.17435532 | U29: =$C29/$E29 -> 0.17435532 | V29: =$C29/$E29 -> 0.17435532 | W29: =$C29/$E29 -> 0.17435532 | X29: =$C29/$E29 -> 0.17435532 | Y29: =$C29/$E29 -> 0.17435532 | Z29: =$C29/$E29 -> 0.17435532 | AA29: =$C29/$E29 -> 0.17435532
B30: 46112 | C30: 2.8036335 | D30: 4 | E30: =+D30*4 -> 16 | F30: =EOMONTH(B30, D30*12) -> 47573 | U30: =$C30/$E30 -> 0.17522709 | V30: =$C30/$E30 -> 0.17522709 | W30: =$C30/$E30 -> 0.17522709 | X30: =$C30/$E30 -> 0.17522709 | Y30: =$C30/$E30 -> 0.17522709 | Z30: =$C30/$E30 -> 0.17522709 | AA30: =$C30/$E30 -> 0.17522709
B31: 46203 | C31: 2.8176517 | D31: 4 | E31: =+D31*4 -> 16 | F31: =EOMONTH(B31, D31*12) -> 47664 | V31: =$C31/$E31 -> 0.17610323 | W31: =$C31/$E31 -> 0.17610323 | X31: =$C31/$E31 -> 0.17610323 | Y31: =$C31/$E31 -> 0.17610323 | Z31: =$C31/$E31 -> 0.17610323 | AA31: =$C31/$E31 -> 0.17610323
B32: 46295 | C32: 2.8317399 | D32: 4 | E32: =+D32*4 -> 16 | F32: =EOMONTH(B32, D32*12) -> 47756 | W32: =$C32/$E32 -> 0.17698375 | X32: =$C32/$E32 -> 0.17698375 | Y32: =$C32/$E32 -> 0.17698375 | Z32: =$C32/$E32 -> 0.17698375 | AA32: =$C32/$E32 -> 0.17698375
B33: 46387 | C33: 2.8458986 | D33: 4 | E33: =+D33*4 -> 16 | F33: =EOMONTH(B33, D33*12) -> 47848 | X33: =$C33/$E33 -> 0.17786866 | Y33: =$C33/$E33 -> 0.17786866 | Z33: =$C33/$E33 -> 0.17786866 | AA33: =$C33/$E33 -> 0.17786866
B34: 46477 | C34: 2.8601281 | D34: 4 | E34: =+D34*4 -> 16 | F34: =EOMONTH(B34, D34*12) -> 47938 | Y34: =$C34/$E34 -> 0.17875801 | Z34: =$C34/$E34 -> 0.17875801 | AA34: =$C34/$E34 -> 0.17875801
B35: 46568 | C35: 2.8744288 | D35: 4 | E35: =+D35*4 -> 16 | F35: =EOMONTH(B35, D35*12) -> 48029 | Z35: =$C35/$E35 -> 0.1796518 | AA35: =$C35/$E35 -> 0.1796518
B36: 46660 | C36: 2.8888009 | D36: 4 | E36: =+D36*4 -> 16 | F36: =EOMONTH(B36, D36*12) -> 48121 | AA36: =$C36/$E36 -> 0.18055006
B37: 46752 | C37: 2.9032449 | D37: 4 | E37: =+D37*4 -> 16 | F37: =EOMONTH(B37, D37*12) -> 48213
B39: Amortization of Deferred Compensation | H39: =SUM(H17:H38) -> 0.888775 | I39: =SUM(I17:I38) -> 1.0538223 | J39: =SUM(J17:J38) -> 1.2196949 | K39: =SUM(K17:K38) -> 1.3863968 | L39: =SUM(L17:L38) -> 1.5539323 | M39: =SUM(M17:M38) -> 1.7223054 | N39: =SUM(N17:N38) -> 1.8915204 | O39: =SUM(O17:O38) -> 2.0615815 | ... AA39: =SUM(AA17:AA38) -> 2.7834724
B44: Capitalized Software Costs
B45: Balance Sheet
B46: Beginning Capitalized Software Costs | H46: =+G49 -> 5.9109174 | I46: =+H49 -> 6.2514641 | J46: =+I49 -> 6.5704936 | K46: =+J49 -> 6.8678982 | L46: =+K49 -> 7.1435698 | M46: =+L49 -> 7.3973997 | N46: =+M49 -> 7.6292788 | O46: =+N49 -> 7.8390972 | ... AA46: =+Z49 -> 9.4078237
B47: New Capitalized Software Costs | H47: =H52*H53 -> 0.58683497 | I47: =I52*I53 -> 0.58976914 | J47: =J52*J53 -> 0.59271799 | K47: =K52*K53 -> 0.59568158 | L47: =L52*L53 -> 0.59865999 | M47: =M52*M53 -> 0.60165329 | N47: =N52*N53 -> 0.60466155 | O47: =O52*O53 -> 0.60768486 | ... AA47: =AA52*AA53 -> 0.64516553
B48: Amortization of Capitalized Software Costs | H48: =-H78 -> -0.24628822 | I48: =-I78 -> -0.27073968 | J48: =-J78 -> -0.29531339 | K48: =-K78 -> -0.32000998 | L48: =-L78 -> -0.34483004 | M48: =-M78 -> -0.36977421 | N48: =-N78 -> -0.3948431 | O48: =-O78 -> -0.42003733 | ... AA48: =-AA78 -> -0.41236629
...

Sheet SaaS Metrics
B2: Key Metrics | AH2: $ in millions, except noted
C3: =YEAR(C4) -> 2020 | D3: =YEAR(D4) -> 2020 | E3: =YEAR(E4) -> 2020 | F3: =YEAR(F4) -> 2020 | G3: =YEAR(G4) -> 2021 | H3: =YEAR(H4) -> 2021 | I3: =YEAR(I4) -> 2021 | J3: =YEAR(J4) -> 2021 | ... AH3: =YEAR(AH4) -> 2027
C4: ='ARR Waterfall'!C4 -> 43921 | D4: =EOMONTH(C4, 3) -> 44012 | E4: =EOMONTH(D4, 3) -> 44104 | F4: =EOMONTH(E4, 3) -> 44196 | G4: =EOMONTH(F4, 3) -> 44286 | H4: =EOMONTH(G4, 3) -> 44377 | I4: =EOMONTH(H4, 3) -> 44469 | J4: =EOMONTH(I4, 3) -> 44561 | K4: =EOMONTH(J4, 3) -> 44651 | ... AH4: =EOMONTH(AG4, 3) -> 46752
B5: =+'ARR Waterfall'!B5 -> ARR Build
B6: =+'ARR Waterfall'!B6 -> Beginning ARR | C6: =+'ARR Waterfall'!C6 -> 289.19772 | D6: =+'ARR Waterfall'!D6 -> 301.18761 | E6: =+'ARR Waterfall'!E6 -> 304.4751 | F6: =+'ARR Waterfall'!F6 -> 308.34238 | G6: =+'ARR Waterfall'!G6 -> 313.78571 | H6: =+'ARR Waterfall'!H6 -> 310.36867 | I6: =+'ARR Waterfall'!I6 -> 309.6027 | ... AH6: =+'ARR Waterfall'!AH6 -> 371.50217
B7: =+'ARR Waterfall'!B7 -> New Logo ARR | C7: =+'ARR Waterfall'!C7 -> 16.54272 | D7: =+'ARR Waterfall'!D7 -> 12.672 | E7: =+'ARR Waterfall'!E7 -> 10.78272 | F7: =+'ARR Waterfall'!F7 -> 12.034256 | G7: =+'ARR Waterfall'!G7 -> 6.912 | H7: =+'ARR Waterfall'!H7 -> 7.87968 | I7: =+'ARR Waterfall'!I7 -> 11.52 | ... AH7: =+'ARR Waterfall'!AH7 -> 14.860087
B8: =+'ARR Waterfall'!B8 -> Upsell ARR | C8: =+'ARR Waterfall'!C8 -> 6.277032 | D8: =+'ARR Waterfall'!D8 -> 4.857832 | E8: =+'ARR Waterfall'!E8 -> 3.987528 | F8: =+'ARR Waterfall'!F8 -> 5.73084 | G8: =+'ARR Waterfall'!G8 -> 5.394216 | H8: =+'ARR Waterfall'!H8 -> 6.486064 | I8: =+'ARR Waterfall'!I8 -> 5.75956 | ... AH8: =+'ARR Waterfall'!AH8 -> 5.5725326
B9: =+'ARR Waterfall'!B9 -> Downsell ARR | C9: =+'ARR Waterfall'!C9 -> -3.550296 | D9: =+'ARR Waterfall'!D9 -> -4.078288 | E9: =+'ARR Waterfall'!E9 -> -3.61396 | F9: =+'ARR Waterfall'!F9 -> -4.169752 | G9: =+'ARR Waterfall'!G9 -> -3.52144 | H9: =+'ARR Waterfall'!H9 -> -4.33488 | I9: =+'ARR Waterfall'!I9 -> -4.362616 | ... AH9: =+'ARR Waterfall'!AH9 -> -3.7150217
B10: =+'ARR Waterfall'!B10 -> Churn ARR | C10: =+'ARR Waterfall'!C10 -> -7.279568 | D10: =+'ARR Waterfall'!D10 -> -10.164048 | E10: =+'ARR Waterfall'!E10 -> -7.289016 | F10: =+'ARR Waterfall'!F10 -> -8.152008 | G10: =+'ARR Waterfall'!G10 -> -12.201816 | H10: =+'ARR Waterfall'!H10 -> -10.79684 | I10: =+'ARR Waterfall'!I10 -> -10.030816 | ... AH10: =+'ARR Waterfall'!AH10 -> -14.860087
B11: =+'ARR Waterfall'!B11 -> Ending ARR | C11: =+'ARR Waterfall'!C11 -> 301.18761 | D11: =+'ARR Waterfall'!D11 -> 304.4751 | E11: =+'ARR Waterfall'!E11 -> 308.34238 | F11: =+'ARR Waterfall'!F11 -> 313.78571 | G11: =+'ARR Waterfall'!G11 -> 310.36867 | H11: =+'ARR Waterfall'!H11 -> 309.6027 | I11: =+'ARR Waterfall'!I11 -> 312.48882 | ... AH11: =+'ARR Waterfall'!AH11 -> 373.35968
B13: =+'ARR Waterfall'!B20 -> Customer Bridge
B14: =+'ARR Waterfall'!B21 -> Beginning Customers | C14: =+'ARR Waterfall'!C21 -> 124 | D14: =+'ARR Waterfall'!D21 -> 126 | E14: =+'ARR Waterfall'!E21 -> 127 | F14: =+'ARR Waterfall'!F21 -> 130 | G14: =+'ARR Waterfall'!G21 -> 132 | H14: =+'ARR Waterfall'!H21 -> 131 | I14: =+'ARR Waterfall'!I21 -> 131 | ... AH14: =+'ARR Waterfall'!AH21 -> 170.50433
B15: =+'ARR Waterfall'!B22 -> New Customers | C15: =+'ARR Waterfall'!C22 -> 6 | D15: =+'ARR Waterfall'!D22 -> 6 | E15: =+'ARR Waterfall'!E22 -> 6 | F15: =+'ARR Waterfall'!F22 -> 5 | G15: =+'ARR Waterfall'!G22 -> 4 | H15: =+'ARR Waterfall'!H22 -> 4 | I15: =+'ARR Waterfall'!I22 -> 5 | ... AH15: =+'ARR Waterfall'!AH22 -> 7.0762319
B16: =+'ARR Waterfall'!B23 -> Churn Customers | C16: =+'ARR Waterfall'!C23 -> -4 | D16: =+'ARR Waterfall'!D23 -> -5 | E16: =+'ARR Waterfall'!E23 -> -3 | F16: =+'ARR Waterfall'!F23 -> -3 | G16: =+'ARR Waterfall'!G23 -> -5 | H16: =+'ARR Waterfall'!H23 -> -4 | I16: =+'ARR Waterfall'!I23 -> -3 | ... AH16: =+'ARR Waterfall'!AH23 -> -5.5551727
B17: =+'ARR Waterfall'!B24 -> Ending Customers | C17: =+'ARR Waterfall'!C24 -> 126 | D17: =+'ARR Waterfall'!D24 -> 127 | E17: =+'ARR Waterfall'!E24 -> 130 | F17: =+'ARR Waterfall'!F24 -> 132 | G17: =+'ARR Waterfall'!G24 -> 131 | H17: =+'ARR Waterfall'!H24 -> 131 | I17: =+'ARR Waterfall'!I24 -> 133 | ... AH17: =+'ARR Waterfall'!AH24 -> 172.02539
B20: Revenue & Retention
B21: YoY ARR Growth
B22: Ending ARR | C22: =+'ARR Waterfall'!C11 -> 301.18761 | D22: =+'ARR Waterfall'!D11 -> 304.4751 | E22: =+'ARR Waterfall'!E11 -> 308.34238 | F22: =+'ARR Waterfall'!F11 -> 313.78571 | G22: =+'ARR Waterfall'!G11 -> 310.36867 | H22: =+'ARR Waterfall'!H11 -> 309.6027 | I22: =+'ARR Waterfall'!I11 -> 312.48882 | J22: =+'ARR Waterfall'!J11 -> 315.91418 | ... AH22: =+'ARR Waterfall'!AH11 -> 373.35968
B23: YoY ARR Growth | G23: =+G22/C22-1 -> 0.030482874 | H23: =+H22/D22-1 -> 0.016840759 | I23: =+I22/E22-1 -> 0.013447545 | J23: =+J22/F22-1 -> 0.0067832024 | K23: =+K22/G22-1 -> 0.026340777 | L23: =+L22/H22-1 -> 0.039668698 | M23: =+M22/I22-1 -> 0.049247534 | N23: =+N22/J22-1 -> 0.069638583 | ... AH23: =+AH22/AD22-1 -> 0.020150501
B25: Retention
B26: Annualized Net Dollar Retention | C26: {=1+((SUM(C8:C10/C6)*4))} -> 0.93702811 | D26: {=1+((SUM(D8:D10/D6)*4))} -> 0.87536667 | E26: {=1+((SUM(E8:E10/E6)*4))} -> 0.90914925 | F26: {=1+((SUM(F8:F10/F6)*4))} -> 0.91449868 | G26: {=1+((SUM(G8:G10/G6)*4))} -> 0.86833001 | H26: {=1+((SUM(H8:H10/H6)*4))} -> 0.88857566 | I26: {=1+((SUM(I8:I10/I6)*4))} -> 0.88845224 | J26: {=1+((SUM(J8:J10/J6)*4))} -> 0.88399816 | ... AH26: {=1+((SUM(AH8:AH10/AH6)*4))} -> 0.86
B27: Annualized Gross Dollar Retention | C27: =1+((SUM(C9:C10)/C6)*4) -> 0.85020817 | D27: =1+((SUM(D9:D10)/D6)*4) -> 0.81085097 | E27: =1+((SUM(E9:E10)/E6)*4) -> 0.85676365 | F27: =1+((SUM(F9:F10)/F6)*4) -> 0.84015483 | G27: =1+((SUM(G9:G10)/G6)*4) -> 0.79956696 | H27: =1+((SUM(H9:H10)/H6)*4) -> 0.80498393 | I27: =1+((SUM(I9:I10)/I6)*4) -> 0.81403997 | J27: =1+((SUM(J9:J10)/J6)*4) -> 0.8001103 | ... AH27: =1+((SUM(AH9:AH10)/AH6)*4) -> 0.8
B28: Annualized Logo Retention | C28: =1+((C16/C14)*4) -> 0.87096774 | D28: =1+((D16/D14)*4) -> 0.84126984 | E28: =1+((E16/E14)*4) -> 0.90551181 | F28: =1+((F16/F14)*4) -> 0.90769231 | G28: =1+((G16/G14)*4) -> 0.84848485 | H28: =1+((H16/H14)*4) -> 0.8778626 | I28: =1+((I16/I14)*4) -> 0.90839695 | J28: =1+((J16/J14)*4) -> 0.81954887 | ... AH28: =1+((AH16/AH14)*4) -> 0.86967668
B30: Quick Ratio
B31: New Logo ARR | C31: =+C7 -> 16.54272 | D31: =+D7 -> 12.672 | E31: =+E7 -> 10.78272 | F31: =+F7 -> 12.034256 | G31: =+G7 -> 6.912 | H31: =+H7 -> 7.87968 | I31: =+I7 -> 11.52 | J31: =+J7 -> 12.48768 | ... AH31: =+AH7 -> 14.860087
B32: Upsell ARR | C32: =+C8 -> 6.277032 | D32: =+D8 -> 4.857832 | E32: =+E8 -> 3.987528 | F32: =+F8 -> 5.73084 | G32: =+G8 -> 5.394216 | H32: =+H8 -> 6.486064 | I32: =+I8 -> 5.75956 | J32: =+J8 -> 6.553504 | ... AH32: =+AH8 -> 5.5725326
B33: Downsell ARR | C33: =+C9 -> -3.550296 | D33: =+D9 -> -4.078288 | E33: =+E9 -> -3.61396 | F33: =+F9 -> -4.169752 | G33: =+G9 -> -3.52144 | H33: =+H9 -> -4.33488 | I33: =+I9 -> -4.362616 | J33: =+J9 -> -3.73416 | ... AH33: =+AH9 -> -3.7150217
B34: Churn ARR | C34: =+C10 -> -7.279568 | D34: =+D10 -> -10.164048 | E34: =+E10 -> -7.289016 | F34: =+F10 -> -8.152008 | G34: =+G10 -> -12.201816 | H34: =+H10 -> -10.79684 | I34: =+I10 -> -10.030816 | J34: =+J10 -> -11.881664 | ... AH34: =+AH10 -> -14.860087
B35: Quick Ratio | C35: =-SUM(C31:C32)/SUM(C33:C34) -> 2.1071134 | D35: =-SUM(D31:D32)/SUM(D33:D34) -> 1.2308256 | E35: =-SUM(E31:E32)/SUM(E33:E34) -> 1.3546988 | F35: =-SUM(F31:F32)/SUM(F33:F34) -> 1.4417661 | G35: =-SUM(G31:G32)/SUM(G33:G34) -> 0.78267606 | H35: =-SUM(H31:H32)/SUM(H33:H34) -> 0.94937945 | I35: =-SUM(I31:I32)/SUM(I33:I34) -> 1.200517 | J35: =-SUM(J31:J32)/SUM(J33:J34) -> 1.2193519 | ... AH35: =-SUM(AH31:AH32)/SUM(AH33:AH34) -> 1.1
B37: Efficiency
B38: Rule of 40
B39: LTM GAAP Revenue | C39: =SUM(Model!C8:C8) -> 73.455054 | D39: =SUM(Model!C8:D8) -> 147.32419 | E39: =SUM(Model!C8:E8) -> 224.46212 | F39: =SUM(Model!C8:F8) -> 302.6107 | G39: =SUM(Model!D8:G8) -> 306.14576 | H39: =SUM(Model!E8:H8) -> 309.22635 | I39: =SUM(Model!F8:I8) -> 310.08463 | J39: =SUM(Model!G8:J8) -> 309.95496 | K39: =SUM(Model!H8:K8) -> 312.16277 | L39: =SUM(Model!I8:L8) -> 315.35929 | M39: =SUM(Model!J8:M8) -> 319.13177 | ... AH39: =SUM(Model!AE8:AH8) -> 355.75934
B40: LTM EBITDA | C40: =SUM(Model!C33:C33) -> 0 | D40: =SUM(Model!C33:D33) -> 0 | E40: =SUM(Model!C33:E33) -> 0 | F40: =SUM(Model!C33:F33) -> 35.199162 | G40: =SUM(Model!D33:G33) -> 71.786924 | H40: =SUM(Model!E33:H33) -> 107.03109 | I40: =SUM(Model!F33:I33) -> 142.75366 | J40: =SUM(Model!G33:J33) -> 143.85535 | K40: =SUM(Model!H33:K33) -> 143.29853 | L40: =SUM(Model!I33:L33) -> 144.41192 | M40: =SUM(Model!J33:M33) -> 145.75263 | ... AH40: =SUM(Model!AE33:AH33) -> 176.07296
B41: YoY Growth | G41: =G39/C39-1 -> 3.1677971 | H41: =H39/D39-1 -> 1.0989515 | I41: =I39/E39-1 -> 0.38145639 | J41: =J39/F39-1 -> 0.024269644 | K41: =K39/G39-1 -> 0.019654072 | L41: =L39/H39-1 -> 0.019833198 | M41: =M39/I39-1 -> 0.029176342 | N41: =N39/J39-1 -> 0.04373284 | ... AH41: =AH39/AD39-1 -> 0.020150501
B42: EBITDA Margin | G42: =G40/G39 -> 0.2344861 | H42: =H40/H39 -> 0.3461254 | I42: =I40/I39 -> 0.46037 | J42: =J40/J39 -> 0.46411696 | K42: =K40/K39 -> 0.45905066 | L42: =L40/L39 -> 0.45792821 | M42: =M40/M39 -> 0.45671615 | N42: =N40/N39 -> 0.45157342 | ... AH42: =AH40/AH39 -> 0.49492153
B43: Rule of 40 | G43: =G41+G42 -> 3.4022832 | H43: =H41+H42 -> 1.4450769 | I43: =I41+I42 -> 0.84182639 | J43: =J41+J42 -> 0.48838661 | K43: =K41+K42 -> 0.47870473 | L43: =L41+L42 -> 0.47776141 | M43: =M41+M42 -> 0.4858925 | N43: =N41+N42 -> 0.49530626 | ... AH43: =AH41+AH42 -> 0.51507203
B45: Magic Number
B46: New Logo ARR | D46: =+D7 -> 12.672 | E46: =+E7 -> 10.78272 | F46: =+F7 -> 12.034256 | G46: =+G7 -> 6.912 | H46: =+H7 -> 7.87968 | I46: =+I7 -> 11.52 | J46: =+J7 -> 12.48768 | K46: =+K7 -> 15.34464 | ... AH46: =+AH7 -> 14.860087
B47: Upsell ARR | D47: =+D8 -> 4.857832 | E47: =+E8 -> 3.987528 | F47: =+F8 -> 5.73084 | G47: =+G8 -> 5.394216 | H47: =+H8 -> 6.486064 | I47: =+I8 -> 5.75956 | J47: =+J8 -> 6.553504 | K47: =+K8 -> 4.374232 | ... AH47: =+AH8 -> 5.5725326
B48: Prior Period S&M | D48: =+Model!C20 -> 14.00397 | E48: =+Model!D20 -> 14.083162 | F48: =+Model!E20 -> 14.056085 | G48: =+Model!F20 -> 14.845196 | H48: =+Model!G20 -> 13.968859 | I48: =+Model!H20 -> 14.048706 | J48: =+Model!I20 -> 14.759204 | K48: =+Model!J20 -> 14.257532 | ... AH48: =+Model!AG20 -> 16.048894
...

Sheet Cohorts
A1: 1000000
B2: Cohorts | O2: $ in millions, except noted
D3: =EOMONTH(#REF!, 3) -> #REF! | E3: =EOMONTH(D3, 3) -> #REF! | F3: =EOMONTH(E3, 3) -> #REF! | G3: =EOMONTH(F3, 3) -> #REF! | H3: =EOMONTH(G3, 3) -> #REF! | I3: =EOMONTH(H3, 3) -> #REF! | J3: =EOMONTH(I3, 3) -> #REF! | K3: =EOMONTH(J3, 3) -> #REF! | L3: =EOMONTH(K3, 3) -> #REF! | ... O3: =EOMONTH(N3, 3) -> #REF!
D4: =EOMONTH(#REF!, 2)+1 -> #REF! | E4: =EOMONTH(D4, 2)+1 -> #REF! | F4: =EOMONTH(E4, 2)+1 -> #REF! | G4: =EOMONTH(F4, 2)+1 -> #REF! | H4: =EOMONTH(G4, 2)+1 -> #REF! | I4: =EOMONTH(H4, 2)+1 -> #REF! | J4: =EOMONTH(I4, 2)+1 -> #REF! | K4: =EOMONTH(J4, 2)+1 -> #REF! | L4: =EOMONTH(K4, 2)+1 -> #REF! | ... O4: =EOMONTH(N4, 2)+1 -> #REF!
D5: ='Raw Customer ARR'!D1 -> 43921 | E5: =EOMONTH(D5, 3) -> 44012 | F5: =EOMONTH(E5, 3) -> 44104 | G5: =EOMONTH(F5, 3) -> 44196 | H5: =EOMONTH(G5, 3) -> 44286 | I5: =EOMONTH(H5, 3) -> 44377 | J5: =EOMONTH(I5, 3) -> 44469 | K5: =EOMONTH(J5, 3) -> 44561 | L5: =EOMONTH(K5, 3) -> 44651 | ... O5: =EOMONTH(N5, 3) -> 44926
B6: ARR by Cohort
B7: =EOMONTH(B8, -3) -> 43830 | D7: =SUMIFS('Raw Customer ARR'!D$2:D$197, 'Raw Customer ARR'!$B$2:$B$197, Cohorts!$B7)/unit -> 284.64489 | E7: =SUMIFS('Raw Customer ARR'!E$2:E$197, 'Raw Customer ARR'!$B$2:$B$197, Cohorts!$B7)/unit -> 275.26038 | F7: =SUMIFS('Raw Customer ARR'!F$2:F$197, 'Raw Customer ARR'!$B$2:$B$197, Cohorts!$B7)/unit -> 268.06846 | G7: =SUMIFS('Raw Customer ARR'!G$2:G$197, 'Raw Customer ARR'!$B$2:$B$197, Cohorts!$B7)/unit -> 261.81396 | H7: =SUMIFS('Raw Customer ARR'!H$2:H$197, 'Raw Customer ARR'!$B$2:$B$197, Cohorts!$B7)/unit -> 251.87383 | I7: =SUMIFS('Raw Customer ARR'!I$2:I$197, 'Raw Customer ARR'!$B$2:$B$197, Cohorts!$B7)/unit -> 243.39045 | J7: =SUMIFS('Raw Customer ARR'!J$2:J$197, 'Raw Customer ARR'!$B$2:$B$197, Cohorts!$B7)/unit -> 234.13417 | K7: =SUMIFS('Raw Customer ARR'!K$2:K$197, 'Raw Customer ARR'!$B$2:$B$197, Cohorts!$B7)/unit -> 224.92661 | ... O7: =SUMIFS('Raw Customer ARR'!O$2:O$197, 'Raw Customer ARR'!$B$2:$B$197, Cohorts!$B7)/unit -> 186.91562
B8: {=TRANSPOSE(D5:O5)} -> 43921 | D8: =SUMIFS('Raw Customer ARR'!D$2:D$197, 'Raw Customer ARR'!$B$2:$B$197, Cohorts!$B8)/unit -> 16.54272 | E8: =SUMIFS('Raw Customer ARR'!E$2:E$197, 'Raw Customer ARR'!$B$2:$B$197, Cohorts!$B8)/unit -> 16.54272 | F8: =SUMIFS('Raw Customer ARR'!F$2:F$197, 'Raw Customer ARR'!$B$2:$B$197, Cohorts!$B8)/unit -> 16.95744 | G8: =SUMIFS('Raw Customer ARR'!G$2:G$197, 'Raw Customer ARR'!$B$2:$B$197, Cohorts!$B8)/unit -> 16.77312 | H8: =SUMIFS('Raw Customer ARR'!H$2:H$197, 'Raw Customer ARR'!$B$2:$B$197, Cohorts!$B8)/unit -> 16.5888 | I8: =SUMIFS('Raw Customer ARR'!I$2:I$197, 'Raw Customer ARR'!$B$2:$B$197, Cohorts!$B8)/unit -> 16.9132 | J8: =SUMIFS('Raw Customer ARR'!J$2:J$197, 'Raw Customer ARR'!$B$2:$B$197, Cohorts!$B8)/unit -> 17.198088 | K8: =SUMIFS('Raw Customer ARR'!K$2:K$197, 'Raw Customer ARR'!$B$2:$B$197, Cohorts!$B8)/unit -> 16.718856 | ... O8: =SUMIFS('Raw Customer ARR'!O$2:O$197, 'Raw Customer ARR'!$B$2:$B$197, Cohorts!$B8)/unit -> 16.882752
B9: 44012 | D9: =SUMIFS('Raw Customer ARR'!D$2:D$197, 'Raw Customer ARR'!$B$2:$B$197, Cohorts!$B9)/unit -> 0 | E9: =SUMIFS('Raw Customer ARR'!E$2:E$197, 'Raw Customer ARR'!$B$2:$B$197, Cohorts!$B9)/unit -> 12.672 | F9: =SUMIFS('Raw Customer ARR'!F$2:F$197, 'Raw Customer ARR'!$B$2:$B$197, Cohorts!$B9)/unit -> 12.53376 | G9: =SUMIFS('Raw Customer ARR'!G$2:G$197, 'Raw Customer ARR'!$B$2:$B$197, Cohorts!$B9)/unit -> 12.243416 | H9: =SUMIFS('Raw Customer ARR'!H$2:H$197, 'Raw Customer ARR'!$B$2:$B$197, Cohorts!$B9)/unit -> 12.18628 | I9: =SUMIFS('Raw Customer ARR'!I$2:I$197, 'Raw Customer ARR'!$B$2:$B$197, Cohorts!$B9)/unit -> 11.574272 | J9: =SUMIFS('Raw Customer ARR'!J$2:J$197, 'Raw Customer ARR'!$B$2:$B$197, Cohorts!$B9)/unit -> 11.119808 | K9: =SUMIFS('Raw Customer ARR'!K$2:K$197, 'Raw Customer ARR'!$B$2:$B$197, Cohorts!$B9)/unit -> 10.885792 | ... O9: =SUMIFS('Raw Customer ARR'!O$2:O$197, 'Raw Customer ARR'!$B$2:$B$197, Cohorts!$B9)/unit -> 8.548288
B10: 44104 | D10: =SUMIFS('Raw Customer ARR'!D$2:D$197, 'Raw Customer ARR'!$B$2:$B$197, Cohorts!$B10)/unit -> 0 | E10: =SUMIFS('Raw Customer ARR'!E$2:E$197, 'Raw Customer ARR'!$B$2:$B$197, Cohorts!$B10)/unit -> 0 | F10: =SUMIFS('Raw Customer ARR'!F$2:F$197, 'Raw Customer ARR'!$B$2:$B$197, Cohorts!$B10)/unit -> 10.78272 | G10: =SUMIFS('Raw Customer ARR'!G$2:G$197, 'Raw Customer ARR'!$B$2:$B$197, Cohorts!$B10)/unit -> 10.92096 | H10: =SUMIFS('Raw Customer ARR'!H$2:H$197, 'Raw Customer ARR'!$B$2:$B$197, Cohorts!$B10)/unit -> 10.92096 | I10: =SUMIFS('Raw Customer ARR'!I$2:I$197, 'Raw Customer ARR'!$B$2:$B$197, Cohorts!$B10)/unit -> 10.73664 | J10: =SUMIFS('Raw Customer ARR'!J$2:J$197, 'Raw Customer ARR'!$B$2:$B$197, Cohorts!$B10)/unit -> 10.891472 | K10: =SUMIFS('Raw Customer ARR'!K$2:K$197, 'Raw Customer ARR'!$B$2:$B$197, Cohorts!$B10)/unit -> 10.343008 | ... O10: =SUMIFS('Raw Customer ARR'!O$2:O$197, 'Raw Customer ARR'!$B$2:$B$197, Cohorts!$B10)/unit -> 8.252008
B11: 44196 | D11: =SUMIFS('Raw Customer ARR'!D$2:D$197, 'Raw Customer ARR'!$B$2:$B$197, Cohorts!$B11)/unit -> 0 | E11: =SUMIFS('Raw Customer ARR'!E$2:E$197, 'Raw Customer ARR'!$B$2:$B$197, Cohorts!$B11)/unit -> 0 | F11: =SUMIFS('Raw Customer ARR'!F$2:F$197, 'Raw Customer ARR'!$B$2:$B$197, Cohorts!$B11)/unit -> 0 | G11: =SUMIFS('Raw Customer ARR'!G$2:G$197, 'Raw Customer ARR'!$B$2:$B$197, Cohorts!$B11)/unit -> 12.034256 | H11: =SUMIFS('Raw Customer ARR'!H$2:H$197, 'Raw Customer ARR'!$B$2:$B$197, Cohorts!$B11)/unit -> 11.8868 | I11: =SUMIFS('Raw Customer ARR'!I$2:I$197, 'Raw Customer ARR'!$B$2:$B$197, Cohorts!$B11)/unit -> 12.196456 | J11: =SUMIFS('Raw Customer ARR'!J$2:J$197, 'Raw Customer ARR'!$B$2:$B$197, Cohorts!$B11)/unit -> 12.533168 | K11: =SUMIFS('Raw Customer ARR'!K$2:K$197, 'Raw Customer ARR'!$B$2:$B$197, Cohorts!$B11)/unit -> 12.723976 | ... O11: =SUMIFS('Raw Customer ARR'!O$2:O$197, 'Raw Customer ARR'!$B$2:$B$197, Cohorts!$B11)/unit -> 12.244904
B12: 44286 | D12: =SUMIFS('Raw Customer ARR'!D$2:D$197, 'Raw Customer ARR'!$B$2:$B$197, Cohorts!$B12)/unit -> 0 | E12: =SUMIFS('Raw Customer ARR'!E$2:E$197, 'Raw Customer ARR'!$B$2:$B$197, Cohorts!$B12)/unit -> 0 | F12: =SUMIFS('Raw Customer ARR'!F$2:F$197, 'Raw Customer ARR'!$B$2:$B$197, Cohorts!$B12)/unit -> 0 | G12: =SUMIFS('Raw Customer ARR'!G$2:G$197, 'Raw Customer ARR'!$B$2:$B$197, Cohorts!$B12)/unit -> 0 | H12: =SUMIFS('Raw Customer ARR'!H$2:H$197, 'Raw Customer ARR'!$B$2:$B$197, Cohorts!$B12)/unit -> 6.912 | I12: =SUMIFS('Raw Customer ARR'!I$2:I$197, 'Raw Customer ARR'!$B$2:$B$197, Cohorts!$B12)/unit -> 6.912 | J12: =SUMIFS('Raw Customer ARR'!J$2:J$197, 'Raw Customer ARR'!$B$2:$B$197, Cohorts!$B12)/unit -> 7.32672 | K12: =SUMIFS('Raw Customer ARR'!K$2:K$197, 'Raw Customer ARR'!$B$2:$B$197, Cohorts!$B12)/unit -> 8.219272 | ... O12: =SUMIFS('Raw Customer ARR'!O$2:O$197, 'Raw Customer ARR'!$B$2:$B$197, Cohorts!$B12)/unit -> 8.650912
B13: 44377 | D13: =SUMIFS('Raw Customer ARR'!D$2:D$197, 'Raw Customer ARR'!$B$2:$B$197, Cohorts!$B13)/unit -> 0 | E13: =SUMIFS('Raw Customer ARR'!E$2:E$197, 'Raw Customer ARR'!$B$2:$B$197, Cohorts!$B13)/unit -> 0 | F13: =SUMIFS('Raw Customer ARR'!F$2:F$197, 'Raw Customer ARR'!$B$2:$B$197, Cohorts!$B13)/unit -> 0 | G13: =SUMIFS('Raw Customer ARR'!G$2:G$197, 'Raw Customer ARR'!$B$2:$B$197, Cohorts!$B13)/unit -> 0 | H13: =SUMIFS('Raw Customer ARR'!H$2:H$197, 'Raw Customer ARR'!$B$2:$B$197, Cohorts!$B13)/unit -> 0 | I13: =SUMIFS('Raw Customer ARR'!I$2:I$197, 'Raw Customer ARR'!$B$2:$B$197, Cohorts!$B13)/unit -> 7.87968 | J13: =SUMIFS('Raw Customer ARR'!J$2:J$197, 'Raw Customer ARR'!$B$2:$B$197, Cohorts!$B13)/unit -> 7.7654 | K13: =SUMIFS('Raw Customer ARR'!K$2:K$197, 'Raw Customer ARR'!$B$2:$B$197, Cohorts!$B13)/unit -> 8.442888 | ... O13: =SUMIFS('Raw Customer ARR'!O$2:O$197, 'Raw Customer ARR'!$B$2:$B$197, Cohorts!$B13)/unit -> 8.164224
