Workbook

Sheet Resources
B4: GO, GO, GO!
B5: Practice really does make perfect!
B6: You got this! :-)
B10: This template is part of a comprehensive course for growth stage investing interviews & roles.
B11: For more video courses and tutorials:
B13: =HYPERLINK("https://GrowthEquityInterviewGuide.com", "GrowthEquityInterviewGuide.com") -> GrowthEquityInterviewGuide.com
B25: All rights reserved. Growth Equity Interview Guide.

Sheet Start ->

Sheet Model (Start - Video)
B2: Assumptions | J2: $ millions
B3: Entry assumptions | E3: Transaction assumptions
B4: LTM revenue | C4: =+E42 -> 50.83 | E4: Transaction fees | G4: 0.01
B5: Entry multiple | C5: 18 | E5: Financing fees | G5: 0.02
B6: Enterprise value | C6: =+C5*C4 -> 914.94
B7: (-) Debt | C7: =+C33 -> 0
B8: (+) Cash | C8: =+C25 -> 5
B9: Equity value | C9: =+C6-C7+C8 -> 919.94
B12: Sources & uses | J12: $ millions
B13: Sources | G13: Uses
B14: New debt | D14: 0 | G14: Purchase TEV | J14: =+C6 -> 914.94
B15: Sponsor equity | D15: =+J19-D14 -> 934.0894 | G15: Ending cash balance | J15: 10
G16: Transaction fees | J16: =+G4*C6 -> 9.1494
G17: Financing fees | J17: =+G5*D14 -> 0
B19: Total sources | D19: =SUM(D14:D18) -> 934.0894 | G19: Total uses | J19: =SUM(J14:J18) -> 934.0894
B23: Model | J23: $ millions
B24: Balance sheet | C24: 0 | D24: Adjust. | E24: Pro forma | F24: 1 | G24: =F24+1 -> 2 | H24: =G24+1 -> 3 | I24: =H24+1 -> 4 | J24: =I24+1 -> 5
B25: Cash | C25: 5 | D25: =+E25-C25 -> 5 | E25: =+J15 -> 10 | F25: =+F122+E25 -> 5 | G25: =+G122+F25 -> 5 | H25: =+H122+G25 -> 5 | I25: =+I122+H25 -> 5 | J25: =+J122+I25 -> 5
B26: Net working capital | C26: 100 | E26: =+D26+C26 -> 100 | F26: =+F80 -> 105 | G26: =+G80 -> 110 | H26: =+H80 -> 115 | I26: =+I80 -> 120 | J26: =+J80 -> 125
B27: Capitalized financing fees | C27: 0 | D27: =+J17 -> 0 | E27: =+D27+C27 -> 0 | F27: =+F91 -> 0 | G27: =+G91 -> 0 | H27: =+H91 -> 0 | I27: =+I91 -> 0 | J27: =+J91 -> 0
B28: Goodwill | C28: 0 | D28: =+C9-C36 -> 774.94 | E28: =+D28+C28 -> 774.94 | F28: =+E28 -> 774.94 | G28: =+F28 -> 774.94 | H28: =+G28 -> 774.94 | I28: =+H28 -> 774.94 | J28: =+I28 -> 774.94
B29: Deferred tax asset | C29: 20 | E29: =+D29+C29 -> 20 | F29: =+E29 -> 20 | G29: =+F29 -> 20 | H29: =+G29 -> 20 | I29: =+H29 -> 20 | J29: =+I29 -> 20
B30: Net PP&E | C30: 20 | E30: =+D30+C30 -> 20 | F30: =+F85 -> 21.42324 | G30: =+G85 -> 23.415776 | H30: =+H85 -> 26.205326 | I30: =+I85 -> 30.110697 | J30: =+J85 -> 35.578216
B31: Total assets | C31: =SUM(C25:C30) -> 145 | E31: =SUM(E25:E30) -> 924.94 | F31: =SUM(F25:F30) -> 926.36324 | G31: =SUM(G25:G30) -> 933.35578 | H31: =SUM(H25:H30) -> 941.14533 | I31: =SUM(I25:I30) -> 950.0507 | J31: =SUM(J25:J30) -> 960.51822
B33: Existing debt | C33: 0 | E33: =+D33+C33 -> 0 | F33: =+F96 -> 0 | G33: =+G96 -> 0 | H33: =+H96 -> 0 | I33: =+I96 -> 0 | J33: =+J96 -> 0
B34: New debt | C34: 0 | E34: =+D34+C34 -> 0 | F34: =+F102 -> 13.342875 | G34: =+G102 -> 31.078685 | H34: =+H102 -> 51.952927 | I34: =+I102 -> 65.558765 | J34: =+J102 -> 65.035369
B35: Shareholder equity | C35: 145 | D35: =+-C35+D15-J16 -> 779.94 | E35: =+D35+C35 -> 924.94 | F35: =+E35+F73 -> 913.02037 | G35: =+F35+G73 -> 902.27709 | H35: =+G35+H73 -> 889.1924 | I35: =+H35+I73 -> 884.49193 | J35: =+I35+J73 -> 895.48285
B36: Total liabilities & equity | C36: =SUM(C33:C35) -> 145 | E36: =SUM(E33:E35) -> 924.94 | F36: =SUM(F33:F35) -> 926.36324 | G36: =SUM(G33:G35) -> 933.35578 | H36: =SUM(H33:H35) -> 941.14533 | I36: =SUM(I33:I35) -> 950.0507 | J36: =SUM(J33:J35) -> 960.51822
B37: Check | C37: =C31-C36 -> 0 | E37: =E31-E36 -> 0 | F37: =F31-F36 -> 0 | G37: =G31-G36 -> 0 | H37: =H31-H36 -> 0 | I37: =I31-I36 -> 0 | J37: =J31-J36 -> 0
B41: Income statement | C41: =+D41-1 -> -2 | D41: =+E41-1 -> -1 | E41: 0 | F41: 1 | G41: =F41+1 -> 2 | H41: =G41+1 -> 3 | I41: =H41+1 -> 4 | J41: =I41+1 -> 5
B42: Revenue | C42: 19.21 | D42: 32.98 | E42: 50.83 | F42: =+E42*(1+F43) -> 71.162 | G42: =+F42*(1+G43) -> 99.6268 | H42: =+G42*(1+H43) -> 139.47752 | I42: =+H42*(1+I43) -> 195.26853 | J42: =+I42*(1+J43) -> 273.37594
B43: % growth | D43: =D42/C42-1 -> 0.71681416 | E43: =E42/D42-1 -> 0.54123711 | F43: 0.4 | G43: 0.4 | H43: 0.4 | I43: 0.4 | J43: 0.4
B44: ^ Assumptions to be replaced by your bottom's up revenue & sales forecast ("Cohorts" tab)
B46: Gross profit | C46: 13 | D46: 23 | E46: 35.8 | F46: =+F47*F$42 -> 49.8134 | G46: =+G47*G$42 -> 69.73876 | H46: =+H47*H$42 -> 97.634264 | I46: =+I47*I$42 -> 136.68797 | J46: =+J47*J$42 -> 191.36316
B47: % of revenue | C47: =+C46/C$42 -> 0.67673087 | D47: =+D46/D$42 -> 0.69739236 | E47: =+E46/E$42 -> 0.70430848 | F47: 0.7 | G47: 0.7 | H47: 0.7 | I47: 0.7 | J47: 0.7
B49: Selling and marketing expenses | C49: 9.56 | D49: 15.55 | E49: 20.75 | F49: =+F50*F$42 -> 28.4648 | G49: =+G50*G$42 -> 37.858184 | H49: =+H50*H$42 -> 50.211907 | I49: =+I50*I$42 -> 66.3913 | J49: =+J50*J$42 -> 87.480301
B50: % of revenue | C50: =+C49/C42 -> 0.49765747 | D50: =+D49/D42 -> 0.47149788 | E50: =+E49/E42 -> 0.40822349 | F50: 0.4 | G50: 0.38 | H50: 0.36 | I50: 0.34 | J50: 0.32
B51: ^ Assumptions to be replaced by your bottom's up revenue & sales forecast ("Cohorts" tab)
B53: Overhead expenses | C53: 10 | D53: 15.2 | E53: 22.2 | F53: =+F54*F$42 -> 28.4648 | G53: =+G54*G$42 -> 34.86938 | H53: =+H54*H$42 -> 48.817132 | I53: =+I54*I$42 -> 58.580558 | J53: =+J54*J$42 -> 68.343985
B54: % of revenue | C54: =+C53/C$42 -> 0.52056221 | D54: =+D53/D$42 -> 0.46088539 | E54: =+E53/E$42 -> 0.43674995 | F54: 0.4 | G54: 0.35 | H54: 0.35 | I54: 0.3 | J54: 0.25
...

Sheet Model (Start - Blank)
B2: Assumptions | J2: $ millions
B3: Entry assumptions | E3: Transaction assumptions
B4: LTM revenue | E4: Transaction fees | G4: 0.01
B5: Entry multiple | C5: 18 | E5: Financing fees | G5: 0.02
B6: Enterprise value
B7: (-) Debt
B8: (+) Cash
B9: Equity value
B12: Sources & uses | J12: $ millions
B13: Sources | G13: Uses
B19: Total sources | G19: Total uses
B23: Model | J23: $ millions
B24: Balance sheet | C24: 0 | D24: Adjust. | E24: Pro forma | F24: 1 | G24: =F24+1 -> 2 | H24: =G24+1 -> 3 | I24: =H24+1 -> 4 | J24: =I24+1 -> 5
B25: Cash | C25: 5
B26: Net working capital | C26: 100
B27: Capitalized financing fees | C27: 0
B28: Goodwill | C28: 0
B29: Deferred tax asset | C29: 20
B30: Net PP&E | C30: 20
B31: Total assets | C31: =SUM(C25:C30) -> 145
B33: Existing debt | C33: 0
B34: New debt | C34: 0
B35: Shareholder equity | C35: 145
B36: Total liabilities & equity | C36: =SUM(C33:C35) -> 145
B37: Check | C37: =C31-C36 -> 0
B41: Income statement | C41: =+D41-1 -> -2 | D41: =+E41-1 -> -1 | E41: 0 | F41: 1 | G41: =F41+1 -> 2 | H41: =G41+1 -> 3 | I41: =H41+1 -> 4 | J41: =I41+1 -> 5
B42: Revenue | C42: 19.21 | D42: 32.98 | E42: 50.83
B43: % growth | D43: =D42/C42-1 -> 0.71681416 | E43: =E42/D42-1 -> 0.54123711 | F43: 0.4 | G43: 0.4 | H43: 0.4 | I43: 0.4 | J43: 0.4
B44: ^ Assumptions to be replaced by your bottom's up revenue & sales forecast ("Cohort" tab)
B46: Gross profit | C46: 13 | D46: 23 | E46: 35.8
B47: % of revenue | C47: =+C46/C$42 -> 0.67673087 | D47: =+D46/D$42 -> 0.69739236 | E47: =+E46/E$42 -> 0.70430848 | F47: 0.7 | G47: 0.7 | H47: 0.7 | I47: 0.7 | J47: 0.7
B49: Selling and marketing expenses | C49: 9.56 | D49: 15.55 | E49: 20.75
B50: % of revenue | C50: =+C49/C42 -> 0.49765747 | D50: =+D49/D42 -> 0.47149788 | E50: =+E49/E42 -> 0.40822349 | F50: 0.4 | G50: 0.38 | H50: 0.36 | I50: 0.34 | J50: 0.32
B51: ^ Assumptions to be replaced by your bottom's up revenue & sales forecast ("Cohort" tab)
B53: Overhead expenses | C53: 10 | D53: 15.2 | E53: 22.2
B54: % of revenue | C54: =+C53/C$42 -> 0.52056221 | D54: =+D53/D$42 -> 0.46088539 | E54: =+E53/E$42 -> 0.43674995 | F54: 0.4 | G54: 0.35 | H54: 0.35 | I54: 0.3 | J54: 0.25
B56: EBITDA | C56: =+C46-C49-C53 -> -6.56 | D56: =+D46-D49-D53 -> -7.75 | E56: =+E46-E49-E53 -> -7.15
B57: % of revenue | C57: =+C56/C42 -> -0.34148881 | D57: =+D56/D42 -> -0.2349909 | E57: =+E56/E42 -> -0.14066496
B59: D&A
B60: % of revenue | F60: 0.06 | G60: 0.06 | H60: 0.06 | I60: 0.06 | J60: 0.06
...

Sheet Cohorts (Start)
B2: ARR Waterfall Summary | M2: $ millions
B3: Annual recurring revenue | F3: -2 | G3: -1 | H3: 0 | I3: 1 | J3: =I3+1 -> 2 | K3: =J3+1 -> 3 | L3: =K3+1 -> 4 | M3: =L3+1 -> 5
B4: ARR, beginning | F4: 12
B5: (+) New bookings
B6: (-) Logo churn
B7: (+) Net upsell/(downsell)
B8: ARR, ending | F8: =SUM(F4:F7) -> 12 | G8: =SUM(G4:G7) -> 0 | H8: =SUM(H4:H7) -> 0
B10: % GAAP recognition | F10: 0.85 | G10: 0.85 | H10: 0.85 | I10: 0.85 | J10: 0.85 | K10: 0.85 | L10: 0.85 | M10: 0.85
B11: Recognized revenue | F11: =+F10*F8 -> 10.2 | G11: =+G10*G8 -> 0 | H11: =+H10*H8 -> 0
B12: % growth | G12: =+IFERROR(G11/F11-1, "n/a") -> -1 | H12: =+IFERROR(H11/G11-1, "n/a") -> n/a
B15: ARR Build | M15: $ millions
B16: Customers by cohort | F16: =+F$3 -> -2 | G16: =+G$3 -> -1 | H16: =+H$3 -> 0 | I16: =+I$3 -> 1 | J16: =+J$3 -> 2 | K16: =+K$3 -> 3 | L16: =+L$3 -> 4 | M16: =+M$3 -> 5
C17: New logos
B18: Before Year -2 | C18: n/a | F18: 53 | G18: 48 | H18: 45
B19: -2 | C19: =+F120 -> 60 | F19: =+$C19 -> 60 | G19: 56 | H19: 54
B20: -1 | C20: =+G120 -> 90 | G20: =+$C20 -> 90 | H20: 80
B21: 0 | C21: =+H120 -> 120 | H21: =+$C21 -> 120
B22: 1 | C22: =+I120 -> 0
B23: 2 | C23: =+J120 -> 0
B24: 3 | C24: =+K120 -> 0
B25: 4 | C25: =+L120 -> 0
B26: 5 | C26: =+M120 -> 0
B27: Total | F27: =SUM(F18:F26) -> 113 | G27: =SUM(G18:G26) -> 194 | H27: =SUM(H18:H26) -> 299
B30: Use this retention curve unless given otherwise --> | E30: Year 0 | F30: +1 Year | G30: +2 Years | H30: +3 Years | I30: Beyond
B31: Customer retention % | E31: 0.85 | F31: 0.92 | G31: 0.94 | H31: 0.96 | I31: 0.96
B33: Retention % | F33: =+F$3 -> -2 | G33: =+G$3 -> -1 | H33: =+H$3 -> 0 | I33: =+I$3 -> 1 | J33: =+J$3 -> 2 | K33: =+K$3 -> 3 | L33: =+L$3 -> 4 | M33: =+M$3 -> 5
B34: =+B18 -> Before Year -2
B35: =+B19 -> -2
B36: =+B20 -> -1
B37: =+B21 -> 0
B38: =+B22 -> 1
B39: =+B23 -> 2
B40: =+B24 -> 3
B41: =+B25 -> 4
B42: =+B26 -> 5
B43: Total
B46: Churned customers | F46: =+F$3 -> -2 | G46: =+G$3 -> -1 | H46: =+H$3 -> 0 | I46: =+I$3 -> 1 | J46: =+J$3 -> 2 | K46: =+K$3 -> 3 | L46: =+L$3 -> 4 | M46: =+M$3 -> 5
B47: =+B34 -> Before Year -2 | F47: 7 | G47: =+F18-G18 -> 5 | H47: =+G18-H18 -> 3
B48: =+B35 -> -2 | G48: =+F19-G19 -> 4 | H48: =+G19-H19 -> 2
B49: =+B36 -> -1 | H49: =+G20-H20 -> 10
...

Sheet Sensitivities (Start)
B2: Sensitivities | J2: $ millions
E3: 0 | F3: 1 | G3: =F3+1 -> 2 | H3: =G3+1 -> 3 | I3: =H3+1 -> 4 | J3: =I3+1 -> 5
B4: Revenue
B5: =+'Model (End)'!$G$9 -> Management case
B6: =+'Model (End)'!$G$10 -> Base case
B8: YoY growth | D8: CAGR
B9: =+'Model (End)'!$G$9 -> Management case
B10: =+'Model (End)'!$G$10 -> Base case
B13: Selling & marketing expenses
B14: =+'Model (End)'!$G$9 -> Management case
B15: =+'Model (End)'!$G$10 -> Base case
B17: % of revenue | D17: CAGR
B18: =+'Model (End)'!$G$9 -> Management case
B19: =+'Model (End)'!$G$10 -> Base case

Sheet Valuation (Start)
B2: Public trading comparables
E3: Valuation metrics | M3: Operating metrics
C4: Enterprise | E4: EV/Revenue | I4: EV/EBITDA | M4: Revenue | Q4: Revenue Growth | U4: EBITDA | Y4: EBITDA margin
C5: Value | E5: LTM | F5: NTM | G5: NTM+1 | I5: LTM | J5: NTM | K5: NTM+1 | M5: LTM | N5: NTM | O5: NTM+1 | Q5: LTM | R5: NTM | S5: NTM+1 | U5: LTM | V5: NTM | W5: NTM+1 | Y5: LTM | Z5: NTM | AA5: NTM+1
B7: Company 1 | C7: 9536 | E7: =+$C7/M7 -> 18.16381 | F7: =+$C7/N7 -> 10.684594 | G7: =+$C7/O7 -> 6.6778711 | I7: =+$C7/U7 -> -181.6381 | J7: =+$C7/V7 -> -213.69188 | K7: =+$C7/W7 -> 333.89356 | M7: 525 | N7: =+M7*(1+R7) -> 892.5 | O7: =+N7*(1+S7) -> 1428 | Q7: 0.87 | R7: 0.7 | S7: 0.6 | U7: =+Y7*M7 -> -52.5 | V7: =+Z7*N7 -> -44.625 | W7: =+AA7*O7 -> 28.56 | Y7: -0.1 | Z7: -0.05 | AA7: 0.02
B8: Company 2 | C8: 5551 | E8: =+$C8/M8 -> 4.6258333 | F8: =+$C8/N8 -> 4.1302083 | G8: =+$C8/O8 -> 3.789182 | I8: =+$C8/U8 -> 14.017677 | J8: =+$C8/V8 -> 11.800595 | K8: =+$C8/W8 -> 10.826234 | M8: 1200 | N8: =+M8*(1+R8) -> 1344 | O8: =+N8*(1+S8) -> 1464.96 | Q8: 0.08 | R8: 0.12 | S8: 0.09 | U8: =+Y8*M8 -> 396 | V8: =+Z8*N8 -> 470.4 | W8: =+AA8*O8 -> 512.736 | Y8: 0.33 | Z8: 0.35 | AA8: 0.35
B9: Company 3 | C9: 5078 | E9: =+$C9/M9 -> 15.295181 | F9: =+$C9/N9 -> 8.4973226 | G9: =+$C9/O9 -> 4.9984251 | I9: =+$C9/U9 -> -38.237952 | J9: =+$C9/V9 -> -28.324409 | K9: =+$C9/W9 -> -24.992125 | M9: 332 | N9: =+M9*(1+R9) -> 597.6 | O9: =+N9*(1+S9) -> 1015.92 | Q9: 0.92 | R9: 0.8 | S9: 0.7 | U9: =+Y9*M9 -> -132.8 | V9: =+Z9*N9 -> -179.28 | W9: =+AA9*O9 -> -203.184 | Y9: -0.4 | Z9: -0.3 | AA9: -0.2
B10: Company 4 | C10: 896 | E10: =+$C10/M10 -> 11.487179 | F10: =+$C10/N10 -> 7.6074036 | G10: =+$C10/O10 -> 5.3953217 | I10: =+$C10/U10 -> -45.948718 | J10: =+$C10/V10 -> -36.225732 | K10: =+$C10/W10 -> -28.39643 | M10: 78 | N10: =+M10*(1+R10) -> 117.78 | O10: =+N10*(1+S10) -> 166.0698 | Q10: 0.66 | R10: 0.51 | S10: 0.41 | U10: =+Y10*M10 -> -19.5 | V10: =+Z10*N10 -> -24.7338 | W10: =+AA10*O10 -> -31.553262 | Y10: -0.25 | Z10: -0.21 | AA10: -0.19
B11: Company 5 | C11: 7412 | E11: =+$C11/M11 -> 12.332779 | F11: =+$C11/N11 -> 10.108835 | G11: =+$C11/O11 -> 8.087068 | I11: =+$C11/U11 -> -246.65557 | J11: =+$C11/V11 -> 336.96117 | K11: =+$C11/W11 -> 80.87068 | M11: 601 | N11: =+M11*(1+R11) -> 733.22 | O11: =+N11*(1+S11) -> 916.525 | Q11: 0.27 | R11: 0.22 | S11: 0.25 | U11: =+Y11*M11 -> -30.05 | V11: =+Z11*N11 -> 21.9966 | W11: =+AA11*O11 -> 91.6525 | Y11: -0.05 | Z11: 0.03 | AA11: 0.1
B12: Company 6 | C12: 4301 | E12: =+$C12/M12 -> 14.336667 | F12: =+$C12/N12 -> 10.779449 | G12: =+$C12/O12 -> 8.6235589 | I12: =+$C12/U12 -> 119.47222 | J12: =+$C12/V12 -> 71.862991 | K12: =+$C12/W12 -> 53.897243 | M12: 300 | N12: =+M12*(1+R12) -> 399 | O12: =+N12*(1+S12) -> 498.75 | Q12: 0.35 | R12: 0.33 | S12: 0.25 | U12: =+Y12*M12 -> 36 | V12: =+Z12*N12 -> 59.85 | W12: =+AA12*O12 -> 79.8 | Y12: 0.12 | Z12: 0.15 | AA12: 0.16
B13: Company 7 | C13: 5523 | E13: =+$C13/M13 -> 24.99095 | F13: =+$C13/N13 -> 12.190707 | G13: =+$C13/O13 -> 6.5895716 | I13: =+$C13/U13 -> -131.53132 | J13: =+$C13/V13 -> -67.726152 | K13: =+$C13/W13 -> -38.762186 | M13: 221 | N13: =+M13*(1+R13) -> 453.05 | O13: =+N13*(1+S13) -> 838.1425 | Q13: 1.08 | R13: 1.05 | S13: 0.85 | U13: =+Y13*M13 -> -41.99 | V13: =+Z13*N13 -> -81.549 | W13: =+AA13*O13 -> -142.48423 | Y13: -0.19 | Z13: -0.18 | AA13: -0.17
B14: Company 8 | C14: 2217 | E14: =+$C14/M14 -> 5.5012407 | F14: =+$C14/N14 -> 5.0470098 | G14: =+$C14/O14 -> 4.7168316 | I14: =+$C14/U14 -> 15.717831 | J14: =+$C14/V14 -> 14.844147 | K14: =+$C14/W14 -> 13.873034 | M14: 403 | N14: =+M14*(1+R14) -> 439.27 | O14: =+N14*(1+S14) -> 470.0189 | Q14: 0.1 | R14: 0.09 | S14: 0.07 | U14: =+Y14*M14 -> 141.05 | V14: =+Z14*N14 -> 149.3518 | W14: =+AA14*O14 -> 159.80643 | Y14: 0.35 | Z14: 0.34 | AA14: 0.34
B16: Entire comp set
B17: Average | E17: =AVERAGE(E7:E14) -> 13.341705 | F17: =AVERAGE(F7:F14) -> 8.6306912 | G17: =AVERAGE(G7:G14) -> 6.1097287 | I17: =AVERAGE(I7:I14) -> -61.850491 | J17: =AVERAGE(J7:J14) -> 11.187591 | K17: =AVERAGE(K7:K14) -> 50.151251
B18: Median | E18: =MEDIAN(E7:E14) -> 13.334723 | F18: =MEDIAN(F7:F14) -> 9.3030788 | G18: =MEDIAN(G7:G14) -> 5.9924467 | I18: =MEDIAN(I7:I14) -> -42.093335 | J18: =MEDIAN(J7:J14) -> -8.2619068 | K18: =MEDIAN(K7:K14) -> 12.349634
B20: Selected comps
B21: Average | E21: =AVERAGE(E11:E12) -> 13.334723 | F21: =AVERAGE(F11:F12) -> 10.444142 | G21: =AVERAGE(G11:G12) -> 8.3553134 | I21: =AVERAGE(I11:I12) -> -63.591676 | J21: =AVERAGE(J11:J12) -> 204.41208 | K21: =AVERAGE(K11:K12) -> 67.383962
B24: Precedent transaction comparables
C25: Acquisition | E25: Valuation metrics | M25: Operating metrics
C26: Enterprise | E26: EV/Revenue | I26: EV/EBITDA | M26: Revenue | Q26: Revenue Growth | U26: EBITDA | Y26: EBITDA margin
C27: Value | E27: LTM | F27: NTM | G27: NTM+1 | I27: LTM | J27: NTM | K27: NTM+1 | M27: LTM | N27: NTM | O27: NTM+1 | Q27: LTM | R27: NTM | S27: NTM+1 | U27: LTM | V27: NTM | W27: NTM+1 | Y27: LTM | Z27: NTM | AA27: NTM+1
B29: Company A | C29: 3000 | E29: =+$C29/M29 -> 24 | F29: =+$C29/N29 -> 13.333333 | G29: =+$C29/O29 -> 8.2304527 | I29: =+$C29/U29 -> -240 | J29: =+$C29/V29 -> -266.66667 | K29: =+$C29/W29 -> 411.52263 | M29: 125 | N29: =+M29*(1+R29) -> 225 | O29: =+N29*(1+S29) -> 364.5 | Q29: 0.78 | R29: 0.8 | S29: 0.62 | U29: =+Y29*M29 -> -12.5 | V29: =+Z29*N29 -> -11.25 | W29: =+AA29*O29 -> 7.29 | Y29: -0.1 | Z29: -0.05 | AA29: 0.02
B30: Company B | C30: 8800 | E30: =+$C30/M30 -> 9.8104794 | F30: =+$C30/N30 -> 8.0413765 | G30: =+$C30/O30 -> 6.8147259 | I30: =+$C30/U30 -> 54.502663 | J30: =+$C30/V30 -> 47.302215 | K30: =+$C30/W30 -> 37.859588 | M30: 897 | N30: =+M30*(1+R30) -> 1094.34 | O30: =+N30*(1+S30) -> 1291.3212 | Q30: 0.32 | R30: 0.22 | S30: 0.18 | U30: =+Y30*M30 -> 161.46 | V30: =+Z30*N30 -> 186.0378 | W30: =+AA30*O30 -> 232.43782 | Y30: 0.18 | Z30: 0.17 | AA30: 0.18
B31: Company C | C31: 2500 | E31: =+$C31/M31 -> 11.261261 | F31: =+$C31/N31 -> 10.23751 | G31: =+$C31/O31 -> 9.4791761 | I31: =+$C31/U31 -> 28.153153 | J31: =+$C31/V31 -> 24.375024 | K31: =+$C31/W31 -> 22.569467 | M31: 222 | N31: =+M31*(1+R31) -> 244.2 | O31: =+N31*(1+S31) -> 263.736 | Q31: 0.12 | R31: 0.1 | S31: 0.08 | U31: =+Y31*M31 -> 88.8 | V31: =+Z31*N31 -> 102.564 | W31: =+AA31*O31 -> 110.76912 | Y31: 0.4 | Z31: 0.42 | AA31: 0.42
B32: Company D | C32: 1250 | E32: =+$C32/M32 -> 23.584906 | F32: =+$C32/N32 -> 11.792453 | G32: =+$C32/O32 -> 6.0474117 | I32: =+$C32/U32 -> -63.742988 | J32: =+$C32/V32 -> -39.308176 | K32: =+$C32/W32 -> -30.237059 | M32: 53 | N32: =+M32*(1+R32) -> 106 | O32: =+N32*(1+S32) -> 206.7 | Q32: 1.22 | R32: 1 | S32: 0.95 | U32: =+Y32*M32 -> -19.61 | V32: =+Z32*N32 -> -31.8 | W32: =+AA32*O32 -> -41.34 | Y32: -0.37 | Z32: -0.3 | AA32: -0.2
B33: Company E | C33: 500 | E33: =+$C33/M33 -> 11.904762 | F33: =+$C33/N33 -> 9.1575092 | G33: =+$C33/O33 -> 7.2106371 | I33: =+$C33/U33 -> -99.206349 | J33: =+$C33/V33 -> -183.15018 | K33: =+$C33/W33 -> 144.21274 | M33: 42 | N33: =+M33*(1+R33) -> 54.6 | O33: =+N33*(1+S33) -> 69.342 | Q33: 0.38 | R33: 0.3 | S33: 0.27 | U33: =+Y33*M33 -> -5.04 | V33: =+Z33*N33 -> -2.73 | W33: =+AA33*O33 -> 3.4671 | Y33: -0.12 | Z33: -0.05 | AA33: 0.05
B35: Entire comp set
B36: Average | E36: =AVERAGE(E29:E33) -> 16.112282 | F36: =AVERAGE(F29:F33) -> 10.512436 | G36: =AVERAGE(G29:G33) -> 7.5564807 | I36: =AVERAGE(I29:I33) -> -64.058704 | J36: =AVERAGE(J29:J33) -> -83.489557 | K36: =AVERAGE(K29:K33) -> 117.18547
B37: Median | E37: =MEDIAN(E29:E33) -> 11.904762 | F37: =MEDIAN(F29:F33) -> 10.23751 | G37: =MEDIAN(G29:G33) -> 7.2106371 | I37: =MEDIAN(I29:I33) -> -63.742988 | J37: =MEDIAN(J29:J33) -> -39.308176 | K37: =MEDIAN(K29:K33) -> 37.859588
B39: Selected comps
B40: Average | E40: =AVERAGE(E33,E30) -> 10.857621 | F40: =AVERAGE(F33,F30) -> 8.5994428 | G40: =AVERAGE(G33,G30) -> 7.0126815 | I40: =AVERAGE(I33,I30) -> -22.351843 | J40: =AVERAGE(J33,J30) -> -67.923984 | K40: =AVERAGE(K33,K30) -> 91.036165
B43: Historical trading comparables - Software index
C45: Median
C46: EV/LTM Rev
B47: 20 quarters ago | C47: 5.2
B48: 19 quarters ago | C48: 5.9
B49: 18 quarters ago | C49: 6.2
B50: 17 quarters ago | C50: 6.5
B51: 16 quarters ago | C51: 7.2
B52: 15 quarters ago | C52: 6.9
...

Sheet End ->

Sheet Model (End)
B2: Assumptions | J2: $ millions
B3: Entry assumptions | G3: Other assumptions
C4: Pre-Money | D4: Post-Money | E4: Assumptions | G4: Rollover equity | J4: 800
B5: LTM revenue | C5: =E61 -> 50.83 | G5: Management option pool | J5: 0.1
B6: Entry multiple | C6: 18
B7: Enterprise value | C7: =C5*C6 -> 914.94 | D7: =C7 -> 914.94
B8: (-) Existing debt | C8: =C52 -> 0 | D8: =D52 -> 0 | G8: ="Active: "&CHOOSE(J8,G9,G10,G11) -> Active: Base case | J8: 2
B9: (-) New debt | C9: =+C53 -> 0 | D9: 0 | G9: Management case | J9: 1
B10: (+) Cash | C10: =C44 -> 5 | D10: 105 | G10: Base case | J10: 2
B11: Equity value | C11: =C7-C8+C10-C9 -> 919.94 | D11: =D7-D8+D10-D9 -> 1019.94
B12: (+) Transaction fees | D12: =+E12*D7 -> 9.1494 | E12: 0.01
B13: (+) Financing fees | D13: =+E13*D9 -> 0 | E13: 0.02
B14: Equity value (incl. fees) | D14: =+D11+D12+D13 -> 1029.0894
B17: Sources & uses | J17: $ millions
B18: Sources | G18: Uses
B19: New debt | D19: =+D9 -> 0 | G19: Proceeds to selling shareholders | J19: =+C11-J20 -> 119.94
B20: Rollover equity | D20: =+J20 -> 800 | G20: Rollover equity | J20: =+J4 -> 800
B21: Sponsor equity | D21: =+J25-D20-D19 -> 229.0894 | G21: Cash added to B/S | J21: =+D10-C10 -> 100
G22: Transaction fees | J22: =+D12 -> 9.1494
G23: Financing fees | J23: =+D13 -> 0
B25: Total sources | D25: =SUM(D19:D24) -> 1029.0894 | G25: Total uses | J25: =SUM(J19:J24) -> 1029.0894
B29: Capitalization table
D30: Pre-Money | H30: Post-Money
D31: $ Amount | E31: Shares | F31: FD Own % | H31: $ Amount | I31: Shares | J31: FD Own %
B32: Primary (incl. fees) | D32: =+E32*D$39/1000000 -> 0 | E32: 0 | F32: =+E32/E$37 -> 0 | H32: =+J21+J22+J23 -> 109.1494 | I32: =+H32*1000000/H$39 -> 118648.39 | J32: =+I32/I$37 -> 0.095457654
B33: Secondary | D33: =+E33*D$39/1000000 -> 0 | E33: 0 | F33: =+E33/E$37 -> 0 | H33: =+D21-H32 -> 119.94 | I33: =+H33*1000000/H$39 -> 130378.07 | J33: =+I33/I$37 -> 0.10489468
B34: Total new sponsor | D34: =SUM(D32:D33) -> 0 | E34: =SUM(E32:E33) -> 0 | F34: =+E34/E$37 -> 0 | H34: =+SUM(H32:H33) -> 229.0894 | I34: =+H34*1000000/H$39 -> 249026.46 | J34: =+I34/I$37 -> 0.20035233
B35: Existing owners | D35: =+C11 -> 919.94 | E35: 1000000 | F35: =+E35/E$37 -> 1 | H35: =J20 -> 800 | I35: =+H35*1000000/H$39 -> 869621.93 | J35: =+I35/I$37 -> 0.69964767
B36: Management options | D36: =+E36*D$39/1000000 -> 0 | E36: 0 | F36: =+E36/E$37 -> 0 | H36: 0 | I36: =SUM(I34:I35)/(1-J5)*J5 -> 124294.27 | J36: =+I36/I$37 -> 0.1
B37: Total company | D37: =SUM(D34:D36) -> 919.94 | E37: =SUM(E34:E36) -> 1000000 | F37: =+E37/E$37 -> 1 | H37: =SUM(H34:H36) -> 1029.0894 | I37: =SUM(I34:I36) -> 1242942.7 | J37: =+I37/I$37 -> 1
B39: Share price | D39: =+D37*1000000/E37 -> 919.94 | H39: =+D39 -> 919.94
B42: Model | J42: $ millions
B43: Balance sheet | C43: 0 | D43: Adjust. | E43: Pro forma | F43: 1 | G43: =F43+1 -> 2 | H43: =G43+1 -> 3 | I43: =H43+1 -> 4 | J43: =I43+1 -> 5
B44: Cash | C44: 5 | D44: =E44-C44 -> 100 | E44: =+D10 -> 105 | F44: =F152+E44 -> 89.351544 | G44: =G152+F44 -> 75.218049 | H44: =H152+G44 -> 62.925027 | I44: =I152+H44 -> 58.710296 | J44: =J152+I44 -> 66.741612
B45: Net working capital | C45: 100 | E45: =D45+C45 -> 100 | F45: =F97 -> 105 | G45: =G97 -> 110 | H45: =H97 -> 115 | I45: =I97 -> 120 | J45: =J97 -> 125
B46: Capitalized financing fees | C46: 0 | D46: =+D13 -> 0 | E46: =D46+C46 -> 0 | F46: =F108 -> 0 | G46: =G108 -> 0 | H46: =H108 -> 0 | I46: =I108 -> 0 | J46: =J108 -> 0
B47: Goodwill | C47: 0 | E47: =D47+C47 -> 0 | F47: =E47 -> 0 | G47: =F47 -> 0 | H47: =G47 -> 0 | I47: =H47 -> 0 | J47: =I47 -> 0
B48: Deferred tax asset | C48: 20 | E48: =D48+C48 -> 20 | F48: =E48-F136 -> 21.93661 | G48: =F48-G136 -> 23.462854 | H48: =G48-H136 -> 24.496502 | I48: =H48-I136 -> 23.845543 | J48: =I48-J136 -> 20.932592
B49: Net PP&E | C49: 20 | E49: =D49+C49 -> 20 | F49: =F102 -> 21.426504 | G49: =G102 -> 23.292171 | H49: =H102 -> 25.663058 | I49: =I102 -> 28.589809 | J49: =J102 -> 32.169244
B50: Total assets | C50: =SUM(C44:C49) -> 145 | E50: =SUM(E44:E49) -> 245 | F50: =SUM(F44:F49) -> 237.71466 | G50: =SUM(G44:G49) -> 231.97307 | H50: =SUM(H44:H49) -> 228.08459 | I50: =SUM(I44:I49) -> 231.14565 | J50: =SUM(J44:J49) -> 244.84345
...

Sheet Model (Pre-Money Options)
B2: Assumptions | J2: $ millions
B3: Entry assumptions | G3: Other assumptions
C4: Pre-Money | D4: Post-Money | E4: Assumptions | G4: Rollover equity | J4: 731
B5: LTM revenue | C5: =E61 -> 50.83 | G5: Management option pool | J5: 0.1
B6: Entry multiple | C6: 18
B7: Enterprise value | C7: =C5*C6 -> 914.94 | D7: =C7 -> 914.94
B8: (-) Existing debt | C8: =C52 -> 0 | D8: =D52 -> 0 | G8: ="Active: "&CHOOSE(J8,G9,G10,G11) -> Active: Base case | J8: 2
B9: (-) New debt | C9: =+C53 -> 0 | D9: 0 | G9: Management case | J9: 1
B10: (+) Cash | C10: =C44 -> 5 | D10: 105 | G10: Base case | J10: 2
B11: Equity value | C11: =C7-C8+C10-C9 -> 919.94 | D11: =D7-D8+D10-D9 -> 1019.94
B12: (+) Transaction fees | D12: =+E12*D7 -> 9.1494 | E12: 0.01
B13: (+) Financing fees | D13: =+E13*D9 -> 0 | E13: 0.02
B14: Equity value (incl. fees) | D14: =+D11+D12+D13 -> 1029.0894
B17: Sources & uses | J17: $ millions
B18: Sources | G18: Uses
B19: New debt | D19: =+D9 -> 0 | G19: Proceeds to selling shareholders | J19: =+D35-J20 -> 96.946
B20: Rollover equity | D20: =+J20 -> 731 | G20: Rollover equity | J20: =+J4 -> 731
B21: Sponsor equity | D21: =+J25-D20-D19 -> 206.0954 | G21: Cash added to B/S | J21: =+D10-C10 -> 100
G22: Transaction fees | J22: =+D12 -> 9.1494
G23: Financing fees | J23: =+D13 -> 0
B25: Total sources | D25: =SUM(D19:D24) -> 937.0954 | G25: Total uses | J25: =SUM(J19:J24) -> 937.0954
B29: Capitalization table (options issued pre-money)
D30: Pre-Money (Post-options) | H30: Post-Money
D31: $ Amount | E31: FD Shares | F31: FD Own % | H31: $ Amount | I31: FD Shares | J31: FD Own %
B32: Primary (incl. fees) | D32: 0 | E32: 0 | F32: =+E32/E$37 -> 0 | H32: =+J21+J22+J23 -> 109.1494 | I32: =+H32*1000000/H$39 -> 131831.54 | J32: =+I32/I$37 -> 0.10606406
B33: Secondary | D33: 0 | E33: 0 | F33: =+E33/E$37 -> 0 | H33: =I33*H39/1000000 -> 96.946 | I33: =E35-I35 -> 117092.18 | J33: =+I33/I$37 -> 0.094205615
B34: Total new sponsor | D34: =SUM(D32:D33) -> 0 | E34: =SUM(E32:E33) -> 0 | F34: =+E34/E$37 -> 0 | H34: =+SUM(H32:H33) -> 206.0954 | I34: =+H34*1000000/H$39 -> 248923.72 | J34: =+I34/I$37 -> 0.20026968
B35: Existing owners | D35: =E35*D39/1000000 -> 827.946 | E35: 1000000 | F35: =+E35/E$37 -> 0.9 | H35: =J20 -> 731 | I35: =+H35*1000000/H$39 -> 882907.82 | J35: =+I35/I$37 -> 0.71033673
B36: Management options | D36: 0 | E36: =SUM(E34:E35)/(1-J5)*J5 -> 111111.11 | F36: =+E36/E$37 -> 0.1 | H36: 0 | I36: =+E36 -> 111111.11 | J36: =+I36/I$37 -> 0.089393594
B37: Total company | D37: =SUM(D34:D36) -> 827.946 | E37: =SUM(E34:E36) -> 1111111.1 | F37: =+E37/E$37 -> 1 | H37: =SUM(H34:H36) -> 937.0954 | I37: =SUM(I34:I36) -> 1242942.7 | J37: =+I37/I$37 -> 1
B39: Share price | D39: =+C11*1000000/E37 -> 827.946 | H39: =+D39 -> 827.946
B42: Model | J42: $ millions
B43: Balance sheet | C43: 0 | D43: Adjust. | E43: Pro forma | F43: 1 | G43: =F43+1 -> 2 | H43: =G43+1 -> 3 | I43: =H43+1 -> 4 | J43: =I43+1 -> 5
B44: Cash | C44: 5 | D44: =E44-C44 -> 100 | E44: =+D10 -> 105 | F44: =F152+E44 -> 89.351544 | G44: =G152+F44 -> 75.218049 | H44: =H152+G44 -> 62.925027 | I44: =I152+H44 -> 58.710296 | J44: =J152+I44 -> 66.741612
B45: Net working capital | C45: 100 | E45: =D45+C45 -> 100 | F45: =F97 -> 105 | G45: =G97 -> 110 | H45: =H97 -> 115 | I45: =I97 -> 120 | J45: =J97 -> 125
B46: Capitalized financing fees | C46: 0 | D46: =+D13 -> 0 | E46: =D46+C46 -> 0 | F46: =F108 -> 0 | G46: =G108 -> 0 | H46: =H108 -> 0 | I46: =I108 -> 0 | J46: =J108 -> 0
B47: Goodwill | C47: 0 | E47: =D47+C47 -> 0 | F47: =E47 -> 0 | G47: =F47 -> 0 | H47: =G47 -> 0 | I47: =H47 -> 0 | J47: =I47 -> 0
B48: Deferred tax asset | C48: 20 | E48: =D48+C48 -> 20 | F48: =E48-F136 -> 21.93661 | G48: =F48-G136 -> 23.462854 | H48: =G48-H136 -> 24.496502 | I48: =H48-I136 -> 23.845543 | J48: =I48-J136 -> 20.932592
B49: Net PP&E | C49: 20 | E49: =D49+C49 -> 20 | F49: =F102 -> 21.426504 | G49: =G102 -> 23.292171 | H49: =H102 -> 25.663058 | I49: =I102 -> 28.589809 | J49: =J102 -> 32.169244
B50: Total assets | C50: =SUM(C44:C49) -> 145 | E50: =SUM(E44:E49) -> 245 | F50: =SUM(F44:F49) -> 237.71466 | G50: =SUM(G44:G49) -> 231.97307 | H50: =SUM(H44:H49) -> 228.08459 | I50: =SUM(I44:I49) -> 231.14565 | J50: =SUM(J44:J49) -> 244.84345
...

Sheet Cohorts (End)
B2: ARR Waterfall Summary | M2: $ millions
B3: Annual recurring revenue | F3: -2 | G3: -1 | H3: 0 | I3: 1 | J3: =I3+1 -> 2 | K3: =J3+1 -> 3 | L3: =K3+1 -> 4 | M3: =L3+1 -> 5
B4: ARR, beginning | F4: 12 | G4: =+F8 -> 22.6 | H4: =+G8 -> 38.8 | I4: =+H8 -> 59.8 | J4: =+I8 -> 83.912 | K4: =+J8 -> 109.74512 | L4: =+K8 -> 139.46396 | M4: =+L8 -> 172.1618
B5: (+) New bookings | F5: =+F112 -> 12 | G5: =+G112 -> 18 | H5: =+H112 -> 24 | I5: =+I112 -> 30 | J5: =+J112 -> 33.6 | K5: =+K112 -> 39.2 | L5: =+L112 -> 44.2 | M5: =+M112 -> 52
B6: (-) Logo churn | F6: =-F85 -> -1.4 | G6: =-G85 -> -1.8 | H6: =-H85 -> -3 | I6: =-I85 -> -5.888 | J6: =-J85 -> -7.76688 | K6: =-K85 -> -9.4811648 | L6: =-L85 -> -11.502158 | M6: =-M85 -> -13.606776
B7: (+) Net upsell/(downsell) | F7: =+F98 -> 0 | G7: =+G98 -> 0 | H7: =+H98 -> 0 | I7: =+I98 -> 0 | J7: =+J98 -> 0 | K7: =+K98 -> 0 | L7: =+L98 -> 0 | M7: =+M98 -> 0
B8: ARR, ending | F8: =SUM(F4:F7) -> 22.6 | G8: =SUM(G4:G7) -> 38.8 | H8: =SUM(H4:H7) -> 59.8 | I8: =SUM(I4:I7) -> 83.912 | J8: =SUM(J4:J7) -> 109.74512 | K8: =SUM(K4:K7) -> 139.46396 | L8: =SUM(L4:L7) -> 172.1618 | M8: =SUM(M4:M7) -> 210.55502
B10: % GAAP recognition | F10: 0.85 | G10: 0.85 | H10: 0.85 | I10: 0.85 | J10: 0.85 | K10: 0.85 | L10: 0.85 | M10: 0.85
B11: Recognized revenue | F11: =+F10*F8 -> 19.21 | G11: =+G10*G8 -> 32.98 | H11: =+H10*H8 -> 50.83 | I11: =+I10*I8 -> 71.3252 | J11: =+J10*J8 -> 93.283352 | K11: =+K10*K8 -> 118.54436 | L11: =+L10*L8 -> 146.33753 | M11: =+M10*M8 -> 178.97177
B12: % growth | G12: =+IFERROR(G11/F11-1, "n/a") -> 0.71681416 | H12: =+IFERROR(H11/G11-1, "n/a") -> 0.54123711 | I12: =+IFERROR(I11/H11-1, "n/a") -> 0.4032107 | J12: =+IFERROR(J11/I11-1, "n/a") -> 0.30785966 | K12: =+IFERROR(K11/J11-1, "n/a") -> 0.27079869 | L12: =+IFERROR(L11/K11-1, "n/a") -> 0.23445371 | M12: =+IFERROR(M11/L11-1, "n/a") -> 0.22300664
B15: ARR Build | M15: $ millions
B16: Customers by cohort | F16: =+F$3 -> -2 | G16: =+G$3 -> -1 | H16: =+H$3 -> 0 | I16: =+I$3 -> 1 | J16: =+J$3 -> 2 | K16: =+K$3 -> 3 | L16: =+L$3 -> 4 | M16: =+M$3 -> 5
C17: New logos
B18: Before Year -2 | C18: n/a | F18: 53 | G18: 48 | H18: 45 | I18: =H18*I34 -> 43.2 | J18: =I18*J34 -> 41.472 | K18: =J18*K34 -> 39.81312 | L18: =K18*L34 -> 38.220595 | M18: =L18*M34 -> 36.691771
B19: -2 | C19: =+F120 -> 60 | F19: =+$C19 -> 60 | G19: 56 | H19: 54 | I19: =H19*I35 -> 50.76 | J19: =I19*J35 -> 48.7296 | K19: =J19*K35 -> 46.780416 | L19: =K19*L35 -> 44.909199 | M19: =L19*M35 -> 43.112831
B20: -1 | C20: =+G120 -> 90 | G20: =+$C20 -> 90 | H20: 80 | I20: =H20*I36 -> 73.6 | J20: =I20*J36 -> 69.184 | K20: =J20*K36 -> 66.41664 | L20: =K20*L36 -> 63.759974 | M20: =L20*M36 -> 61.209575
B21: 0 | C21: =+H120 -> 120 | H21: =+$C21 -> 120 | I21: =H21*I37 -> 102 | J21: =I21*J37 -> 93.84 | K21: =J21*K37 -> 88.2096 | L21: =K21*L37 -> 84.681216 | M21: =L21*M37 -> 81.293967
B22: 1 | C22: =+I120 -> 150 | I22: =+$C22 -> 150 | J22: =I22*J38 -> 127.5 | K22: =J22*K38 -> 117.3 | L22: =K22*L38 -> 110.262 | M22: =L22*M38 -> 105.85152
B23: 2 | C23: =+J120 -> 168 | J23: =+$C23 -> 168 | K23: =J23*K39 -> 142.8 | L23: =K23*L39 -> 131.376 | M23: =L23*M39 -> 123.49344
B24: 3 | C24: =+K120 -> 196 | K24: =+$C24 -> 196 | L24: =K24*L40 -> 166.6 | M24: =L24*M40 -> 153.272
B25: 4 | C25: =+L120 -> 221 | L25: =+$C25 -> 221 | M25: =L25*M41 -> 187.85
B26: 5 | C26: =+M120 -> 260 | M26: =+$C26 -> 260
B27: Total | F27: =SUM(F18:F26) -> 113 | G27: =SUM(G18:G26) -> 194 | H27: =SUM(H18:H26) -> 299 | I27: =SUM(I18:I26) -> 419.56 | J27: =SUM(J18:J26) -> 548.7256 | K27: =SUM(K18:K26) -> 697.31978 | L27: =SUM(L18:L26) -> 860.80898 | M27: =SUM(M18:M26) -> 1052.7751
B30: Use this retention curve unless given otherwise --> | E30: Year 0 | F30: +1 Year | G30: +2 Years | H30: +3 Years | I30: Beyond
B31: Customer retention % | E31: 0.85 | F31: 0.92 | G31: 0.94 | H31: 0.96 | I31: 0.96
B33: Retention % | F33: =+F$3 -> -2 | G33: =+G$3 -> -1 | H33: =+H$3 -> 0 | I33: =+I$3 -> 1 | J33: =+J$3 -> 2 | K33: =+K$3 -> 3 | L33: =+L$3 -> 4 | M33: =+M$3 -> 5
B34: =+B18 -> Before Year -2 | G34: =+G18/F18 -> 0.90566038 | H34: =+H18/G18 -> 0.9375 | I34: 0.96 | J34: 0.96 | K34: 0.96 | L34: 0.96 | M34: 0.96
B35: =+B19 -> -2 | G35: =+G19/F19 -> 0.93333333 | H35: =+H19/G19 -> 0.96428571 | I35: 0.94 | J35: 0.96 | K35: 0.96 | L35: 0.96 | M35: 0.96
B36: =+B20 -> -1 | H36: =+H20/G20 -> 0.88888889 | I36: 0.92 | J36: 0.94 | K36: 0.96 | L36: 0.96 | M36: 0.96
B37: =+B21 -> 0 | I37: 0.85 | J37: 0.92 | K37: 0.94 | L37: 0.96 | M37: 0.96
B38: =+B22 -> 1 | J38: 0.85 | K38: 0.92 | L38: 0.94 | M38: 0.96
B39: =+B23 -> 2 | K39: 0.85 | L39: 0.92 | M39: 0.94
B40: =+B24 -> 3 | L40: 0.85 | M40: 0.92
B41: =+B25 -> 4 | M41: 0.85
B42: =+B26 -> 5
B43: Total
B46: Churned customers | F46: =+F$3 -> -2 | G46: =+G$3 -> -1 | H46: =+H$3 -> 0 | I46: =+I$3 -> 1 | J46: =+J$3 -> 2 | K46: =+K$3 -> 3 | L46: =+L$3 -> 4 | M46: =+M$3 -> 5
B47: =+B34 -> Before Year -2 | F47: 7 | G47: =+F18-G18 -> 5 | H47: =+G18-H18 -> 3 | I47: =+H18-I18 -> 1.8 | J47: =+I18-J18 -> 1.728 | K47: =+J18-K18 -> 1.65888 | L47: =+K18-L18 -> 1.5925248 | M47: =+L18-M18 -> 1.5288238
B48: =+B35 -> -2 | G48: =+F19-G19 -> 4 | H48: =+G19-H19 -> 2 | I48: =+H19-I19 -> 3.24 | J48: =+I19-J19 -> 2.0304 | K48: =+J19-K19 -> 1.949184 | L48: =+K19-L19 -> 1.8712166 | M48: =+L19-M19 -> 1.796368
B49: =+B36 -> -1 | H49: =+G20-H20 -> 10 | I49: =+H20-I20 -> 6.4 | J49: =+I20-J20 -> 4.416 | K49: =+J20-K20 -> 2.76736 | L49: =+K20-L20 -> 2.6566656 | M49: =+L20-M20 -> 2.550399
...

Sheet Sensitivities (End)
B2: Sensitivities | J2: $ millions
E3: 0 | F3: 1 | G3: =F3+1 -> 2 | H3: =G3+1 -> 3 | I3: =H3+1 -> 4 | J3: =I3+1 -> 5
B4: Revenue | E4: ='Model (End)'!E61 -> 50.83 | F4: =+OFFSET(F4, 'Model (End)'!$J$8, 0) -> 71.3252 | G4: =+OFFSET(G4, 'Model (End)'!$J$8, 0) -> 93.283352 | H4: =+OFFSET(H4, 'Model (End)'!$J$8, 0) -> 118.54436 | I4: =+OFFSET(I4, 'Model (End)'!$J$8, 0) -> 146.33753 | J4: =+OFFSET(J4, 'Model (End)'!$J$8, 0) -> 178.97177
B5: =+'Model (End)'!$G$9 -> Management case | E5: =+E4 -> 50.83 | F5: 71.162 | G5: 99.6268 | H5: 139.47752 | I5: 195.26853 | J5: 273.37594
B6: =+'Model (End)'!$G$10 -> Base case | E6: =+E5 -> 50.83 | F6: =+'Cohorts (End)'!I11 -> 71.3252 | G6: =+'Cohorts (End)'!J11 -> 93.283352 | H6: =+'Cohorts (End)'!K11 -> 118.54436 | I6: =+'Cohorts (End)'!L11 -> 146.33753 | J6: =+'Cohorts (End)'!M11 -> 178.97177
B8: YoY growth | D8: CAGR
B9: =+'Model (End)'!$G$9 -> Management case | D9: =((J5/E5)^(1/5)-1) -> 0.4 | F9: =+F5/E5-1 -> 0.4 | G9: =+G5/F5-1 -> 0.4 | H9: =+H5/G5-1 -> 0.4 | I9: =+I5/H5-1 -> 0.4 | J9: =+J5/I5-1 -> 0.4
B10: =+'Model (End)'!$G$10 -> Base case | D10: =((J6/E6)^(1/5)-1) -> 0.2862722 | F10: =+F6/E6-1 -> 0.4032107 | G10: =+G6/F6-1 -> 0.30785966 | H10: =+H6/G6-1 -> 0.27079869 | I10: =+I6/H6-1 -> 0.23445371 | J10: =+J6/I6-1 -> 0.22300664
B13: Selling & marketing expenses | E13: =+'Model (End)'!E67 -> 20.75 | F13: =+OFFSET(F13, 'Model (End)'!$J$8, 0) -> 26.34 | G13: =+OFFSET(G13, 'Model (End)'!$J$8, 0) -> 34.32 | H13: =+OFFSET(H13, 'Model (End)'!$J$8, 0) -> 39.3 | I13: =+OFFSET(I13, 'Model (End)'!$J$8, 0) -> 45.88 | J13: =+OFFSET(J13, 'Model (End)'!$J$8, 0) -> 52.46
B14: =+'Model (End)'!$G$9 -> Management case | E14: =+E13 -> 20.75 | F14: 28.4648 | G14: 37.858184 | H14: 50.211907 | I14: 66.3913 | J14: 87.480301
B15: =+'Model (End)'!$G$10 -> Base case | E15: =+E14 -> 20.75 | F15: ='Cohorts (End)'!I132 -> 26.34 | G15: ='Cohorts (End)'!J132 -> 34.32 | H15: ='Cohorts (End)'!K132 -> 39.3 | I15: ='Cohorts (End)'!L132 -> 45.88 | J15: ='Cohorts (End)'!M132 -> 52.46
B17: % of revenue | D17: CAGR
B18: =+'Model (End)'!$G$9 -> Management case | D18: =((J14/E14)^(1/5)-1) -> 0.33345521 | F18: =+F14/F5 -> 0.4 | G18: =+G14/G5 -> 0.38 | H18: =+H14/H5 -> 0.36 | I18: =+I14/I5 -> 0.34 | J18: =+J14/J5 -> 0.32
B19: =+'Model (End)'!$G$10 -> Base case | D19: =((J15/E15)^(1/5)-1) -> 0.20382134 | F19: =+F15/F6 -> 0.36929444 | G19: =+G15/G6 -> 0.36791131 | H19: =+H15/H6 -> 0.33152146 | I19: =+I15/I6 -> 0.31352177 | J19: =+J15/J6 -> 0.29311886

Sheet Valuation (End)
B2: Public trading comparables | AC2: $ millions
E3: Valuation metrics | M3: Operating metrics
C4: Enterprise | E4: EV/Revenue | I4: EV/EBITDA | M4: Revenue | Q4: Revenue Growth | V4: EBITDA | Z4: EBITDA margin
C5: Value | E5: LTM | F5: NTM | G5: NTM+1 | I5: LTM | J5: NTM | K5: NTM+1 | M5: LTM | N5: NTM | O5: NTM+1 | Q5: LTM | R5: NTM | S5: NTM+1 | T5: CAGR | V5: LTM | W5: NTM | X5: NTM+1 | Z5: LTM | AA5: NTM | AB5: NTM+1 | AC5: Average
B7: Company 1 | C7: 9536 | E7: =+$C7/M7 -> 18.16381 | F7: =+$C7/N7 -> 10.684594 | G7: =+$C7/O7 -> 6.6778711 | I7: =+$C7/V7 -> -181.6381 | J7: =+$C7/W7 -> -213.69188 | K7: =+$C7/X7 -> 333.89356 | M7: 525 | N7: =+M7*(1+R7) -> 892.5 | O7: =+N7*(1+S7) -> 1428 | Q7: 0.87 | R7: 0.7 | S7: 0.6 | T7: =(O7/M7)^(1/2)-1 -> 0.64924225 | V7: =+Z7*M7 -> -52.5 | W7: =+AA7*N7 -> -44.625 | X7: =+AB7*O7 -> 28.56 | Z7: -0.1 | AA7: -0.05 | AB7: 0.02 | AC7: =AVERAGE(Z7:AB7) -> -0.043333333
B8: Company 2 | C8: 5551 | E8: =+$C8/M8 -> 4.6258333 | F8: =+$C8/N8 -> 4.1302083 | G8: =+$C8/O8 -> 3.789182 | I8: =+$C8/V8 -> 14.017677 | J8: =+$C8/W8 -> 11.800595 | K8: =+$C8/X8 -> 10.826234 | M8: 1200 | N8: =+M8*(1+R8) -> 1344 | O8: =+N8*(1+S8) -> 1464.96 | Q8: 0.08 | R8: 0.12 | S8: 0.09 | T8: =(O8/M8)^(1/2)-1 -> 0.10489819 | V8: =+Z8*M8 -> 396 | W8: =+AA8*N8 -> 470.4 | X8: =+AB8*O8 -> 512.736 | Z8: 0.33 | AA8: 0.35 | AB8: 0.35 | AC8: =AVERAGE(Z8:AB8) -> 0.34333333
B9: Company 3 | C9: 5078 | E9: =+$C9/M9 -> 15.295181 | F9: =+$C9/N9 -> 8.4973226 | G9: =+$C9/O9 -> 4.9984251 | I9: =+$C9/V9 -> -38.237952 | J9: =+$C9/W9 -> -28.324409 | K9: =+$C9/X9 -> -24.992125 | M9: 332 | N9: =+M9*(1+R9) -> 597.6 | O9: =+N9*(1+S9) -> 1015.92 | Q9: 0.92 | R9: 0.8 | S9: 0.7 | T9: =(O9/M9)^(1/2)-1 -> 0.74928557 | V9: =+Z9*M9 -> -132.8 | W9: =+AA9*N9 -> -179.28 | X9: =+AB9*O9 -> -203.184 | Z9: -0.4 | AA9: -0.3 | AB9: -0.2 | AC9: =AVERAGE(Z9:AB9) -> -0.3
B10: Company 4 | C10: 896 | E10: =+$C10/M10 -> 11.487179 | F10: =+$C10/N10 -> 7.6074036 | G10: =+$C10/O10 -> 5.3953217 | I10: =+$C10/V10 -> -45.948718 | J10: =+$C10/W10 -> -36.225732 | K10: =+$C10/X10 -> -28.39643 | M10: 78 | N10: =+M10*(1+R10) -> 117.78 | O10: =+N10*(1+S10) -> 166.0698 | Q10: 0.66 | R10: 0.51 | S10: 0.41 | T10: =(O10/M10)^(1/2)-1 -> 0.45914358 | V10: =+Z10*M10 -> -19.5 | W10: =+AA10*N10 -> -24.7338 | X10: =+AB10*O10 -> -31.553262 | Z10: -0.25 | AA10: -0.21 | AB10: -0.19 | AC10: =AVERAGE(Z10:AB10) -> -0.21666667
B11: Company 5 | C11: 7412 | E11: =+$C11/M11 -> 12.332779 | F11: =+$C11/N11 -> 10.108835 | G11: =+$C11/O11 -> 8.087068 | I11: =+$C11/V11 -> -246.65557 | J11: =+$C11/W11 -> 336.96117 | K11: =+$C11/X11 -> 80.87068 | M11: 601 | N11: =+M11*(1+R11) -> 733.22 | O11: =+N11*(1+S11) -> 916.525 | Q11: 0.27 | R11: 0.22 | S11: 0.25 | T11: =(O11/M11)^(1/2)-1 -> 0.2349089 | V11: =+Z11*M11 -> -30.05 | W11: =+AA11*N11 -> 21.9966 | X11: =+AB11*O11 -> 91.6525 | Z11: -0.05 | AA11: 0.03 | AB11: 0.1 | AC11: =AVERAGE(Z11:AB11) -> 0.026666667
B12: Company 6 | C12: 4301 | E12: =+$C12/M12 -> 14.336667 | F12: =+$C12/N12 -> 10.779449 | G12: =+$C12/O12 -> 8.6235589 | I12: =+$C12/V12 -> 119.47222 | J12: =+$C12/W12 -> 71.862991 | K12: =+$C12/X12 -> 53.897243 | M12: 300 | N12: =+M12*(1+R12) -> 399 | O12: =+N12*(1+S12) -> 498.75 | Q12: 0.35 | R12: 0.33 | S12: 0.25 | T12: =(O12/M12)^(1/2)-1 -> 0.2893797 | V12: =+Z12*M12 -> 36 | W12: =+AA12*N12 -> 59.85 | X12: =+AB12*O12 -> 79.8 | Z12: 0.12 | AA12: 0.15 | AB12: 0.16 | AC12: =AVERAGE(Z12:AB12) -> 0.14333333
B13: Company 7 | C13: 5523 | E13: =+$C13/M13 -> 24.99095 | F13: =+$C13/N13 -> 12.190707 | G13: =+$C13/O13 -> 6.5895716 | I13: =+$C13/V13 -> -131.53132 | J13: =+$C13/W13 -> -67.726152 | K13: =+$C13/X13 -> -38.762186 | M13: 221 | N13: =+M13*(1+R13) -> 453.05 | O13: =+N13*(1+S13) -> 838.1425 | Q13: 1.08 | R13: 1.05 | S13: 0.85 | T13: =(O13/M13)^(1/2)-1 -> 0.94743421 | V13: =+Z13*M13 -> -41.99 | W13: =+AA13*N13 -> -81.549 | X13: =+AB13*O13 -> -142.48423 | Z13: -0.19 | AA13: -0.18 | AB13: -0.17 | AC13: =AVERAGE(Z13:AB13) -> -0.18
B14: Company 8 | C14: 2217 | E14: =+$C14/M14 -> 5.5012407 | F14: =+$C14/N14 -> 5.0470098 | G14: =+$C14/O14 -> 4.7168316 | I14: =+$C14/V14 -> 15.717831 | J14: =+$C14/W14 -> 14.844147 | K14: =+$C14/X14 -> 13.873034 | M14: 403 | N14: =+M14*(1+R14) -> 439.27 | O14: =+N14*(1+S14) -> 470.0189 | Q14: 0.1 | R14: 0.09 | S14: 0.07 | T14: =(O14/M14)^(1/2)-1 -> 0.079953703 | V14: =+Z14*M14 -> 141.05 | W14: =+AA14*N14 -> 149.3518 | X14: =+AB14*O14 -> 159.80643 | Z14: 0.35 | AA14: 0.34 | AB14: 0.34 | AC14: =AVERAGE(Z14:AB14) -> 0.34333333
B16: Entire comp set
B17: Average | E17: =AVERAGE(E7:E14) -> 13.341705 | F17: =AVERAGE(F7:F14) -> 8.6306912 | G17: =AVERAGE(G7:G14) -> 6.1097287 | I17: =AVERAGE(I7:I14) -> -61.850491 | J17: =AVERAGE(J7:J14) -> 11.187591 | K17: =AVERAGE(K7:K14) -> 50.151251
B18: Median | E18: =MEDIAN(E7:E14) -> 13.334723 | F18: =MEDIAN(F7:F14) -> 9.3030788 | G18: =MEDIAN(G7:G14) -> 5.9924467 | I18: =MEDIAN(I7:I14) -> -42.093335 | J18: =MEDIAN(J7:J14) -> -8.2619068 | K18: =MEDIAN(K7:K14) -> 12.349634
B20: Selected comps
B21: Average | E21: =AVERAGE(E11:E12) -> 13.334723 | F21: =AVERAGE(F11:F12) -> 10.444142 | G21: =AVERAGE(G11:G12) -> 8.3553134 | I21: =AVERAGE(I11:I12) -> -63.591676 | J21: =AVERAGE(J11:J12) -> 204.41208 | K21: =AVERAGE(K11:K12) -> 67.383962
B24: Precedent transaction comparables | AC24: $ millions
C25: Acquisition | E25: Valuation metrics | M25: Operating metrics
C26: Enterprise | E26: EV/Revenue | I26: EV/EBITDA | M26: Revenue | Q26: Revenue Growth | V26: EBITDA | Z26: EBITDA margin
C27: Value | E27: LTM | F27: NTM | G27: NTM+1 | I27: LTM | J27: NTM | K27: NTM+1 | M27: LTM | N27: NTM | O27: NTM+1 | Q27: LTM | R27: NTM | S27: NTM+1 | T27: CAGR | V27: LTM | W27: NTM | X27: NTM+1 | Z27: LTM | AA27: NTM | AB27: NTM+1 | AC27: Average
B29: Company A | C29: 3000 | E29: =+$C29/M29 -> 24 | F29: =+$C29/N29 -> 13.333333 | G29: =+$C29/O29 -> 8.2304527 | I29: =+$C29/V29 -> -240 | J29: =+$C29/W29 -> -266.66667 | K29: =+$C29/X29 -> 411.52263 | M29: 125 | N29: =+M29*(1+R29) -> 225 | O29: =+N29*(1+S29) -> 364.5 | Q29: 0.78 | R29: 0.8 | S29: 0.62 | T29: =(O29/M29)^(1/2)-1 -> 0.70762994 | V29: =+Z29*M29 -> -12.5 | W29: =+AA29*N29 -> -11.25 | X29: =+AB29*O29 -> 7.29 | Z29: -0.1 | AA29: -0.05 | AB29: 0.02 | AC29: =AVERAGE(Z29:AB29) -> -0.043333333
B30: Company B | C30: 8800 | E30: =+$C30/M30 -> 9.8104794 | F30: =+$C30/N30 -> 8.0413765 | G30: =+$C30/O30 -> 6.8147259 | I30: =+$C30/V30 -> 54.502663 | J30: =+$C30/W30 -> 47.302215 | K30: =+$C30/X30 -> 37.859588 | M30: 897 | N30: =+M30*(1+R30) -> 1094.34 | O30: =+N30*(1+S30) -> 1291.3212 | Q30: 0.32 | R30: 0.22 | S30: 0.18 | T30: =(O30/M30)^(1/2)-1 -> 0.19983332 | V30: =+Z30*M30 -> 161.46 | W30: =+AA30*N30 -> 186.0378 | X30: =+AB30*O30 -> 232.43782 | Z30: 0.18 | AA30: 0.17 | AB30: 0.18 | AC30: =AVERAGE(Z30:AB30) -> 0.17666667
B31: Company C | C31: 2500 | E31: =+$C31/M31 -> 11.261261 | F31: =+$C31/N31 -> 10.23751 | G31: =+$C31/O31 -> 9.4791761 | I31: =+$C31/V31 -> 28.153153 | J31: =+$C31/W31 -> 24.375024 | K31: =+$C31/X31 -> 22.569467 | M31: 222 | N31: =+M31*(1+R31) -> 244.2 | O31: =+N31*(1+S31) -> 263.736 | Q31: 0.12 | R31: 0.1 | S31: 0.08 | T31: =(O31/M31)^(1/2)-1 -> 0.089954127 | V31: =+Z31*M31 -> 88.8 | W31: =+AA31*N31 -> 102.564 | X31: =+AB31*O31 -> 110.76912 | Z31: 0.4 | AA31: 0.42 | AB31: 0.42 | AC31: =AVERAGE(Z31:AB31) -> 0.41333333
B32: Company D | C32: 1250 | E32: =+$C32/M32 -> 23.584906 | F32: =+$C32/N32 -> 11.792453 | G32: =+$C32/O32 -> 6.0474117 | I32: =+$C32/V32 -> -63.742988 | J32: =+$C32/W32 -> -39.308176 | K32: =+$C32/X32 -> -30.237059 | M32: 53 | N32: =+M32*(1+R32) -> 106 | O32: =+N32*(1+S32) -> 206.7 | Q32: 1.22 | R32: 1 | S32: 0.95 | T32: =(O32/M32)^(1/2)-1 -> 0.97484177 | V32: =+Z32*M32 -> -19.61 | W32: =+AA32*N32 -> -31.8 | X32: =+AB32*O32 -> -41.34 | Z32: -0.37 | AA32: -0.3 | AB32: -0.2 | AC32: =AVERAGE(Z32:AB32) -> -0.29
B33: Company E | C33: 500 | E33: =+$C33/M33 -> 11.904762 | F33: =+$C33/N33 -> 9.1575092 | G33: =+$C33/O33 -> 7.2106371 | I33: =+$C33/V33 -> -99.206349 | J33: =+$C33/W33 -> -183.15018 | K33: =+$C33/X33 -> 144.21274 | M33: 42 | N33: =+M33*(1+R33) -> 54.6 | O33: =+N33*(1+S33) -> 69.342 | Q33: 0.38 | R33: 0.3 | S33: 0.27 | T33: =(O33/M33)^(1/2)-1 -> 0.28491245 | V33: =+Z33*M33 -> -5.04 | W33: =+AA33*N33 -> -2.73 | X33: =+AB33*O33 -> 3.4671 | Z33: -0.12 | AA33: -0.05 | AB33: 0.05 | AC33: =AVERAGE(Z33:AB33) -> -0.04
B35: Entire comp set
B36: Average | E36: =AVERAGE(E29:E33) -> 16.112282 | F36: =AVERAGE(F29:F33) -> 10.512436 | G36: =AVERAGE(G29:G33) -> 7.5564807 | I36: =AVERAGE(I29:I33) -> -64.058704 | J36: =AVERAGE(J29:J33) -> -83.489557 | K36: =AVERAGE(K29:K33) -> 117.18547
B37: Median | E37: =MEDIAN(E29:E33) -> 11.904762 | F37: =MEDIAN(F29:F33) -> 10.23751 | G37: =MEDIAN(G29:G33) -> 7.2106371 | I37: =MEDIAN(I29:I33) -> -63.742988 | J37: =MEDIAN(J29:J33) -> -39.308176 | K37: =MEDIAN(K29:K33) -> 37.859588
B39: Selected comps
B40: Average | E40: =AVERAGE(E33,E30) -> 10.857621 | F40: =AVERAGE(F33,F30) -> 8.5994428 | G40: =AVERAGE(G33,G30) -> 7.0126815 | I40: =AVERAGE(I33,I30) -> -22.351843 | J40: =AVERAGE(J33,J30) -> -67.923984 | K40: =AVERAGE(K33,K30) -> 91.036165
B43: Historical trading comparables - Software index
C45: Median
C46: EV/LTM Rev
B47: 20 quarters ago | C47: 5.2
B48: 19 quarters ago | C48: 5.9
B49: 18 quarters ago | C49: 6.2
B50: 17 quarters ago | C50: 6.5
B51: 16 quarters ago | C51: 7.2
B52: 15 quarters ago | C52: 6.9
...
