Workbook

Sheet Start ->

Sheet Model - Start
B2: Model | J2: $ millions
B3: Income statement | C3: =+D3-1 -> -2 | D3: =+E3-1 -> -1 | E3: 0 | F3: 1 | G3: =F3+1 -> 2 | H3: =G3+1 -> 3 | I3: =H3+1 -> 4 | J3: =I3+1 -> 5
B4: Gross revenue | C4: 73.836296 | D4: 92.488396 | E4: 119.83782
B5: % Growth | D5: =D4/C4-1 -> 0.25261424 | E5: =E4/D4-1 -> 0.29570657
B7: Cancellations | C7: 10.410918 | D7: 13.688283 | E7: 18.215349
B8: Net revenue | C8: =C4-C7 -> 63.425378 | D8: =D4-D7 -> 78.800113 | E8: =E4-E7 -> 101.62247
B10: COGS | C10: 11.315087 | D10: 14.10522 | E10: 18.292045
B11: Gross profit | C11: =C8-C10 -> 52.110291 | D11: =D8-D10 -> 64.694893 | E11: =E8-E10 -> 83.330428
B13: Operations & support | C13: 11.923971 | D13: 14.499221 | E13: 17.479065
B14: Product development | C14: 11.099441 | D14: 14.18402 | E14: 18.698535
B15: Ad spend | C15: =+'Revenue Build - Start'!C20+'Revenue Build - Start'!C38 -> 8.4 | D15: =+'Revenue Build - Start'!D20+'Revenue Build - Start'!D38 -> 11.4 | E15: =+'Revenue Build - Start'!E20+'Revenue Build - Start'!E38 -> 13.8
B16: General & administrative | C16: 8.3721499 | D16: 10.874416 | E16: 13.719034
B17: Operating expenses | C17: =SUM(C13:C16) -> 39.795562 | D17: =SUM(D13:D16) -> 50.957657 | E17: =SUM(E13:E16) -> 63.696634
B19: EBITDA | C19: =+C11-C17 -> 12.314729 | D19: =+D11-D17 -> 13.737236 | E19: =+E11-E17 -> 19.633794
B22: Balance sheet | E22: 0 | F22: 1 | G22: =F22+1 -> 2 | H22: =G22+1 -> 3 | I22: =H22+1 -> 4 | J22: =I22+1 -> 5
B23: Cash | E23: 110.9
B24: Receivables | E24: 55.1
B25: Capitalized financing fees | E25: 0
B26: Goodwill | E26: 0
B27: Net PP&E | E27: 3
B28: Other assets | E28: 15.8
B29: Total assets | E29: =SUM(E23:E28) -> 184.8
B31: Payables & accrued expenses | E31: 38.4
B32: Other liabilities | E32: 7.7
B33: Debt | E33: 0
B34: Shareholder equity | E34: 138.7
B35: Total liabilities & equity | E35: =SUM(E31:E34) -> 184.8
B37: Working capital
B38: Receivable turnover | E38: =+E8/E24 -> 1.844328
B39: Payable turnover | E39: =+E10/E31 -> 0.47635534
B40: Net working capital | E40: =+E24+E28-E31-E32 -> 24.8

Sheet Revenue Build - Start
B2: Revenue Build | J2: $ millions
B3: Supply & Demand | C3: =+D3-1 -> -2 | D3: =+E3-1 -> -1 | E3: 0 | F3: 1 | G3: =F3+1 -> 2 | H3: =G3+1 -> 3 | I3: =H3+1 -> 4 | J3: =I3+1 -> 5
B4: Total vehicle days rented | C4: =MIN(C17,C35) -> 3212127 | D4: =MIN(D17,D35) -> 4304628.9 | E4: =MIN(E17,E35) -> 5402115.2
B5: Average price per vehicle day rented | C5: =+C6*1000000/C4 -> 152.23 | D5: =+D6*1000000/D4 -> 144.2 | E5: =+E6*1000000/E4 -> 147.89
B6: Total booking value | C6: 488.98209 | D6: 620.72749 | E6: 798.91881
B8: Marketplace fee % | C8: =+C9/C6 -> 0.151 | D8: =+D9/D6 -> 0.149 | E8: =+E9/E6 -> 0.15
B9: Gross revenue | C9: 73.836296 | D9: 92.488396 | E9: 119.83782
B12: Supply | C12: =+D12-1 -> -2 | D12: =+E12-1 -> -1 | E12: 0 | F12: 1 | G12: =F12+1 -> 2 | H12: =G12+1 -> 3 | I12: =H12+1 -> 4 | J12: =I12+1 -> 5
B13: Vehicles days available
B14: Beginning | D14: =+C17 -> 3212127 | E14: =+D17 -> 4304628.9
B15: New added | D15: =+D25 -> 1628927.1 | E15: =+E25 -> 1911061.1
B16: Churned | D16: 536425.21 | E16: 813574.86
B17: Ending | C17: 3212127 | D17: =D14+D15-D16 -> 4304628.9 | E17: =E14+E15-E16 -> 5402115.2
B18: % Growth | D18: =+D17/C17-1 -> 0.34011791 | E18: =+E17/D17-1 -> 0.25495491
B20: Vehicle ad spend | C20: 3.2 | D20: 4.5 | E20: 5.8
B21: Acquisition cost per vehicle | C21: 543.26 | D21: 621.02 | E21: 732.23
B22: New vehicles added | C22: =+C20*1000000/C21 -> 5890.3656 | D22: =+D20*1000000/D21 -> 7246.1434 | E22: =+E20*1000000/E21 -> 7921.0084
B24: Vehicle days available per vehicle added | C24: 250 | D24: 248 | E24: 252
B25: Total vehicle days added | C25: =+C24*AVERAGE(C22) -> 1472591.4 | D25: =+D24*AVERAGE(C22:D22) -> 1628927.1 | E25: =+E24*AVERAGE(D22:E22) -> 1911061.1
B27: Churn as % of prior ending | D27: =+D16/D14 -> 0.167 | E27: =+E16/E14 -> 0.189
B30: Demand | C30: =+D30-1 -> -2 | D30: =+E30-1 -> -1 | E30: 0 | F30: 1 | G30: =F30+1 -> 2 | H30: =G30+1 -> 3 | I30: =H30+1 -> 4 | J30: =I30+1 -> 5
B31: Driver days demanded
B32: Beginning | D32: =+C35 -> 3505699 | E32: =+D35 -> 5665304.5
B33: New added | D33: =+D43 -> 2731034.5 | E33: =+E43 -> 2471860.1
B34: Churned | D34: 571428.94 | E34: 974432.38
B35: Ending | C35: 3505699 | D35: =D32+D33-D34 -> 5665304.5 | E35: =E32+E33-E34 -> 7162732.3
B36: % Growth | D36: =+D35/C35-1 -> 0.61602709 | E36: =+E35/D35-1 -> 0.26431548
B38: Driver ad spend | C38: 5.2 | D38: 6.9 | E38: 8
B39: Acquisition cost per driver | C39: 14.5 | D39: 17.25 | E39: 18.87
B40: New drivers added | C40: =+C38*1000000/C39 -> 358620.69 | D40: =+D38*1000000/D39 -> 400000 | E40: =+E38*1000000/E39 -> 423953.37
B42: Driver days demanded per driver added | C42: 8 | D42: 7.2 | E42: 6
B43: Total driver days added | C43: =+C42*AVERAGE(C40) -> 2868965.5 | D43: =+D42*AVERAGE(C40:D40) -> 2731034.5 | E43: =+E42*AVERAGE(D40:E40) -> 2471860.1
B45: Churn as % of prior ending | D45: =+D34/D32 -> 0.163 | E45: =+E34/E32 -> 0.172

Sheet End ->

Sheet Model - End
B2: Assumptions | J2: $ millions
B3: Entry assumptions | G3: Other assumptions
C4: Pre-Money | D4: Post-Money | E4: Assumptions | G4: New option pool | J4: 0.043
B5: LTM EBITDA | C5: =E78 -> 19.633794 | G5: Family - % shares sold | J5: 0
B6: Entry multiple | C6: 15 | G6: Seed investor - % shares sold | J6: 0.5
B7: Enterprise value | C7: =C5*C6 -> 294.5069 | D7: =C7 -> 294.5069 | G7: Existing employees - % shares sold | J7: 0
B8: (-) New debt | C8: =+C105 -> 0 | D8: 0
B9: (+) Cash | C9: =C95 -> 110.9 | D9: 110.9
B10: Equity value | C10: =C7+C9-C8 -> 405.4069 | D10: =D7+D9-D8 -> 405.4069
B11: (+) Transaction fees | D11: =+E11*D7 -> 1.4725345 | E11: 0.005
B12: (+) Financing fees | D12: =+E12*D8 -> 0 | E12: 0
B13: Equity value (incl. fees) | D13: =+D10+D11+D12 -> 406.87944
B16: Sources & uses | J16: $ millions
B17: Sources | G17: Uses
B18: New debt | D18: =+D8 -> 0 | G18: Proceeds to selling shareholders | J18: =+SUM(D35:D37)-SUM(H35:H37) -> 61.945108
B19: Rollover equity | D19: =+J19 -> 343.4618 | G19: Rollover equity | J19: =SUM(H35:H37) -> 343.4618
B20: Sponsor equity | D20: =+J24-D19-D18 -> 63.417642 | G20: Cash added to B/S | J20: =+D9-C9 -> 0
G21: Transaction fees | J21: =+D11 -> 1.4725345
G22: Financing fees | J22: =+D12 -> 0
B24: Total sources | D24: =SUM(D18:D23) -> 406.87944 | G24: Total uses | J24: =SUM(J18:J23) -> 406.87944
B25: Check 1? | D25: =+D24-J24 -> 0
B26: Check 2? | D26: =+D20-H34 -> 0
B28: Capitalization table
D29: Pre-Money | H29: Post-Money
D30: $ Amount | E30: FD Shares | F30: FD own % | H30: $ Amount | I30: FD Shares | J30: FD own %
B31: Primary | D31: =+E31*D$41/1000000 -> 0 | E31: 0 | F31: =+E31/E$39 -> 0 | H31: =J20 -> 0 | I31: =+H31*1000000/H$41 -> 0 | J31: =+I31/I$39 -> 0
B32: Secondary | D32: =+E32*D$41/1000000 -> 0 | E32: 0 | F32: =+E32/E$39 -> 0 | H32: =D35-H35+D36-H36+D37-H37 -> 61.945108 | I32: =+H32*1000000/H$41 -> 1300000 | J32: =+I32/I$39 -> 0.14622708
B33: Deal fees | D33: 0 | E33: 0 | F33: =+E33/E$39 -> 0 | H33: =J21+J22 -> 1.4725345 | I33: 0 | J33: =+I33/I$39 -> 0
B34: Total new sponsor | D34: =SUM(D31:D33) -> 0 | E34: =SUM(E31:E33) -> 0 | F34: =+E34/E$39 -> 0 | H34: =SUM(H31:H33) -> 63.417642 | I34: =SUM(I31:I33) -> 1300000 | J34: =+I34/I$39 -> 0.14622708
B35: Family | D35: =+E35*D$41/1000000 -> 257.31045 | E35: 5400000 | F35: =+E35/E$39 -> 0.63469676 | H35: =+I35*H$41/1000000 -> 257.31045 | I35: =+E35*(1-J5) -> 5400000 | J35: =+I35/I$39 -> 0.6074048
B36: Seed investor | D36: =+E36*D$41/1000000 -> 123.89022 | E36: 2600000 | F36: =+E36/E$39 -> 0.30559473 | H36: =+I36*H$41/1000000 -> 61.945108 | I36: =+E36*(1-J6) -> 1300000 | J36: =+I36/I$39 -> 0.14622708
B37: Existing employee options | D37: =+E37*D$41/1000000 -> 24.206242 | E37: 508000 | F37: =+E37/E$39 -> 0.05970851 | H37: =+I37*H$41/1000000 -> 24.206242 | I37: =+E37*(1-J7) -> 508000 | J37: =+I37/I$39 -> 0.057141044
B38: New option pool | D38: =+E38*D$41/1000000 -> 0 | E38: 0 | F38: =+E38/E$39 -> 0 | H38: 0 | I38: =SUM(I34:I37)/(1-J4)*J4 -> 382282.13 | J38: =+I38/I$39 -> 0.043
B39: Total company | D39: =SUM(D34:D38) -> 405.4069 | E39: =SUM(E34:E38) -> 8508000 | F39: =+E39/E$39 -> 1 | H39: =SUM(H34:H38) -> 406.87944 | I39: =SUM(I34:I38) -> 8890282.1 | J39: =+I39/I$39 -> 1
B41: Share price | D41: =+C10*1000000/E39 -> 47.650083 | H41: =+D41 -> 47.650083
B44: Model | J44: $ millions
B45: Income statement | C45: =+D45-1 -> -2 | D45: =+E45-1 -> -1 | E45: 0 | F45: 1 | G45: =F45+1 -> 2 | H45: =G45+1 -> 3 | I45: =H45+1 -> 4 | J45: =I45+1 -> 5
B46: Gross revenue | C46: =+'Revenue Build - End'!C21 -> 73.836296 | D46: =+'Revenue Build - End'!D21 -> 92.488396 | E46: =+'Revenue Build - End'!E21 -> 119.83782 | F46: =+'Revenue Build - End'!F21 -> 148.79459 | G46: =+'Revenue Build - End'!G21 -> 191.91399 | H46: =+'Revenue Build - End'!H21 -> 242.33648 | I46: =+'Revenue Build - End'!I21 -> 301.40048 | J46: =+'Revenue Build - End'!J21 -> 370.68247
B47: % Growth | D47: =D46/C46-1 -> 0.25261424 | E47: =E46/D46-1 -> 0.29570657 | F47: =F46/E46-1 -> 0.24163296 | G47: =G46/F46-1 -> 0.28979148 | H47: =H46/G46-1 -> 0.26273478 | I47: =I46/H46-1 -> 0.24372725 | J47: =J46/I46-1 -> 0.22986688
B49: Cancellations | C49: =C54*C$46 -> 10.410918 | D49: =D54*D$46 -> 13.688283 | E49: =E54*E$46 -> 18.215349 | F49: =F54*F$46 -> 22.319189 | G49: =G54*G$46 -> 28.787099 | H49: =H54*H$46 -> 36.350471 | I49: =I54*I$46 -> 45.210072 | J49: =J54*J$46 -> 55.60237
...

Sheet Revenue Build - End
B2: Revenue Build | J2: $ millions
B3: Supply & Demand | C3: =+D3-1 -> -2 | D3: =+E3-1 -> -1 | E3: 0 | F3: 1 | G3: =F3+1 -> 2 | H3: =G3+1 -> 3 | I3: =H3+1 -> 4 | J3: =I3+1 -> 5
B4: Vehicle days available | C4: =+C30 -> 3212127 | D4: =+D30 -> 4304628.9 | E4: =+E30 -> 5402115.2 | F4: =+F30 -> 6388042.2 | G4: =+G30 -> 7356466.4 | H4: =+H30 -> 8326512.9 | I4: =+I30 -> 9314840.6 | J4: =+J30 -> 10336253
B5: Driver days demanded | C5: =+C53 -> 3505699 | D5: =+D53 -> 5665304.5 | E5: =+E53 -> 7162732.3 | F5: =+F53 -> 8727222.9 | G5: =+G53 -> 10120227 | H5: =+H53 -> 11366633 | I5: =+I53 -> 12487861 | J5: =+J53 -> 13502350
B6: Supply as % of demand | C6: =+C4/C5 -> 0.91625864 | D6: =+D4/D5 -> 0.75982304 | E6: =+E4/E5 -> 0.75419756 | F6: =+F4/F5 -> 0.73196734 | G6: =+G4/G5 -> 0.72690725 | H6: =+H4/H5 -> 0.73253997 | I6: =+I4/I5 -> 0.7459116 | J6: =+J4/J5 -> 0.76551511
B8: Vehicle days rented
B9: Supply or demand minimum | C9: =+MIN(C4,C5) -> 3212127 | D9: =+MIN(D4,D5) -> 4304628.9 | E9: =+MIN(E4,E5) -> 5402115.2 | F9: =+MIN(F4,F5) -> 6388042.2 | G9: =+MIN(G4,G5) -> 7356466.4 | H9: =+MIN(H4,H5) -> 8326512.9 | I9: =+MIN(I4,I5) -> 9314840.6 | J9: =+MIN(J4,J5) -> 10336253
B10: Marketplace matching efficiency factor | C10: 1 | D10: 1 | E10: 1 | F10: 1 | G10: 1 | H10: 1 | I10: 1 | J10: 1
B11: Total vehicle days rented | C11: =+C10*C9 -> 3212127 | D11: =+D10*D9 -> 4304628.9 | E11: =+E10*E9 -> 5402115.2 | F11: =+F10*F9 -> 6388042.2 | G11: =+G10*G9 -> 7356466.4 | H11: =+H10*H9 -> 8326512.9 | I11: =+I10*I9 -> 9314840.6 | J11: =+J10*J9 -> 10336253
B13: Average price per vehicle day rented | C13: 152.23 | D13: 144.2 | E13: 147.89 | F13: =+E13*(1+F14) -> 155.2845 | G13: =+F13*(1+G14) -> 163.04872 | H13: =+G13*(1+H14) -> 171.20116 | I13: =+H13*(1+I14) -> 179.76122 | J13: =+I13*(1+J14) -> 188.74928
B14: % Growth | D14: =+D13/C13-1 -> -0.05274913 | E14: =+E13/D13-1 -> 0.025589459 | F14: 0.05 | G14: 0.05 | H14: 0.05 | I14: 0.05 | J14: 0.05
B16: Total booking value | C16: =+C13*C11/1000000 -> 488.98209 | D16: =+D13*D11/1000000 -> 620.72749 | E16: =+E13*E11/1000000 -> 798.91881 | F16: =+F13*F11/1000000 -> 991.96393 | G16: =+G13*G11/1000000 -> 1199.4625 | H16: =+H13*H11/1000000 -> 1425.5087 | I16: =+I13*I11/1000000 -> 1674.4471 | J16: =+J13*J11/1000000 -> 1950.9603
B17: % Growth | D17: =+D16/C16-1 -> 0.26942785 | E17: =+E16/D16-1 -> 0.28706853 | F17: =+F16/E16-1 -> 0.24163296 | G17: =+G16/F16-1 -> 0.20917951 | H17: =+H16/G16-1 -> 0.18845627 | I17: =+I16/H16-1 -> 0.17463129 | J17: =+J16/I16-1 -> 0.16513704
B19: Marketplace fee % | C19: 0.151 | D19: 0.149 | E19: 0.15 | F19: 0.15 | G19: 0.16 | H19: 0.17 | I19: 0.18 | J19: 0.19
B21: Gross revenue | C21: =+C19*C16 -> 73.836296 | D21: =+D19*D16 -> 92.488396 | E21: =+E19*E16 -> 119.83782 | F21: =+F19*F16 -> 148.79459 | G21: =+G19*G16 -> 191.91399 | H21: =+H19*H16 -> 242.33648 | I21: =+I19*I16 -> 301.40048 | J21: =+J19*J16 -> 370.68247
B22: % Growth | D22: =+D21/C21-1 -> 0.25261424 | E22: =+E21/D21-1 -> 0.29570657 | F22: =+F21/E21-1 -> 0.24163296 | G22: =+G21/F21-1 -> 0.28979148 | H22: =+H21/G21-1 -> 0.26273478 | I22: =+I21/H21-1 -> 0.24372725 | J22: =+J21/I21-1 -> 0.22986688
B25: Supply | C25: =+D25-1 -> -2 | D25: =+E25-1 -> -1 | E25: 0 | F25: 1 | G25: =F25+1 -> 2 | H25: =G25+1 -> 3 | I25: =H25+1 -> 4 | J25: =I25+1 -> 5
B26: Vehicles days available
B27: Beginning | D27: =+C30 -> 3212127 | E27: =+D30 -> 4304628.9 | F27: =+E30 -> 5402115.2 | G27: =+F30 -> 6388042.2 | H27: =+G30 -> 7356466.4 | I27: =+H30 -> 8326512.9 | J27: =+I30 -> 9314840.6
B28: New added | D28: =+D43 -> 1628927.1 | E28: =+E43 -> 1911061.1 | F28: =+F43 -> 2066350 | G28: =+G43 -> 2246032.6 | H28: =+H43 -> 2441339.8 | I28: =+I43 -> 2653630.2 | J28: =+J43 -> 2884380.7
B29: Churned | D29: =D27*D45 -> 536425.21 | E29: =E27*E45 -> 813574.86 | F29: =F27*F45 -> 1080423 | G29: =G27*G45 -> 1277608.4 | H29: =H27*H45 -> 1471293.3 | I29: =I27*I45 -> 1665302.6 | J29: =J27*J45 -> 1862968.1
B30: Ending | C30: 3212127 | D30: =D27+D28-D29 -> 4304628.9 | E30: =E27+E28-E29 -> 5402115.2 | F30: =F27+F28-F29 -> 6388042.2 | G30: =G27+G28-G29 -> 7356466.4 | H30: =H27+H28-H29 -> 8326512.9 | I30: =I27+I28-I29 -> 9314840.6 | J30: =J27+J28-J29 -> 10336253
B31: % Growth | D31: =+D30/C30-1 -> 0.34011791 | E31: =+E30/D30-1 -> 0.25495491 | F31: =+F30/E30-1 -> 0.18250758 | G31: =+G30/F30-1 -> 0.15159953 | H31: =+H30/G30-1 -> 0.13186311 | I31: =+I30/H30-1 -> 0.11869647 | J31: =+J30/I30-1 -> 0.10965433
B33: Vehicle ad spend | C33: 3.2 | D33: 4.5 | E33: 5.8 | F33: =+E33*(1+F34) -> 7.25 | G33: =+F33*(1+G34) -> 9.0625 | H33: =+G33*(1+H34) -> 11.328125 | I33: =+H33*(1+I34) -> 14.160156 | J33: =+I33*(1+J34) -> 17.700195
B34: % Growth | D34: =+D33/C33-1 -> 0.40625 | E34: =+E33/D33-1 -> 0.28888889 | F34: 0.25 | G34: 0.25 | H34: 0.25 | I34: 0.25 | J34: 0.25
B36: Acquisition cost per vehicle | C36: 543.26 | D36: 621.02 | E36: 732.23 | F36: =+E36*(1+F37) -> 842.0645 | G36: =+F36*(1+G37) -> 968.37417 | H36: =+G36*(1+H37) -> 1113.6303 | I36: =+H36*(1+I37) -> 1280.6748 | J36: =+I36*(1+J37) -> 1472.7761
B37: % Growth | D37: =+D36/C36-1 -> 0.14313588 | E37: =+E36/D36-1 -> 0.17907636 | F37: 0.15 | G37: 0.15 | H37: 0.15 | I37: 0.15 | J37: 0.15
B39: New vehicles added | C39: =+C33*1000000/C36 -> 5890.3656 | D39: =+D33*1000000/D36 -> 7246.1434 | E39: =+E33*1000000/E36 -> 7921.0084 | F39: =+F33*1000000/F36 -> 8609.7918 | G39: =+G33*1000000/G36 -> 9358.4693 | H39: =+H33*1000000/H36 -> 10172.249 | I39: =+I33*1000000/I36 -> 11056.793 | J39: =+J33*1000000/J36 -> 12018.253
B41: Vehicle days available per vehicle added | C41: 250 | D41: 248 | E41: 252 | F41: 250 | G41: 250 | H41: 250 | I41: 250 | J41: 250
B43: Total vehicle days added | C43: =+C41*AVERAGE(C39) -> 1472591.4 | D43: =+D41*AVERAGE(C39:D39) -> 1628927.1 | E43: =+E41*AVERAGE(D39:E39) -> 1911061.1 | F43: =+F41*AVERAGE(E39:F39) -> 2066350 | G43: =+G41*AVERAGE(F39:G39) -> 2246032.6 | H43: =+H41*AVERAGE(G39:H39) -> 2441339.8 | I43: =+I41*AVERAGE(H39:I39) -> 2653630.2 | J43: =+J41*AVERAGE(I39:J39) -> 2884380.7
B45: Churn as % of prior ending | D45: 0.167 | E45: 0.189 | F45: 0.2 | G45: 0.2 | H45: 0.2 | I45: 0.2 | J45: 0.2
B48: Demand | C48: =+D48-1 -> -2 | D48: =+E48-1 -> -1 | E48: 0 | F48: 1 | G48: =F48+1 -> 2 | H48: =G48+1 -> 3 | I48: =H48+1 -> 4 | J48: =I48+1 -> 5
B49: Driver days demanded
B50: Beginning | D50: =+C53 -> 3505699 | E50: =+D53 -> 5665304.5 | F50: =+E53 -> 7162732.3 | G50: =+F53 -> 8727222.9 | H50: =+G53 -> 10120227 | I50: =+H53 -> 11366633 | J50: =+I53 -> 12487861
B51: New added | D51: =+D66 -> 2731034.5 | E51: =+E66 -> 2471860.1 | F51: =+F66 -> 2567273.2 | G51: =+G66 -> 2614815.3 | H51: =+H66 -> 2663237.8 | I51: =+I66 -> 2712557 | J51: =+J66 -> 2762789.5
B52: Churned | D52: =D50*D68 -> 571428.94 | E52: =E50*E68 -> 974432.38 | F52: =F50*F68 -> 1002782.5 | G52: =G50*G68 -> 1221811.2 | H52: =H50*H68 -> 1416831.8 | I52: =I50*I68 -> 1591328.6 | J52: =J50*J68 -> 1748300.6
B53: Ending | C53: 3505699 | D53: =D50+D51-D52 -> 5665304.5 | E53: =E50+E51-E52 -> 7162732.3 | F53: =F50+F51-F52 -> 8727222.9 | G53: =G50+G51-G52 -> 10120227 | H53: =H50+H51-H52 -> 11366633 | I53: =I50+I51-I52 -> 12487861 | J53: =J50+J51-J52 -> 13502350
B54: % Growth | D54: =+D53/C53-1 -> 0.61602709 | E54: =+E53/D53-1 -> 0.26431548 | F54: =+F53/E53-1 -> 0.21842093 | G54: =+G53/F53-1 -> 0.15961596 | H54: =+H53/G53-1 -> 0.12315988 | I54: =+I53/H53-1 -> 0.098642084 | J54: =+J53/I53-1 -> 0.081238004
B56: Driver ad spend | C56: 5.2 | D56: 6.9 | E56: 8 | F56: =+E56*(1+F57) -> 8.8 | G56: =+F56*(1+G57) -> 9.68 | H56: =+G56*(1+H57) -> 10.648 | I56: =+H56*(1+I57) -> 11.7128 | J56: =+I56*(1+J57) -> 12.88408
B57: % Growth | D57: =+D56/C56-1 -> 0.32692308 | E57: =+E56/D56-1 -> 0.15942029 | F57: 0.1 | G57: 0.1 | H57: 0.1 | I57: 0.1 | J57: 0.1
...
